Workbook

Sheet converted_MPa_Loss_modulus_f2
A1: Study_id | B1: Instance | C1: fill
A2: 1 | B2: 1
A3: 1 | B3: 2
A4: 1 | B4: 3
A5: 1 | B5: 4
A6: 1 | B6: 5
A7: 2 | B7: 1 | C7: loss | D7: =Loss_modulus_G!C7/1000000 -> 0.0002628283 | E7: =Loss_modulus_G!D7/1000000 -> 0.00037761495 | F7: =Loss_modulus_G!E7/1000000 -> 0.00055496078 | G7: =Loss_modulus_G!F7/1000000 -> 0.00077947695 | H7: =Loss_modulus_G!G7/1000000 -> 0.0010948239 | I7: =Loss_modulus_G!H7/1000000 -> 0.0014696473 | J7: =Loss_modulus_G!I7/1000000 -> 0.001972795 | K7: =Loss_modulus_G!J7/1000000 -> 0.0024742446 | ... N7: =Loss_modulus_G!M7/1000000 -> 0.0034752304
A8: 2 | B8: 2 | C8: loss | D8: =Loss_modulus_G!C8/1000000 -> 3.5015658e-05 | E8: =Loss_modulus_G!D8/1000000 -> 4.9181671e-05 | F8: =Loss_modulus_G!E8/1000000 -> 6.753178e-05 | G8: =Loss_modulus_G!F8/1000000 -> 9.0651929e-05 | H8: =Loss_modulus_G!G8/1000000 -> 0.00013627815 | I8: =Loss_modulus_G!H8/1000000 -> 0.00020956149 | J8: =Loss_modulus_G!I8/1000000 -> 0.00030108459 | K8: =Loss_modulus_G!J8/1000000 -> 0.00043257914 | ... N8: =Loss_modulus_G!M8/1000000 -> 0.0014696473
A9: 2 | B9: 3 | C9: loss | D9: =Loss_modulus_G!C9/1000000 -> 0.0011455562 | E9: =Loss_modulus_G!D9/1000000 -> 0.0014696473 | F9: =Loss_modulus_G!E9/1000000 -> 0.0022093387 | G9: =Loss_modulus_G!F9/1000000 -> 0.0029657268 | H9: =Loss_modulus_G!G9/1000000 -> 0.0043585724 | I9: =Loss_modulus_G!H9/1000000 -> 0.0062621189 | J9: =Loss_modulus_G!I9/1000000 -> 0.00859857 | K9: =Loss_modulus_G!J9/1000000 -> 0.012353877 | ... N9: =Loss_modulus_G!M9/1000000 -> 0.040112404
A10: 3 | B10: 1 | C10: loss | D10: =Loss_modulus_G!C10/1000000 -> 1.8107198e-05 | E10: =Loss_modulus_G!D10/1000000 -> 2.2579744e-05 | F10: =Loss_modulus_G!E10/1000000 -> 2.8157026e-05 | G10: =Loss_modulus_G!F10/1000000 -> 3.6197426e-05 | H10: =Loss_modulus_G!G10/1000000 -> 5.2560702e-05 | I10: =Loss_modulus_G!H10/1000000 -> 6.4063634e-05 | J10: =Loss_modulus_G!I10/1000000 -> 7.5742362e-05 | K10: =Loss_modulus_G!J10/1000000 -> 8.8197149e-05 | ... Z10: =Loss_modulus_G!Y10/1000000 -> 0.00020845306
A11: 3 | B11: 2 | C11: loss | D11: =Loss_modulus_G!C11/1000000 -> 6.5543394e-05 | E11: =Loss_modulus_G!D11/1000000 -> 6.2142458e-05 | F11: =Loss_modulus_G!E11/1000000 -> 6.5543394e-05 | G11: =Loss_modulus_G!F11/1000000 -> 7.0727251e-05 | H11: =Loss_modulus_G!G11/1000000 -> 8.2357372e-05 | I11: =Loss_modulus_G!H11/1000000 -> 9.3734793e-05 | J11: =Loss_modulus_G!I11/1000000 -> 0.00010668397 | K11: =Loss_modulus_G!J11/1000000 -> 0.00012422668 | ... Z11: =Loss_modulus_G!Y11/1000000 -> 0.00032169034
A12: 3 | B12: 3 | C12: loss | D12: =Loss_modulus_G!C12/1000000 -> 0.00015141374 | E12: =Loss_modulus_G!D12/1000000 -> 0.00015141374 | F12: =Loss_modulus_G!E12/1000000 -> 0.00015257068 | G12: =Loss_modulus_G!F12/1000000 -> 0.00015257068 | H12: =Loss_modulus_G!G12/1000000 -> 0.00016844041 | I12: =Loss_modulus_G!H12/1000000 -> 0.0001845507 | J12: =Loss_modulus_G!I12/1000000 -> 0.00019170994 | K12: =Loss_modulus_G!J12/1000000 -> 0.00020687236 | ... Z12: =Loss_modulus_G!Y12/1000000 -> 0.00038911919
A13: 3 | B13: 4 | C13: loss | D13: =Loss_modulus_G!C13/1000000 -> 4.2796175e-05 | E13: =Loss_modulus_G!D13/1000000 -> 6.0278896e-05 | F13: =Loss_modulus_G!E13/1000000 -> 9.0234351e-05 | G13: =Loss_modulus_G!F13/1000000 -> 0.00010832052 | H13: =Loss_modulus_G!G13/1000000 -> 0.0001300318 | I13: =Loss_modulus_G!H13/1000000 -> 0.0001572875 | J13: =Loss_modulus_G!I13/1000000 -> 0.00016844041 | K13: =Loss_modulus_G!J13/1000000 -> 0.00018881351 | ... Z13: =Loss_modulus_G!Y13/1000000 -> 0.00033163561
A14: 4 | B14: 1 | C14: loss | D14: =Loss_modulus_G!C14/1000000 -> 6.0388241e-06 | E14: =Loss_modulus_G!D14/1000000 -> 9.7830932e-06 | F14: =Loss_modulus_G!E14/1000000 -> 1.7301957e-05 | G14: =Loss_modulus_G!F14/1000000 -> 2.9935773e-05 | H14: =Loss_modulus_G!G14/1000000 -> 4.7445003e-05 | I14: =Loss_modulus_G!H14/1000000 -> 7.040752e-05 | J14: =Loss_modulus_G!I14/1000000 -> 9.7830932e-05 | K14: =Loss_modulus_G!J14/1000000 -> 0.00015505158 | ... X14: =Loss_modulus_G!W14/1000000 -> 0.0087671239
A15: 4 | B15: 2 | C15: loss | D15: =Loss_modulus_G!C15/1000000 -> 2.3519526e-05 | E15: =Loss_modulus_G!D15/1000000 -> 3.4145489e-05 | F15: =Loss_modulus_G!E15/1000000 -> 5.0671283e-05 | G15: =Loss_modulus_G!F15/1000000 -> 7.6862461e-05 | H15: =Loss_modulus_G!G15/1000000 -> 0.00010916797 | I15: =Loss_modulus_G!H15/1000000 -> 0.00016200328 | J15: =Loss_modulus_G!I15/1000000 -> 0.00022510283 | K15: =Loss_modulus_G!J15/1000000 -> 0.0003340485 | ... X15: =Loss_modulus_G!W15/1000000 -> 0.015505158
A16: 4 | B16: 3 | C16: loss | D16: =Loss_modulus_G!C16/1000000 -> 6.0388241e-05 | E16: =Loss_modulus_G!D16/1000000 -> 7.5195262e-05 | F16: =Loss_modulus_G!E16/1000000 -> 0.00010448348 | G16: =Loss_modulus_G!F16/1000000 -> 0.0001329871 | H16: =Loss_modulus_G!G16/1000000 -> 0.00018888196 | I16: =Loss_modulus_G!H16/1000000 -> 0.00027421754 | J16: =Loss_modulus_G!I16/1000000 -> 0.00037275937 | K16: =Loss_modulus_G!J16/1000000 -> 0.00051794747 | ... X16: =Loss_modulus_G!W16/1000000 -> 0.018077687
A17: 5 | B17: 1 | C17: loss | D17: =Loss_modulus_G!C17/1000000 -> 3.408738e-05 | E17: =Loss_modulus_G!D17/1000000 -> 3.2492953e-05 | F17: =Loss_modulus_G!E17/1000000 -> 3.5760045e-05 | G17: =Loss_modulus_G!F17/1000000 -> 3.8732196e-05 | H17: =Loss_modulus_G!G17/1000000 -> 4.3312755e-05 | I17: =Loss_modulus_G!H17/1000000 -> 5.0006807e-05 | J17: =Loss_modulus_G!I17/1000000 -> 5.7735435e-05 | K17: =Loss_modulus_G!J17/1000000 -> 6.6658534e-05 | ... AT17: =Loss_modulus_G!AS17/1000000 -> 0.01726516
A18: 5 | B18: 2 | C18: loss | D18: =Loss_modulus_G!C18/1000000 -> 0.00035646024 | E18: =Loss_modulus_G!D18/1000000 -> 0.00039861605 | F18: =Loss_modulus_G!E18/1000000 -> 0.00043174652 | G18: =Loss_modulus_G!F18/1000000 -> 0.00045293229 | H18: =Loss_modulus_G!G18/1000000 -> 0.00047515765 | I18: =Loss_modulus_G!H18/1000000 -> 0.00048280587 | J18: =Loss_modulus_G!I18/1000000 -> 0.00046022277 | K18: =Loss_modulus_G!J18/1000000 -> 0.00048280587 | ... AT18: =Loss_modulus_G!AS18/1000000 -> 0.0047364261
A19: 5 | B19: 3 | C19: loss | D19: =Loss_modulus_G!C19/1000000 -> 0.00018819955 | E19: =Loss_modulus_G!D19/1000000 -> 0.00022078355 | F19: =Loss_modulus_G!E19/1000000 -> 0.00025900899 | G19: =Loss_modulus_G!F19/1000000 -> 0.00029903922 | H19: =Loss_modulus_G!G19/1000000 -> 0.00035081349 | I19: =Loss_modulus_G!H19/1000000 -> 0.00038608698 | J19: =Loss_modulus_G!I19/1000000 -> 0.00048280587 | K19: =Loss_modulus_G!J19/1000000 -> 0.00053990361 | ... AT19: =Loss_modulus_G!AS19/1000000 -> 0.012747034
A20: 5 | B20: 4 | C20: loss | D20: =Loss_modulus_G!C20/1000000 -> 3.8986037e-05 | E20: =Loss_modulus_G!D20/1000000 -> 4.4435214e-05 | F20: =Loss_modulus_G!E20/1000000 -> 4.9824527e-05 | G20: =Loss_modulus_G!F20/1000000 -> 5.4961277e-05 | H20: =Loss_modulus_G!G20/1000000 -> 6.1627241e-05 | I20: =Loss_modulus_G!H20/1000000 -> 7.0241036e-05 | J20: =Loss_modulus_G!I20/1000000 -> 7.6225849e-05 | K20: =Loss_modulus_G!J20/1000000 -> 8.4084493e-05 | ... AT20: =Loss_modulus_G!AS20/1000000 -> 0.0066225116
A21: 5 | B21: 5 | C21: loss | D21: =Loss_modulus_G!C21/1000000 -> 6.0429639e-06 | E21: =Loss_modulus_G!D21/1000000 -> 6.8876042e-06 | F21: =Loss_modulus_G!E21/1000000 -> 7.850302e-06 | G21: =Loss_modulus_G!F21/1000000 -> 8.2450479e-06 | H21: =Loss_modulus_G!G21/1000000 -> 9.7099258e-06 | I21: =Loss_modulus_G!H21/1000000 -> 1.1249581e-05 | J21: =Loss_modulus_G!I21/1000000 -> 1.2821964e-05 | K21: =Loss_modulus_G!J21/1000000 -> 1.3466706e-05 | ... AT21: =Loss_modulus_G!AS21/1000000 -> 0.0096466162
A22: 5 | B22: 6 | C22: loss | D22: =Loss_modulus_G!C22/1000000 -> 7.9797381e-06 | E22: =Loss_modulus_G!D22/1000000 -> 6.5578483e-06 | F22: =Loss_modulus_G!E22/1000000 -> 6.1426005e-06 | G22: =Loss_modulus_G!F22/1000000 -> 5.8485129e-06 | H22: =Loss_modulus_G!G22/1000000 -> 6.24388e-06 | I22: =Loss_modulus_G!H22/1000000 -> 6.6659743e-06 | J22: =Loss_modulus_G!I22/1000000 -> 7.4744552e-06 | K22: =Loss_modulus_G!J22/1000000 -> 8.2450479e-06 | ... AT22: =Loss_modulus_G!AS22/1000000 -> 0.0093362066
A23: 6 | B23: 1 | C23: visc | D23: 7.7097756e-05 | E23: 7.4301278e-05 | F23: 8.9829509e-05 | G23: 0.00010538435 | H23: 0.00011590326 | I23: 0.00014525886 | J23: 0.0001669931 | K23: 0.00020701515 | L23: 0.00023428977 | M23: 0.0003023178 | N23: 0.00036733502 | O23: 0.00047027305 | P23: 0.00063649837 | Q23: 0.00075463476 | R23: 0.00096409654 | S23: 0.0012042519 | T23: 0.0015407851 | U23: 0.0019487468 | V23: 0.0024928802 | W23: 0.0030323365 | X23: 0.0036588599 | Y23: 0.0047241517 | Z23: 0.005840507 | AA23: 0.0069601765 | AB23: 0.0083297526 | AC23: 0.010235974 | AD23: 0.012399998 | AE23: 0.014216058 | AF23: 0.018216286 | AG23: 0.020690852 | AH23: 0.022839783 | AI23: 0.026024117 | AJ23: 0.030159919 | AK23: 0.032335756 | AL23: 0.033043843
A24: 6 | B24: 2 | C24: visc | D24: 0.0007629862 | E24: 0.00086227928 | F24: 0.0008965819 | G24: 0.00091698796 | H24: 0.0012851754 | I24: 0.0012351648 | J24: 0.0010529805 | K24: 0.001539111 | L24: 0.0017036965 | M24: 0.0020051724 | N24: 0.002507519 | O24: 0.0024961807 | P24: 0.003593323 | Q24: 0.0037385062 | R24: 0.0043510516 | S24: 0.005071421 | T24: 0.0056669144 | U24: 0.0069027519 | V24: 0.0084336757 | W24: 0.0098296168 | X24: 0.011300706 | Y24: 0.01311652 | Z24: 0.015717025 | AA24: 0.017085824 | AB24: 0.021429431 | AC24: 0.023862782 | AD24: 0.028027712 | AE24: 0.033552013 | AF24: 0.040022823 | AG24: 0.040021809 | AH24: 0.045536681 | AI24: 0.051210939 | AJ24: 0.059315335 | AK24: 0.069588297 | AL24: 0.061150009
A25: 6 | B25: 3 | C25: visc | D25: 0.0046500131 | E25: 0.0049586773 | F25: 0.0054968115 | G25: 0.0057325124 | H25: 0.0062653076 | I25: 0.0064211418 | J25: 0.0064738833 | K25: 0.0090725802 | L25: 0.0095405462 | M25: 0.01041698 | N25: 0.009197147 | O25: 0.010781972 | P25: 0.011363087 | Q25: 0.013700243 | R25: 0.01466642 | S25: 0.016291478 | T25: 0.01943161 | U25: 0.021521292 | V25: 0.025711561 | W25: 0.030307663 | X25: 0.031311148 | Y25: 0.036724491 | Z25: 0.040776742 | AA25: 0.044171991 | AB25: 0.050554367 | AC25: 0.061803601 | AD25: 0.063463677 | AE25: 0.077303857 | AF25: 0.083650546 | AG25: 0.087771916 | AH25: 0.10052898 | AI25: 0.09524592 | AJ25: 0.13007389 | AK25: 0.15482401 | AL25: 0.13841202
A26: 6 | B26: 4 | C26: visc | D26: 0.013990956 | E26: 0.014669241 | F26: 0.012072506 | G26: 0.015266342 | H26: 0.01601216 | I26: 0.017080366 | J26: 0.016159118 | K26: 0.018724734 | L26: 0.02139505 | M26: 0.023493449 | N26: 0.024204771 | O26: 0.022233203 | P26: 0.027971877 | Q26: 0.031190031 | R26: 0.036601523 | S26: 0.034349703 | T26: 0.0424112 | U26: 0.049082995 | V26: 0.048222833 | W26: 0.057367492 | X26: 0.055704659 | Y26: 0.067046771 | Z26: 0.064396749 | AA26: 0.066938633 | AB26: 0.078683959 | AC26: 0.095588752 | AD26: 0.10495804 | AE26: 0.10408099 | AF26: 0.10681458 | AG26: 0.12411322 | AH26: 0.12095653 | AI26: 0.13062557 | AJ26: 0.15545064 | AK26: 0.18167444 | AL26: 0.21589409
A27: 7 | B27: 1 | C27: loss | D27: =Loss_modulus_G!C27/1000000 -> 3.9483219e-05 | E27: =Loss_modulus_G!D27/1000000 -> 0.00011319094 | F27: =Loss_modulus_G!E27/1000000 -> 0.00031786459 | G27: =Loss_modulus_G!F27/1000000 -> 0.00075670006 | H27: =Loss_modulus_G!G27/1000000 -> 0.0014652755 | I27: =Loss_modulus_G!H27/1000000 -> 0.0025067045 | J27: =Loss_modulus_G!I27/1000000 -> 0.0040307064 | K27: =Loss_modulus_G!J27/1000000 -> 0.0060919084 | ... Y27: =Loss_modulus_G!X27/1000000 -> 0.071124289
A28: 7 | B28: 2 | C28: loss | D28: =Loss_modulus_G!C28/1000000 -> 0.0071862487 | E28: =Loss_modulus_G!D28/1000000 -> 0.01108774 | F28: =Loss_modulus_G!E28/1000000 -> 0.01936402 | G28: =Loss_modulus_G!F28/1000000 -> 0.033818005 | H28: =Loss_modulus_G!G28/1000000 -> 0.056671307 | I28: =Loss_modulus_G!H28/1000000 -> 0.091125779 | J28: =Loss_modulus_G!I28/1000000 -> 0.12945166 | K28: =Loss_modulus_G!J28/1000000 -> 0.15270614 | ... N28: =Loss_modulus_G!M28/1000000 -> 0.27793689
A29: 8 | B29: 1 | C29: tan | D29: 436.89378 | E29: 406.85419 | F29: 365.76277 | G29: 306.68393 | H29: 217.67894 | I29: 146.84974 | J29: 120.04096 | K29: 108.16966 | L29: 91.410302 | M29: 74.135577 | N29: 60.215929 | O29: 45.874997 | P29: 35.090626 | Q29: 19.39072
A30: 8 | B30: 2 | C30: tan | D30: 459.88623 | E30: 430.41945 | F30: 382.55751 | G30: 329.05694 | H30: 245.05574 | I30: 173.58358 | J30: 145.67102 | K30: 124.12808 | L30: 99.464861 | M30: 79.324197 | N30: 66.106204 | O30: 57.082317 | P30: 48.034702 | Q30: 37.198295
A31: 8 | B31: 3 | C31: tan | D31: 404.28611 | E31: 386.28413 | F31: 383.73373 | G31: 343.16912 | H31: 281.01766 | I31: 204.15518 | J31: 169.90942 | K31: 172.1326 | L31: 157.70425 | M31: 124.77541 | N31: 108.03562 | O31: 92.494526 | P31: 79.99463 | Q31: 58.363653
A32: 8 | B32: 4 | C32: tan | D32: 232.29858 | E32: 217.00039 | F32: 200.09075 | G32: 172.31202 | H32: 137.40353 | I32: 103.2329 | J32: 79.925942 | K32: 64.687908 | L32: 51.474078 | M32: 46.257982 | N32: 41.999351 | O32: 40.792946 | P32: 31.957638 | Q32: 20.279912
A33: 9 | B33: 1 | C33: tan | D33: 283.09238 | E33: 294.90261 | F33: 292.99552 | G33: 295.83917 | H33: 301.93001 | I33: 357.71306 | J33: 296.11062 | K33: 152.38978 | L33: 83.102067 | M33: 48.489738 | N33: 36.043601 | O33: 27.55308 | P33: 22.302895 | Q33: 18.822435
A34: 9 | B34: 2 | C34: tan | D34: 69.919072 | E34: 67.32482 | F34: 76.942652 | G34: 78.41825 | H34: 108.72241 | I34: 199.01624 | J34: 240.43269 | K34: 128.19886 | L34: 66.331965 | M34: 32.854228 | N34: 25.296134 | O34: 22.426742 | P34: 20.014431 | Q34: 17.673497
A35: 9 | B35: 3 | C35: tan | D35: 207.87029 | E35: 198.26532 | F35: 195.23845 | G35: 200.12212 | H35: 212.00585 | I35: 288.3734 | J35: 305.12381 | K35: 177.64324 | L35: 97.288201 | M35: 60.300664 | N35: 45.903156 | O35: 33.703876 | P35: 28.10276 | Q35: 22.246355
A36: 9 | B36: 4 | C36: tan | D36: 187.59881 | E36: 189.95217 | F36: 182.58578 | G36: 192.85744 | H36: 220.00184 | I36: 299.3939 | J36: 327.8495 | K36: 186.17748 | L36: 99.155228 | M36: 61.295702 | N36: 44.948003 | O36: 39.458196 | P36: 19.143782
A37: 11 | B37: 1a
A38: 11 | B38: 2a
A39: 11 | B39: 3a
A40: 11 | B40: 4a
...

Sheet Physchem_properties
A1: Study_id | B1: Instance | C1: Monomer_A | D1: Monomer_B | E1: HB_ratio (mol%) | F1: HV_ratio (mol%) | G1: Mw_PHBV | H1: Mn_PHBV | I1: Density | J1: Density_units | K1: PDI | L1: Additive_1 | M1: Additive1_type | N1: Additive1_name | O1: Additive1_percentage (wt%) | P1: Additive_2 | Q1: Additive2_type | R1: Additive2_name | S1: Additive2_percentage (wt%) | T1: final_formulation_PHA_percentage (wt%) | V1: Row No.
A2: 1 | B2: 1 | C2: 3HB | D2: 3HV | E2: 97 | F2: 3 | I2: 1.24 | J2: g/cm3 | L2: No | P2: No | T2: 100 | V2: 1
A3: 1 | B3: 2 | C3: 3HB | D3: 3HV | E3: 97 | F3: 3 | I3: 1.24 | J3: g/cm3 | L3: No | P3: No | T3: 100 | V3: 2
A4: 1 | B4: 3 | C4: 3HB | D4: 3HV | E4: 97 | F4: 3 | I4: 1.24 | J4: g/cm3 | L4: No | P4: No | T4: 100 | V4: 3
A5: 1 | B5: 4 | C5: 3HB | D5: 3HV | E5: 97 | F5: 3 | I5: 1.24 | J5: g/cm3 | L5: No | P5: No | T5: 100 | V5: 4
A6: 1 | B6: 5 | C6: 3HB | D6: 3HV | E6: 97 | F6: 3 | I6: 1.24 | J6: g/cm3 | L6: No | P6: No | T6: 100 | V6: 5
A7: 2 | B7: 1 | C7: 3HB | D7: 3HV | E7: 100 | F7: 0 | G7: 440000 | H7: 260000 | L7: No | P7: No | T7: 100 | V7: 6
A8: 2 | B8: 2 | C8: 3HB | D8: 3HV | E8: 100 | F8: 0 | G8: 440000 | H8: 260000 | L8: Yes | M8: Reinforcment and stiffening modifiers | N8: lignin | O8: 10 | P8: No | T8: 90 | V8: 7
A9: 2 | B9: 3 | C9: 3HB | D9: 3HV | E9: 100 | F9: 0 | G9: 440000 | H9: 260000 | L9: Yes | M9: Reinforcment and stiffening modifiers | N9: lignin | O9: 60 | P9: No | T9: 40 | V9: 8
A10: 3 | B10: 1 | C10: 3HB | D10: 3HV | E10: 100 | F10: 0 | G10: 223000 | K10: 1.23 | L10: No | P10: No | T10: 100 | V10: 10
A11: 3 | B11: 2 | C11: 3HB | D11: 3HV | E11: 100 | F11: 0 | G11: 223000 | K11: 1.23 | L11: Yes | M11: Reinforcment and stiffening modifiers | N11: LCB | O11: 30 | P11: No | T11: 70 | V11: 11
A12: 3 | B12: 3 | C12: 3HB | D12: 3HV | E12: 100 | F12: 0 | G12: 223000 | K12: 1.23 | L12: Yes | M12: Reinforcment and stiffening modifiers | N12: IL | O12: 30 | P12: No | T12: 70 | V12: 12
A13: 3 | B13: 4 | C13: 3HB | D13: 3HV | E13: 100 | F13: 0 | G13: 223000 | K13: 1.23 | L13: Yes | M13: Reinforcment and stiffening modifiers | N13: HC | O13: 30 | P13: No | T13: 70 | V13: 13
A14: 4 | B14: 1 | C14: 3HB | D14: 3HV | E14: 97 | F14: 3 | I14: 1.23 | J14: g/cm3 | L14: No | P14: No | T14: 100 | V14: 14
A15: 4 | B15: 2 | C15: 3HB | D15: 3HV | E15: 97 | F15: 3 | I15: 1.23 | J15: g/cm3 | L15: Yes | M15: Reinforcment and stiffening modifiers | N15: wood_fiber | O15: 15 | P15: No | T15: 85 | V15: 15
A16: 4 | B16: 3 | C16: 3HB | D16: 3HV | E16: 97 | F16: 3 | I16: 1.23 | J16: g/cm3 | L16: Yes | M16: Reinforcment and stiffening modifiers | N16: cellulose | O16: 15 | P16: No | T16: 85 | V16: 16
A17: 5 | B17: 1 | C17: 3HB | D17: 3HV | E17: 92 | F17: 8 | G17: 443000 | L17: No | P17: No | T17: 100 | V17: 17
A18: 5 | B18: 2 | C18: 3HB | D18: 3HV | E18: 92 | F18: 8 | G18: 443000 | L18: Yes | M18: Reinforcment and stiffening modifiers | N18: IN | O18: 30 | P18: No | T18: 70 | V18: 18
A19: 5 | B19: 3 | C19: 3HB | D19: 3HV | E19: 92 | F19: 8 | G19: 443000 | L19: Yes | M19: Reinforcment and stiffening modifiers | N19: IN-AC | O19: 30 | P19: No | T19: 70 | V19: 19
A20: 5 | B20: 4 | C20: 3HB | D20: 3HV | E20: 92 | F20: 8 | G20: 443000 | L20: Yes | M20: Reinforcment and stiffening modifiers | N20: IN-PR | O20: 30 | P20: No | T20: 70 | V20: 20
A21: 5 | B21: 5 | C21: 3HB | D21: 3HV | E21: 92 | F21: 8 | G21: 443000 | L21: Yes | M21: Reinforcment and stiffening modifiers | N21: IN-BU | O21: 30 | P21: No | T21: 70 | V21: 21
A22: 5 | B22: 6 | C22: 3HB | D22: 3HV | E22: 92 | F22: 8 | G22: 443000 | L22: Yes | M22: Reinforcment and stiffening modifiers | N22: IN-HE | O22: 30 | P22: No | T22: 70 | V22: 22
A23: 6 | B23: 1 | C23: 3HB | D23: 3HV | E23: 100 | F23: 0 | G23: 117869 | H23: 49078 | L23: No | P23: No | T23: 100 | V23: 23
A24: 6 | B24: 2 | C24: 3HB | D24: 3HV | E24: 100 | F24: 0 | G24: 117869 | H24: 49078 | L24: Yes | M24: Reinforcment and stiffening modifiers | N24: lignin | O24: 5 | P24: No | T24: 95 | V24: 24
A25: 6 | B25: 3 | C25: 3HB | D25: 3HV | E25: 100 | F25: 0 | G25: 117869 | H25: 49078 | L25: Yes | M25: Reinforcment and stiffening modifiers | N25: lignin | O25: 7 | P25: No | T25: 93 | V25: 25
A26: 6 | B26: 4 | C26: 3HB | D26: 3HV | E26: 100 | F26: 0 | G26: 117869 | H26: 49078 | L26: Yes | M26: Reinforcment and stiffening modifiers | N26: lignin | O26: 9 | P26: No | T26: 91 | V26: 26
A27: 7 | B27: 1 | C27: 3HB | D27: 3HV | E27: 100 | F27: 0 | G27: 890000 | H27: 462000 | L27: No | P27: No | T27: 100 | V27: 27
A28: 7 | B28: 2 | C28: 3HB | D28: 3HV | E28: 100 | F28: 0 | G28: 890000 | H28: 462000 | L28: Yes | M28: Reinforcment and stiffening modifiers | N28: LRR | O28: 30 | P28: No | T28: 70 | V28: 28
A29: 8 | B29: 1 | C29: 3HB | D29: 3HB | E29: 100 | F29: 0 | G29: 490000 | I29: 1.25 | J29: g/cm3 | L29: Yes | M29: Plasticizers and flexibility enhancers | N29: ATBC | O29: 10 | P29: No | T29: 90 | V29: 29
A30: 8 | B30: 2 | C30: 3HB | D30: 3HV | E30: 100 | F30: 0 | G30: 490000 | I30: 1.25 | J30: g/cm3 | L30: Yes | M30: Plasticizers and flexibility enhancers | N30: ATBC | O30: 10 | P30: Yes | Q30: Reinforcment and stiffening modifiers | R30: CLF | S30: 5 | T30: 85 | V30: 30
A31: 8 | B31: 3 | C31: 3HB | D31: 3HV | E31: 100 | F31: 0 | G31: 490000 | I31: 1.25 | J31: g/cm3 | L31: Yes | M31: Plasticizers and flexibility enhancers | N31: ATBC | O31: 10 | P31: Yes | Q31: Reinforcment and stiffening modifiers | R31: CLF | S31: 10 | T31: 80 | V31: 31
A32: 8 | B32: 4 | C32: 3HB | D32: 3HV | E32: 100 | F32: 0 | G32: 490000 | I32: 1.25 | J32: g/cm3 | L32: Yes | M32: Plasticizers and flexibility enhancers | N32: ATBC | O32: 20 | P32: Yes | Q32: Reinforcment and stiffening modifiers | R32: CLF | S32: 5 | T32: 75 | V32: 32
A33: 9 | B33: 1 | C33: 3HB | D33: 3HV | E33: 22.9 | F33: 77.1 | G33: 286000 | K33: 2.5 | L33: No | P33: No | T33: 100 | V33: 33
A34: 9 | B34: 2 | C34: 3HB | D34: 3HV | E34: 22.9 | F34: 77.1 | G34: 286000 | K34: 2.5 | L34: Yes | M34: Reinforcment and stiffening modifiers | N34: lignin | O34: 1 | P34: No | T34: 99 | V34: 34
A35: 9 | B35: 3 | C35: 3HB | D35: 3HV | E35: 22.9 | F35: 77.1 | G35: 286000 | K35: 2.5 | L35: Yes | M35: Reinforcment and stiffening modifiers | N35: lignin | O35: 5 | P35: No | T35: 95 | V35: 35
A36: 9 | B36: 4 | C36: 3HB | D36: 3HV | E36: 22.9 | F36: 77.1 | G36: 286000 | K36: 2.5 | L36: Yes | M36: Reinforcment and stiffening modifiers | N36: lignin | O36: 10 | P36: No | T36: 90 | V36: 36
A37: 11 | B37: 1a | C37: 3HB | D37: 3HV | E37: 100 | F37: 0 | G37: 450000 | L37: No | P37: No | T37: 100 | V37: 37
A38: 11 | B38: 2a | C38: 3HB | D38: 3HV | E38: 100 | F38: 0 | G38: 450000 | L38: Yes | M38: Reinforcment and stiffening modifiers | N38: biorefinery_lignin | O38: 10 | P38: No | T38: 90 | V38: 38
A39: 11 | B39: 3a | C39: 3HB | D39: 3HV | E39: 100 | F39: 0 | G39: 450000 | L39: Yes | M39: Reinforcment and stiffening modifiers | N39: biorefinery_lignin | O39: 20 | P39: No | T39: 80 | V39: 39
A40: 11 | B40: 4a | C40: 3HB | D40: 3HV | E40: 100 | F40: 0 | G40: 450000 | L40: Yes | M40: Reinforcment and stiffening modifiers | N40: biorefinery_lignin | O40: 50 | P40: No | T40: 50 | V40: 40
...

Sheet Thermal_properties
A1: Study_id | B1: Instance | C1: Tg1 | D1: Tg2 | E1: Tc1 | F1: Tc2 | G1: Tmc | H1: Tm1 | I1: Tm2 | J1: Td5 | K1: Tdeg | L1: Temperature_units | M1: DΗm1 | N1: DΗm2 | O1: DHc1 | P1: DHc2 | Q1: Enthaply_units | R1: Crystallinity_%
A2: 1 | B2: 1 | E2: 125 | H2: 168 | L2: celsius
A3: 1 | B3: 2 | E3: 125 | H3: 168 | L3: celsius
A4: 1 | B4: 3 | E4: 125 | H4: 168 | L4: celsius
A5: 1 | B5: 4 | E5: 125 | H5: 168 | L5: celsius
A6: 1 | B6: 5 | E6: 125 | H6: 168 | L6: celsius
A7: 2 | B7: 1 | C7: 3 | G7: 89 | H7: 172 | L7: celsius | M7: 92 | Q7: J/g | R7: 63
A8: 2 | B8: 2 | C8: 7 | G8: 132 | H8: 174 | L8: celsius | M8: 90 | Q8: J/g | R8: 61
A9: 2 | B9: 3 | C9: 17 | G9: 86 | H9: 165 | L9: celsius | M9: 31 | Q9: J/g | R9: 21
A10: 3 | B10: 1 | C10: 3.8 | E10: 46.6 | G10: 63.2 | L10: celsius | M10: 83.3 | O10: 72.8 | P10: 15.3 | Q10: J/g
A11: 3 | B11: 2 | C11: 4.6 | E11: 46.7 | G11: 62.9 | L11: celsius | M11: 83.1 | O11: 30 | P11: 45 | Q11: J/g
A12: 3 | B12: 3 | C12: 3.8 | E12: 41.6 | G12: 47.3 | L12: celsius | M12: 83.7 | O12: 50 | P12: 27.9 | Q12: J/g
A13: 3 | B13: 4 | C13: 4.7 | E13: 41.2 | G13: 62.2 | L13: celsius | M13: 82.3 | O13: 15.7 | P13: 49.7 | Q13: J/g
A14: 4 | B14: 1
A15: 4 | B15: 2
A16: 4 | B16: 3
A17: 5 | B17: 1 | E17: 91 | I17: 170 | L17: celsius | O17: 74 | Q17: J/g | R17: 64.3
A18: 5 | B18: 2 | E18: 71 | H18: 163 | I18: 172 | L18: celsius | O18: 47 | Q18: J/g | R18: 62.3
A19: 5 | B19: 3 | E19: 60 | H19: 160 | I19: 170 | L19: celsius | O19: 34 | Q19: J/g | R19: 64.2
A20: 5 | B20: 4 | E20: 66 | H20: 158 | I20: 170 | L20: celsius | O20: 33 | Q20: J/g | R20: 64.8
A21: 5 | B21: 5 | E21: 71 | H21: 158 | I21: 170 | L21: celsius | O21: 34 | Q21: J/g | R21: 64.8
A22: 5 | B22: 6 | E22: 77 | H22: 167 | I22: 174 | L22: celsius | O22: 49 | Q22: J/g | R22: 64.5
A23: 6 | B23: 1 | C23: -1.3 | G23: 53 | H23: 167.8 | J23: 265.5 | L23: celsius | M23: 74.1 | Q23: J/g | R23: 50.8
A24: 6 | B24: 2 | C24: 0.2 | G24: 72.9 | H24: 167.7 | J24: 265.1 | L24: celsius | M24: 71.3 | Q24: J/g | R24: 48.8
A25: 6 | B25: 3 | C25: 1.3 | G25: 69.4 | H25: 168.6 | J25: 267.5 | L25: celsius | M25: 65.1 | Q25: J/g | R25: 44.6
A26: 6 | B26: 4 | C26: 2 | G26: 68.4 | H26: 169.2 | J26: 266.5 | L26: celsius | M26: 62.3 | Q26: J/g | R26: 42.7
A27: 7 | B27: 1 | C27: 3.9 | E27: 47.4 | H27: 175 | L27: celsius | M27: 87.4 | O27: 68.7 | Q27: J/g
A28: 7 | B28: 2 | C28: 3.8 | E28: 42.9 | H28: 171.4 | L28: celsius | M28: 87.8 | O28: 25.1 | Q28: J/g
A29: 8 | B29: 1 | C29: -13.4 | E29: 85.7 | H29: 161.3 | I29: 170.3 | J29: 215.7 | K29: 279.1 | L29: celsius | M29: 86 | N29: 88.7 | O29: 73.9 | Q29: J/g | R29: 58.9
A30: 8 | B30: 2 | C30: -10.1 | E30: 87.5 | H30: 161.8 | I30: 170.4 | J30: 226.5 | K30: 287.2 | L30: celsius | M30: 83.7 | N30: 85.4 | O30: 68.5 | Q30: J/g | R30: 60.4
A31: 8 | B31: 3 | C31: -6.3 | E31: 83.8 | H31: 161.2 | I31: 170 | J31: 229.3 | K31: 288.9 | L31: celsius | M31: 84.5 | N31: 79.9 | O31: 61.9 | Q31: J/g | R31: 64.3
A32: 8 | B32: 4 | C32: -21 | E32: 77 | H32: 155.5 | I32: 166.7 | J32: 203 | K32: 287.4 | L32: celsius | M32: 79 | N32: 73.7 | O32: 57.5 | Q32: J/g | R32: 63.6
A33: 9 | B33: 1 | C33: −3.7 | E33: 104.2 | H33: 150.8 | I33: 162.3 | L33: celsius | M33: 20.1 | N33: 17.3 | O33: 28.6 | Q33: J/g
A34: 9 | B34: 2 | C34: −2.6 | E34: 100.8 | H34: 149.4 | I34: 161.7 | L34: celsius | M34: 18.3 | N34: 19 | O34: 32.5 | Q34: J/g
A35: 9 | B35: 3 | C35: −2.2 | E35: 96 | H35: 148.2 | I35: 161.4 | L35: celsius | M35: 15.6 | N35: 20.3 | O35: 30.7 | Q35: J/g
A36: 9 | B36: 4 | C36: −1.5 | E36: 107.2 | H36: 151.1 | I36: 161.9 | L36: celsius | M36: 20.5 | N36: 13.5 | O36: 26.9 | Q36: J/g
A37: 11 | B37: 1a | L37: celsius
A38: 11 | B38: 2a | L38: celsius
A39: 11 | B39: 3a | L39: celsius
A40: 11 | B40: 4a | L40: celsius
...

Sheet Rheological_experimental_detail
A1: Study_id | B1: Instance | C1: Test type | D1: constant parameters | E1: geometry | F1: plate diameter | G1: gap size | H1: morphology | I1: diameter | J1: thickness | K1: size units | L1: Angular_frequency_units | M1: Texp | N1: Texp_units | O1: Viscosity_units | P1: Modulus_units | Q1: Strain_fixed(%) | R1: Frequency_experimental_fixed (Hz) | V1: Row No.
A2: 1 | B2: 1 | C2: DFS | D2: strain,temp | E2: parallel plate | G2: 1.8 | K2: mm | L2: rad/s | M2: 180 | N2: celsius | O2: Pa*s | Q2: 1 | V2: 1
A3: 1 | B3: 2 | C3: DFS | D3: strain,temp | E3: parallel plate | G3: 1.8 | K3: mm | L3: rad/s | M3: 170 | N3: celsius | O3: Pa*s | Q3: 1 | V3: 2
A4: 1 | B4: 3 | C4: DFS | D4: strain,temp | E4: parallel plate | G4: 1.8 | K4: mm | L4: rad/s | M4: 160 | N4: celsius | O4: Pa*s | Q4: 1 | V4: 3
A5: 1 | B5: 4 | C5: DFS | D5: strain,temp | E5: parallel plate | G5: 1.8 | K5: mm | L5: rad/s | M5: 150 | N5: celsius | O5: Pa*s | Q5: 1 | V5: 4
A6: 1 | B6: 5 | C6: DFS | D6: strain,temp | E6: parallel plate | G6: 1.8 | K6: mm | L6: rad/s | M6: 145 | N6: celsius | O6: Pa*s | Q6: 1 | V6: 5
A7: 2 | B7: 1 | C7: DFS | D7: strain,temp | E7: parallel plate | F7: 25 | G7: 0.75 | H7: disc | I7: 25 | J7: 0.5 | K7: mm | L7: rad/s | M7: 175 | N7: celsius | O7: Pa*s | P7: Pa | V7: 6
A8: 2 | B8: 2 | C8: DFS | D8: strain,temp | E8: parallel plate | F8: 25 | G8: 0.75 | H8: disc | I8: 25 | J8: 0.5 | K8: mm | L8: rad/s | M8: 175 | N8: celsius | O8: Pa*s | P8: Pa | V8: 7
A9: 2 | B9: 3 | C9: DFS | D9: strain,temp | E9: parallel plate | F9: 25 | G9: 0.75 | H9: disc | I9: 25 | J9: 0.5 | K9: mm | L9: rad/s | M9: 175 | N9: celsius | O9: Pa*s | P9: Pa | V9: 8
A10: 3 | B10: 1 | C10: DFS | D10: strain,temp | E10: parallel plate | F10: 25 | G10: 0.8 | K10: mm | L10: rad/s | M10: 190 | N10: celsius | O10: Pa*s | P10: Pa | V10: 10
A11: 3 | B11: 2 | C11: DFS | D11: strain,temp | E11: parallel plate | F11: 25 | G11: 0.8 | K11: mm | L11: rad/s | M11: 190 | N11: celsius | O11: Pa*s | P11: Pa | V11: 11
A12: 3 | B12: 3 | C12: DFS | D12: strain,temp | E12: parallel plate | F12: 25 | G12: 0.8 | K12: mm | L12: rad/s | M12: 190 | N12: celsius | O12: Pa*s | P12: Pa | V12: 12
A13: 3 | B13: 4 | C13: DFS | D13: strain,temp | E13: parallel plate | F13: 25 | G13: 0.8 | K13: mm | L13: rad/s | M13: 190 | N13: celsius | O13: Pa*s | P13: Pa | V13: 13
A14: 4 | B14: 1 | C14: DFS | D14: strain,temp | E14: parallel plate | F14: 25 | G14: 1.5 | K14: mm | L14: hz | M14: 180 | N14: celsius | O14: Pa*s | P14: Pa | Q14: 0.1 | V14: 14
A15: 4 | B15: 2 | C15: DFS | D15: strain,temp | E15: parallel plate | F15: 25 | G15: 1.5 | K15: mm | L15: hz | M15: 180 | N15: celsius | O15: Pa*s | P15: Pa | Q15: 0.1 | V15: 15
A16: 4 | B16: 3 | C16: DFS | D16: strain,temp | E16: parallel plate | F16: 25 | G16: 1.5 | K16: mm | L16: hz | M16: 180 | N16: celsius | O16: Pa*s | P16: Pa | Q16: 0.1 | V16: 16
A17: 5 | B17: 1 | C17: DFS | D17: strain,temp | E17: parallel plate | H17: disc | I17: 25 | J17: 2 | K17: mm | L17: rad/s | M17: 175 | N17: celsius | P17: Pa | Q17: 1 | V17: 17
A18: 5 | B18: 2 | C18: DFS | D18: strain,temp | E18: parallel plate | H18: disc | I18: 25 | J18: 2 | K18: mm | L18: rad/s | M18: 175 | N18: celsius | P18: Pa | Q18: 1 | V18: 18
A19: 5 | B19: 3 | C19: DFS | D19: strain,temp | E19: parallel plate | H19: disc | I19: 25 | J19: 2 | K19: mm | L19: rad/s | M19: 175 | N19: celsius | P19: Pa | Q19: 1 | V19: 19
A20: 5 | B20: 4 | C20: DFS | D20: strain,temp | E20: parallel plate | H20: disc | I20: 25 | J20: 2 | K20: mm | L20: rad/s | M20: 175 | N20: celsius | P20: Pa | Q20: 1 | V20: 20
A21: 5 | B21: 5 | C21: DFS | D21: strain,temp | E21: parallel plate | H21: disc | I21: 25 | J21: 2 | K21: mm | L21: rad/s | M21: 175 | N21: celsius | P21: Pa | Q21: 1 | V21: 21
A22: 5 | B22: 6 | C22: DFS | D22: strain,temp | E22: parallel plate | H22: disc | I22: 25 | J22: 2 | K22: mm | L22: rad/s | M22: 175 | N22: celsius | P22: Pa | Q22: 1 | V22: 22
A23: 6 | B23: 1 | C23: DFS | D23: strain,temp | E23: parallel plate | F23: 25 | K23: mm | L23: rad/s | M23: 175 | N23: celsius | O23: Pa*s | P23: Pa | Q23: 1 | V23: 23
A24: 6 | B24: 2 | C24: DFS | D24: strain,temp | E24: parallel plate | F24: 25 | K24: mm | L24: rad/s | M24: 175 | N24: celsius | O24: Pa*s | P24: Pa | Q24: 1 | V24: 24
A25: 6 | B25: 3 | C25: DFS | D25: strain,temp | E25: parallel plate | F25: 25 | K25: mm | L25: rad/s | M25: 175 | N25: celsius | O25: Pa*s | P25: Pa | Q25: 1 | V25: 25
A26: 6 | B26: 4 | C26: DFS | D26: strain,temp | E26: parallel plate | F26: 25 | K26: mm | L26: rad/s | M26: 175 | N26: celsius | O26: Pa*s | P26: Pa | Q26: 1 | V26: 26
A27: 7 | B27: 1 | C27: DFS | D27: strain,temp | E27: parallel plate | F27: 20 | K27: mm | L27: rad/s | M27: 190 | N27: celsius | P27: Pa | Q27: 0.3 | V27: 27
A28: 7 | B28: 2 | C28: DFS | D28: strain,temp | E28: parallel plate | F28: 20 | K28: mm | L28: rad/s | M28: 190 | N28: celsius | P28: Pa | Q28: 0.3 | V28: 28
A29: 8 | B29: 1 | C29: DTS | D29: angular frequency,stress or strain | L29: hz | N29: celsius | O29: Pa*s | P29: MPa | R29: 1 | V29: 29
A30: 8 | B30: 2 | C30: DTS | D30: angular frequency,stress or strain | L30: hz | N30: celsius | O30: Pa*s | P30: MPa | R30: 1 | V30: 30
A31: 8 | B31: 3 | C31: DTS | D31: angular frequency,stress or strain | L31: hz | N31: celsius | O31: Pa*s | P31: MPa | R31: 1 | V31: 31
A32: 8 | B32: 4 | C32: DTS | D32: angular frequency,stress or strain | L32: hz | N32: celsius | O32: Pa*s | P32: MPa | R32: 1 | V32: 32
A33: 9 | B33: 1 | C33: DTS | D33: angular frequency,strain | L33: hz | N33: celsius | P33: MPa | R33: 1 | V33: 33
A34: 9 | B34: 2 | C34: DTS | D34: angular frequency,strain | L34: hz | N34: celsius | P34: MPa | R34: 1 | V34: 34
A35: 9 | B35: 3 | C35: DTS | D35: angular frequency,strain | L35: hz | N35: celsius | P35: MPa | R35: 1 | V35: 35
A36: 9 | B36: 4 | C36: DTS | D36: angular frequency,strain | L36: hz | N36: celsius | P36: MPa | R36: 1 | V36: 36
A37: 11 | B37: 1a | C37: DFS | D37: strain,temp | F37: 25 | G37: 0.5 | K37: mm | L37: hz | M37: 190 | N37: celsius | O37: Pa*s | V37: 37
A38: 11 | B38: 2a | C38: DFS | D38: strain,temp | F38: 25 | G38: 0.5 | K38: mm | L38: hz | M38: 190 | N38: celsius | O38: Pa*s | V38: 38
A39: 11 | B39: 3a | C39: DFS | D39: strain,temp | F39: 25 | G39: 0.5 | K39: mm | L39: hz | M39: 190 | N39: celsius | O39: Pa*s | V39: 39
A40: 11 | B40: 4a | C40: DFS | D40: strain,temp | F40: 25 | G40: 0.5 | K40: mm | L40: hz | M40: 190 | N40: celsius | O40: Pa*s | V40: 40
...

Sheet Storage_modulus_G
A1: Study_id | B1: Instance
A2: 1 | B2: 1
A3: 1 | B3: 2
A4: 1 | B4: 3
A5: 1 | B5: 4
A6: 1 | B6: 5
A7: 2 | B7: 1 | C7: 78.116806 | D7: 110.30285 | E7: 161.51092 | F7: 240.82605 | G7: 365.67181 | H7: 545.24672 | I7: 756.04718 | J7: 1010.9551 | K7: 1453.6524 | L7: 2015.6559 | M7: 2552.349
A8: 2 | B8: 2 | C8: 2.2640686 | D8: 2.4346432 | E8: 2.7646514 | F8: 2.9729398 | G8: 3.4377762 | H8: 3.9037559 | I8: 4.5968525 | J8: 6.2593606 | K8: 8.2191423 | L8: 11.605631 | M8: 28.773357
A9: 2 | B9: 3 | C9: 690.42533 | D9: 843.07752 | E9: 1067.5572 | F9: 1453.6524 | G9: 2015.6559 | H9: 2599.121 | I9: 3670.0229 | J9: 4819.0929 | K9: 7317.3413 | L9: 11947.776 | M9: 12616.717
A10: 3 | B10: 1 | C10: 23.747494 | D10: 14.724465 | E10: 21.193096 | F10: 40.083479 | G10: 164.36732 | H10: 332.84384 | I10: 906.07968 | J10: 1675.1462 | K10: 3241.2192 | L10: 6130.2672 | M10: 10114.452 | N10: 17465.243 | O10: 26914.327 | P10: 39629.908 | Q10: 57039.791 | R10: 78444.668 | S10: 96277.662 | T10: 115505.58 | U10: 138573.57 | V10: 166248.53 | W10: 194962.27 | X10: 218461.03 | Y10: 233898.81
A11: 3 | B11: 2 | C11: 2151.7122 | D11: 2009.695 | E11: 1529.3751 | F11: 1564.5833 | G11: 2959.1684 | H11: 4163.3207 | I11: 6869.1468 | J11: 10829.2 | K11: 16312.503 | L11: 24019.288 | M11: 34571.243 | N11: 47544.523 | O11: 71618.416 | P11: 98494.1 | Q11: 138573.57 | R11: 177996.66 | S11: 223490.28 | T11: 307357.74 | U11: 377230.03 | V11: 462986.54 | W11: 581319.85 | X11: 651386.2 | Y11: 781476.6
A12: 3 | B12: 3 | C12: 132407.03 | D12: 138573.57 | E12: 145027.3 | F12: 148366.01 | G12: 158850.46 | H12: 170075.79 | I12: 182094.38 | J12: 199450.56 | K12: 218461.03 | L12: 244792.08 | M12: 287071.52 | N12: 344403.49 | O12: 413185.41 | P12: 473645.1 | Q12: 581319.85 | R12: 713472.54 | S12: 855962.41 | T12: 1050550.2 | U12: 1231996.7 | V12: 1380489 | W12: 1618921.2 | X12: 1656190.8 | Y12: 1855811.1
A13: 3 | B13: 4 | C13: 168.15128 | D13: 1364.8679 | E13: 5227.4111 | F13: 8823.3654 | G13: 17072.218 | H13: 29479.644 | I13: 43407.201 | J13: 63914.783 | K13: 87899.584 | L13: 110365.57 | M13: 170075.79 | N13: 228635.32 | O13: 280611.48 | P13: 336653.29 | Q13: 403887.39 | R13: 484549.03 | S13: 608393.43 | T13: 697417.09 | U13: 763890.84 | V13: 855962.41 | W13: 1003800.6 | X13: 959131.36 | Y13: 1150682.5
A14: 4 | B14: 1 | C14: 0.66089431 | D14: 0.7961412 | E14: 1.5479929 | F14: 2.0741095 | G14: 3.8239152 | H14: 6.684709 | I14: 14.846263 | J14: 20.978874 | K14: 45.369676 | L14: 93.035108 | M14: 195.9202 | N14: 423.70414 | O14: 966.38129 | P14: 2035.0771 | Q14: 3557.5836 | R14: 6917.2583 | S14: 11164.899 | T14: 17547.871 | U14: 27579.987 | V14: 41101.852 | W14: 59645.483
A15: 4 | B15: 2 | C15: 19.36996 | D15: 26.652784 | E15: 50.462678 | F15: 67.613435 | G15: 100.76282 | H15: 146.22327 | I15: 206.62436 | J15: 291.97558 | K15: 423.70414 | L15: 702.31938 | M15: 1074.8631 | N15: 1689.3622 | O15: 2655.1705 | P15: 4519.7614 | Q15: 7295.1849 | R15: 12418.222 | S15: 20043.806 | T15: 35039.222 | U15: 52218.186 | V15: 75777.095 | W15: 109964.91
A16: 4 | B16: 3 | C16: 75.203426 | D16: 83.645435 | E16: 162.63766 | F16: 185.77056 | G16: 206.62436 | H16: 299.84561 | I16: 401.75417 | J16: 583.01076 | K16: 846.04359 | L16: 1195.5225 | M16: 1829.6846 | N16: 2655.1705 | O16: 4285.6155 | P16: 6917.2583 | Q16: 11164.899 | R16: 18020.863 | S16: 26856.097 | T16: 46948.007 | U16: 68129.207 | V16: 98866.579 | W16: 139705.83
A17: 5 | B17: 1 | C17: 8.3623838 | D17: 9.6548029 | E17: 10.970386 | F17: 11.146967 | G17: 12.465233 | H17: 14.623406 | I17: 17.711947 | J17: 19.806603 | K17: 22.505491 | L17: 25.983748 | M17: 29.524347 | N17: 31.978226 | O17: 36.335645 | P17: 38.118632 | Q17: 41.951374 | R17: 46.169488 | S17: 51.629599 | T17: 58.664754 | U17: 63.540601 | V17: 71.055059 | W17: 82.036726 | X17: 88.855105 | Y17: 104.23907 | Z17: 116.56662 | AA17: 138.94955 | AB17: 163.00663 | AC17: 191.22884 | AD17: 227.94829 | AE17: 276.09217 | AF17: 339.78692 | AG17: 424.90715 | AH17: 514.64978 | AI17: 653.93409 | AJ17: 792.04842 | AK17: 1022.6069 | AL17: 1299.3643 | AM17: 1651.023 | AN17: 2064.6218 | AO17: 2752.1185 | AP17: 3910.5065 | AQ17: 5468.4479 | AR17: 8828.9379 | AS17: 16991.659
A18: 5 | B18: 2 | C18: 362.19788 | D18: 418.17611 | E18: 460.22277 | F18: 490.57719 | G18: 514.64978 | H18: 514.64978 | I18: 575.51345 | J18: 603.75386 | K18: 633.38001 | L18: 633.38001 | M18: 643.575 | N18: 719.68567 | O18: 708.285 | P18: 708.285 | Q18: 731.26985 | R18: 767.15321 | S18: 792.04842 | T18: 792.04842 | U18: 830.91418 | V18: 885.7179 | W18: 899.97457 | X18: 857.87853 | Y18: 857.87853 | Z18: 871.68708 | AA18: 914.46071 | AB18: 929.18002 | AC18: 1039.067 | AD18: 1039.067 | AE18: 990.46495 | AF18: 1107.5996 | AG18: 1143.5428 | AH18: 1180.6524 | AI18: 1299.3643 | AJ18: 1299.3643 | AK18: 1320.2791 | AL18: 1453.0301 | AM18: 1524.3302 | AN18: 1817.0296 | AO18: 2200.7958 | AP18: 2933.637 | AQ18: 4372.972 | AR18: 7770.1599 | AS18: 16991.659
A19: 5 | B19: 3 | C19: 168.29643 | D19: 217.28608 | E19: 246.89392 | F19: 280.5362 | G19: 323.89349 | H19: 362.19788 | I19: 418.17611 | J19: 445.75731 | K19: 490.57719 | L19: 539.90361 | M19: 584.77701 | N19: 633.38001 | O19: 767.15321 | P19: 817.75152 | Q19: 899.97457 | R19: 1006.4076 | S19: 1072.7862 | T19: 1180.6524 | U19: 1407.3593 | V19: 1599.129 | W19: 1677.5981 | X19: 1817.0296 | Y19: 2131.6217 | Z19: 2272.2148 | AA19: 2422.0808 | AB19: 2933.637 | AC19: 3077.5904 | AD19: 3333.3804 | AE19: 4037.408 | AF19: 4372.972 | AG19: 4661.3955 | AH19: 5381.8212 | AI19: 6115.1592 | AJ19: 6623.4129 | AK19: 7406.7131 | AL19: 7895.2297 | AM19: 8828.9379 | AN19: 9411.2587 | AO19: 10357.539 | AP19: 12150.796 | AQ19: 12952.213 | AR19: 17265.16 | AS19: 24532.199
A20: 5 | B20: 4 | C20: 73.773048 | D20: 89.768713 | E20: 109.2326 | F20: 118.53965 | G20: 128.63969 | H20: 139.6003 | I20: 151.4948 | J20: 159.11259 | K20: 172.66961 | L20: 184.3423 | M20: 190.4713 | N20: 206.70021 | O20: 224.31188 | P20: 235.59121 | Q20: 251.51749 | R20: 272.94777 | S20: 282.02272 | T20: 301.08782 | U20: 316.22777 | V20: 348.82985 | W20: 378.55152 | X20: 384.7931 | Y20: 417.57899 | Z20: 468.22494 | AA20: 491.76924 | AB20: 551.41335 | AC20: 588.6896 | AD20: 660.08866 | AE20: 704.71151 | AF20: 728.14171 | AG20: 829.91591 | AH20: 915.47761 | AI20: 977.36508 | AJ20: 1113.9739 | AK20: 1208.8888 | AL20: 1377.8583 | AM20: 1570.445 | AN20: 1789.95 | AO20: 2287.5732 | AP20: 3172.6375 | AQ20: 4546.4294 | AR20: 7927.7095 | AS20: 16821.018
A21: 5 | B21: 5 | C21: 5.4781808 | D21: 7.850302 | E21: 9.0950862 | F21: 9.552425 | G21: 10.710988 | H21: 11.815257 | I21: 12.613984 | J21: 13.688745 | K21: 15.100011 | L21: 15.602055 | M21: 16.931412 | N21: 18.374035 | O21: 19.939576 | P21: 22.357942 | Q21: 23.869367 | R21: 25.069619 | S21: 28.110181 | T21: 31.519516 | U21: 31.519516 | V21: 33.650276 | W21: 38.986037 | X21: 43.005374 | Y21: 48.221269 | Z21: 51.481089 | AA21: 57.724959 | AB21: 63.67622 | AC21: 71.399173 | AD21: 76.225849 | AE21: 88.312611 | AF21: 105.71771 | AG21: 118.53965 | AH21: 139.6003 | AI21: 159.11259 | AJ21: 190.4713 | AK21: 243.42414 | AL21: 311.09836 | AM21: 372.41119 | AN21: 569.7467 | AO21: 843.5996 | AP21: 1570.445 | AQ21: 2694.0008 | AR21: 5623.4133 | AS21: 15001.558
A22: 5 | B22: 6 | C22: 3.1934591 | D22: 4.0812712 | E22: 4.8063809 | F22: 5.4781808 | G22: 6.5578483 | H22: 6.8876042 | I22: 7.5976943 | J22: 7.850302 | K22: 8.5191787 | L22: 8.9475585 | M22: 9.397479 | N22: 9.552425 | O22: 9.8700234 | P22: 10.366329 | Q22: 10.53725 | R22: 11.623607 | S22: 12.409378 | T22: 13.248268 | U22: 13.914446 | V22: 15.348981 | W22: 16.120792 | X22: 17.494347 | Y22: 18.676987 | Z22: 20.94222 | AA22: 23.869367 | AB22: 26.330223 | AC22: 29.044786 | AD22: 34.769079 | AE22: 42.307801 | AF22: 49.016343 | AG22: 61.627241 | AH22: 74.989421 | AI22: 91.248823 | AJ22: 114.72527 | AK22: 151.4948 | AL22: 210.10829 | AM22: 301.08782 | AN22: 453.15836 | AO22: 764.75571 | AP22: 1570.445 | AQ22: 2876.1188 | AR22: 6622.5116 | AS22: 17098.363
A23: 6 | B23: 1 | C23: 15.091406 | D23: 21.789989 | E23: 25.135957 | F23: 27.273818 | G23: 27.836111 | H23: 41.865969 | I23: 48.294709 | J23: 54.585254 | K23: 62.967107 | L23: 68.322579 | M23: 66.942453 | N23: 72.636037 | O23: 102.75828 | P23: 116.14289 | Q23: 148.36934 | R23: 189.53775 | S23: 252.21594 | T23: 322.19892 | U23: 465.21253 | V23: 644.84223 | W23: 875.77574 | X23: 1165.3858 | Y23: 1582.7385 | Z23: 2106.1338 | AA23: 2979.5499 | AB23: 3884.7658 | AC23: 4862.4345 | AD23: 6470.3918 | AE23: 8265.7474 | AF23: 10559.265 | AG23: 13216.687 | AH23: 16883.954 | AI23: 21133.093 | AJ23: 22930.503 | AK23: 26996.945
A24: 6 | B24: 2 | C24: 1141.8448 | D24: 1488.7483 | E24: 1752.7594 | F24: 2021.9048 | G24: 2063.5896 | H24: 2285.2646 | I24: 2582.9278 | J24: 2690.528 | K24: 2802.6107 | L24: 2979.5499 | M24: 3167.6599 | N24: 3367.6461 | O24: 3654.0708 | P24: 4130.0255 | Q24: 4573.6811 | R24: 5169.418 | S24: 5963.2094 | T24: 6603.7893 | U24: 7165.4542 | V24: 7935.1816 | W24: 8787.5946 | X24: 10345.966 | Y24: 11934.644 | Z24: 13489.17 | AA24: 15560.503 | AB24: 18319.966 | AC24: 21568.786 | AD24: 24378.191 | AE24: 29293.087 | AF24: 35924.558 | AG24: 42295.335 | AH24: 46838.784 | AI24: 55145.064 | AJ24: 59835.257 | AK24: 69023.276
A25: 6 | B25: 3 | C25: 7935.1816 | D25: 7774.8897 | E25: 7774.8897 | F25: 8436.159 | G25: 8787.5946 | H25: 9342.3881 | I25: 9342.3881 | J25: 10345.966 | K25: 10999.145 | L25: 12431.82 | M25: 14340.791 | N25: 15560.503 | O25: 17949.9 | P25: 19083.144 | Q25: 21133.093 | R25: 23403.253 | S25: 25917.277 | T25: 29293.087 | U25: 32439.809 | V25: 35198.877 | W25: 38980.01 | X25: 44057.284 | Y25: 49795.89 | Z25: 54031.126 | AA25: 61068.857 | AB25: 67628.996 | AC25: 78013.784 | AD25: 86394.181 | AE25: 101715.12 | AF25: 112641.56 | AG25: 127313.5 | AH25: 146863.15 | AI25: 152981.22 | AJ25: 156135.17 | AK25: 162639.49
A26: 6 | B26: 4 | C26: 21568.786 | D26: 19083.144 | E26: 20287.934 | F26: 20706.202 | G26: 22013.461 | H26: 22930.503 | I26: 24880.787 | J26: 26451.603 | K26: 27553.53 | L26: 29293.087 | M26: 31142.468 | N26: 35198.877 | O26: 37421.112 | P26: 38980.01 | Q26: 40603.849 | R26: 44965.596 | S26: 46838.784 | T26: 47804.441 | U26: 56281.968 | V26: 56281.968 | W26: 62327.89 | X26: 66262.88 | Y26: 74893.838 | Z26: 81263.702 | AA26: 84649.006 | AB26: 89993.211 | AC26: 105952.4 | AD26: 122221.94 | AE26: 132617.15 | AF26: 140989.77 | AG26: 162639.49 | AH26: 180110.55 | AI26: 191481.59 | AJ26: 156135.17 | AK26: 140989.77
A27: 7 | B27: 1 | C27: 1.8968234 | D27: 5.2178163 | E27: 15.270614 | F27: 45.623944 | G27: 133.52437 | H27: 345.23641 | I27: 741.2337 | J27: 1465.2755 | K27: 2666.9137 | L27: 4657.5919 | M27: 7645.5384 | N27: 11555.275 | O27: 17828.757 | P27: 24809.547 | Q27: 35244.001 | R27: 47059.33 | S27: 59060.953 | T27: 75670.006 | U27: 91125.779 | V27: 109738.43 | W27: 129451.66 | X27: 152706.14
A28: 7 | B28: 2 | C28: 8303.9077 | D28: 9018.9702 | E28: 12550.317 | F28: 21031.486 | G28: 36730.126 | H28: 68246.552 | I28: 129451.66 | J28: 195649.99 | K28: 314599.37 | L28: 465759.19 | M28: 675454.99
A29: 8 | B29: 1 | C29: 6874.0686 | D29: 6236.9598 | E29: 5275.7079 | F29: 4359.1654 | G29: 3643.8152 | H29: 3163.1893 | I29: 2682.5633 | J29: 2201.9374 | K29: 1631.8927 | L29: 1151.2668 | M29: 815.94635 | N29: 558.86736 | O29: 402.3845 | P29: 223.54694
A30: 8 | B30: 2 | C30: 7522.3547 | D30: 6762.2951 | E30: 5678.0924 | F30: 4817.4367 | G30: 4102.0864 | H30: 3587.9285 | I30: 3040.2385 | J30: 2369.5976 | K30: 1732.4888 | L30: 1274.2176 | M30: 961.25186 | N30: 760.05961 | O30: 581.22206 | P30: 424.7392
A31: 8 | B31: 3 | C31: 7622.9508 | D31: 7108.7928 | E31: 6315.2012 | F31: 5208.6438 | G31: 4415.0522 | H31: 3856.1848 | I31: 3375.5589 | J31: 2894.9329 | K31: 2302.5335 | L31: 1643.07 | M31: 1274.2176 | N31: 994.7839 | O31: 793.59165 | P31: 558.86736
A32: 8 | B32: 4 | C32: 4046.1997 | D32: 3643.8152 | E32: 3084.9478 | F32: 2604.3219 | G32: 2257.8241 | H32: 1967.2131 | I32: 1687.7794 | J32: 1430.7004 | K32: 1117.7347 | L32: 894.18778 | M32: 670.64083 | N32: 536.51267 | O32: 357.67511 | P32: 212.3696
A33: 9 | B33: 1 | C33: 2779.4524 | D33: 2835.9128 | E33: 2742.4381 | F33: 2705.9166 | G33: 2616.7267 | H33: 2303.8034 | I33: 1490.105 | J33: 944.61477 | K33: 722.44769 | L33: 586.89303 | M33: 445.86093 | N33: 321.0334 | O33: 239.03256 | P33: 174.43365
A34: 9 | B34: 2 | C34: 3444.4343 | D34: 3375.8588 | E34: 3375.8588 | F34: 3286.544 | G34: 3052.9252 | H34: 2599.2447 | I34: 1658.8084 | J34: 1016.8995 | K34: 757.15512 | L34: 627.5828 | M34: 483.20778 | N34: 347.92426 | O34: 271.50011 | P34: 207.6451
A35: 9 | B35: 3 | C35: 3242.7766 | D35: 3199.5921 | E35: 3114.9407 | F35: 3156.9827 | G35: 2932.5735 | H35: 2530.4766 | I35: 1625.783 | J35: 1030.6244 | K35: 767.37435 | L35: 606.897 | M35: 470.42358 | N35: 329.75778 | O35: 250.51603 | P35: 181.59234
A36: 9 | B36: 4 | C36: 3398.5643 | D36: 3375.8588 | E36: 3286.544 | F36: 3242.7766 | G36: 3073.4586 | H36: 2652.0444 | I36: 1750.1928 | J36: 1080.1371 | K36: 777.73151 | L36: 644.63795 | M36: 493.02341 | N36: 329.75778 | O36: 125.59752
A37: 11 | B37: 1a
A38: 11 | B38: 2a
A39: 11 | B39: 3a
A40: 11 | B40: 4a
...

Sheet converted_MPa_Storage_modulus_G
A1: Study_id | B1: Instance
A2: 1 | B2: 1
A3: 1 | B3: 2
A4: 1 | B4: 3
A5: 1 | B5: 4
A6: 1 | B6: 5
A7: 2 | B7: 1 | C7: =Storage_modulus_G!C7/1000000 -> 7.8116806e-05 | D7: =Storage_modulus_G!D7/1000000 -> 0.00011030285 | E7: =Storage_modulus_G!E7/1000000 -> 0.00016151092 | F7: =Storage_modulus_G!F7/1000000 -> 0.00024082605 | G7: =Storage_modulus_G!G7/1000000 -> 0.00036567181 | H7: =Storage_modulus_G!H7/1000000 -> 0.00054524672 | I7: =Storage_modulus_G!I7/1000000 -> 0.00075604718 | J7: =Storage_modulus_G!J7/1000000 -> 0.0010109551 | ... M7: =Storage_modulus_G!M7/1000000 -> 0.002552349
A8: 2 | B8: 2 | C8: =Storage_modulus_G!C8/1000000 -> 2.2640686e-06 | D8: =Storage_modulus_G!D8/1000000 -> 2.4346432e-06 | E8: =Storage_modulus_G!E8/1000000 -> 2.7646514e-06 | F8: =Storage_modulus_G!F8/1000000 -> 2.9729398e-06 | G8: =Storage_modulus_G!G8/1000000 -> 3.4377762e-06 | H8: =Storage_modulus_G!H8/1000000 -> 3.9037559e-06 | I8: =Storage_modulus_G!I8/1000000 -> 4.5968525e-06 | J8: =Storage_modulus_G!J8/1000000 -> 6.2593606e-06 | ... M8: =Storage_modulus_G!M8/1000000 -> 2.8773357e-05
A9: 2 | B9: 3 | C9: =Storage_modulus_G!C9/1000000 -> 0.00069042533 | D9: =Storage_modulus_G!D9/1000000 -> 0.00084307752 | E9: =Storage_modulus_G!E9/1000000 -> 0.0010675572 | F9: =Storage_modulus_G!F9/1000000 -> 0.0014536524 | G9: =Storage_modulus_G!G9/1000000 -> 0.0020156559 | H9: =Storage_modulus_G!H9/1000000 -> 0.002599121 | I9: =Storage_modulus_G!I9/1000000 -> 0.0036700229 | J9: =Storage_modulus_G!J9/1000000 -> 0.0048190929 | ... M9: =Storage_modulus_G!M9/1000000 -> 0.012616717
A10: 3 | B10: 1 | C10: =Storage_modulus_G!C10/1000000 -> 2.3747494e-05 | D10: =Storage_modulus_G!D10/1000000 -> 1.4724465e-05 | E10: =Storage_modulus_G!E10/1000000 -> 2.1193096e-05 | F10: =Storage_modulus_G!F10/1000000 -> 4.0083479e-05 | G10: =Storage_modulus_G!G10/1000000 -> 0.00016436732 | H10: =Storage_modulus_G!H10/1000000 -> 0.00033284384 | I10: =Storage_modulus_G!I10/1000000 -> 0.00090607968 | J10: =Storage_modulus_G!J10/1000000 -> 0.0016751462 | ... Y10: =Storage_modulus_G!Y10/1000000 -> 0.23389881
A11: 3 | B11: 2 | C11: =Storage_modulus_G!C11/1000000 -> 0.0021517122 | D11: =Storage_modulus_G!D11/1000000 -> 0.002009695 | E11: =Storage_modulus_G!E11/1000000 -> 0.0015293751 | F11: =Storage_modulus_G!F11/1000000 -> 0.0015645833 | G11: =Storage_modulus_G!G11/1000000 -> 0.0029591684 | H11: =Storage_modulus_G!H11/1000000 -> 0.0041633207 | I11: =Storage_modulus_G!I11/1000000 -> 0.0068691468 | J11: =Storage_modulus_G!J11/1000000 -> 0.0108292 | ... Y11: =Storage_modulus_G!Y11/1000000 -> 0.7814766
A12: 3 | B12: 3 | C12: =Storage_modulus_G!C12/1000000 -> 0.13240703 | D12: =Storage_modulus_G!D12/1000000 -> 0.13857357 | E12: =Storage_modulus_G!E12/1000000 -> 0.1450273 | F12: =Storage_modulus_G!F12/1000000 -> 0.14836601 | G12: =Storage_modulus_G!G12/1000000 -> 0.15885046 | H12: =Storage_modulus_G!H12/1000000 -> 0.17007579 | I12: =Storage_modulus_G!I12/1000000 -> 0.18209438 | J12: =Storage_modulus_G!J12/1000000 -> 0.19945056 | ... Y12: =Storage_modulus_G!Y12/1000000 -> 1.8558111
A13: 3 | B13: 4 | C13: =Storage_modulus_G!C13/1000000 -> 0.00016815128 | D13: =Storage_modulus_G!D13/1000000 -> 0.0013648679 | E13: =Storage_modulus_G!E13/1000000 -> 0.0052274111 | F13: =Storage_modulus_G!F13/1000000 -> 0.0088233654 | G13: =Storage_modulus_G!G13/1000000 -> 0.017072218 | H13: =Storage_modulus_G!H13/1000000 -> 0.029479644 | I13: =Storage_modulus_G!I13/1000000 -> 0.043407201 | J13: =Storage_modulus_G!J13/1000000 -> 0.063914783 | ... Y13: =Storage_modulus_G!Y13/1000000 -> 1.1506825
A14: 4 | B14: 1 | C14: =Storage_modulus_G!C14/1000000 -> 6.6089431e-07 | D14: =Storage_modulus_G!D14/1000000 -> 7.961412e-07 | E14: =Storage_modulus_G!E14/1000000 -> 1.5479929e-06 | F14: =Storage_modulus_G!F14/1000000 -> 2.0741095e-06 | G14: =Storage_modulus_G!G14/1000000 -> 3.8239152e-06 | H14: =Storage_modulus_G!H14/1000000 -> 6.684709e-06 | I14: =Storage_modulus_G!I14/1000000 -> 1.4846263e-05 | J14: =Storage_modulus_G!J14/1000000 -> 2.0978874e-05 | ... W14: =Storage_modulus_G!W14/1000000 -> 0.059645483
A15: 4 | B15: 2 | C15: =Storage_modulus_G!C15/1000000 -> 1.936996e-05 | D15: =Storage_modulus_G!D15/1000000 -> 2.6652784e-05 | E15: =Storage_modulus_G!E15/1000000 -> 5.0462678e-05 | F15: =Storage_modulus_G!F15/1000000 -> 6.7613435e-05 | G15: =Storage_modulus_G!G15/1000000 -> 0.00010076282 | H15: =Storage_modulus_G!H15/1000000 -> 0.00014622327 | I15: =Storage_modulus_G!I15/1000000 -> 0.00020662436 | J15: =Storage_modulus_G!J15/1000000 -> 0.00029197558 | ... W15: =Storage_modulus_G!W15/1000000 -> 0.10996491
A16: 4 | B16: 3 | C16: =Storage_modulus_G!C16/1000000 -> 7.5203426e-05 | D16: =Storage_modulus_G!D16/1000000 -> 8.3645435e-05 | E16: =Storage_modulus_G!E16/1000000 -> 0.00016263766 | F16: =Storage_modulus_G!F16/1000000 -> 0.00018577056 | G16: =Storage_modulus_G!G16/1000000 -> 0.00020662436 | H16: =Storage_modulus_G!H16/1000000 -> 0.00029984561 | I16: =Storage_modulus_G!I16/1000000 -> 0.00040175417 | J16: =Storage_modulus_G!J16/1000000 -> 0.00058301076 | ... W16: =Storage_modulus_G!W16/1000000 -> 0.13970583
A17: 5 | B17: 1 | C17: =Storage_modulus_G!C17/1000000 -> 8.3623838e-06 | D17: =Storage_modulus_G!D17/1000000 -> 9.6548029e-06 | E17: =Storage_modulus_G!E17/1000000 -> 1.0970386e-05 | F17: =Storage_modulus_G!F17/1000000 -> 1.1146967e-05 | G17: =Storage_modulus_G!G17/1000000 -> 1.2465233e-05 | H17: =Storage_modulus_G!H17/1000000 -> 1.4623406e-05 | I17: =Storage_modulus_G!I17/1000000 -> 1.7711947e-05 | J17: =Storage_modulus_G!J17/1000000 -> 1.9806603e-05 | ... AS17: =Storage_modulus_G!AS17/1000000 -> 0.016991659
A18: 5 | B18: 2 | C18: =Storage_modulus_G!C18/1000000 -> 0.00036219788 | D18: =Storage_modulus_G!D18/1000000 -> 0.00041817611 | E18: =Storage_modulus_G!E18/1000000 -> 0.00046022277 | F18: =Storage_modulus_G!F18/1000000 -> 0.00049057719 | G18: =Storage_modulus_G!G18/1000000 -> 0.00051464978 | H18: =Storage_modulus_G!H18/1000000 -> 0.00051464978 | I18: =Storage_modulus_G!I18/1000000 -> 0.00057551345 | J18: =Storage_modulus_G!J18/1000000 -> 0.00060375386 | ... AS18: =Storage_modulus_G!AS18/1000000 -> 0.016991659
A19: 5 | B19: 3 | C19: =Storage_modulus_G!C19/1000000 -> 0.00016829643 | D19: =Storage_modulus_G!D19/1000000 -> 0.00021728608 | E19: =Storage_modulus_G!E19/1000000 -> 0.00024689392 | F19: =Storage_modulus_G!F19/1000000 -> 0.0002805362 | G19: =Storage_modulus_G!G19/1000000 -> 0.00032389349 | H19: =Storage_modulus_G!H19/1000000 -> 0.00036219788 | I19: =Storage_modulus_G!I19/1000000 -> 0.00041817611 | J19: =Storage_modulus_G!J19/1000000 -> 0.00044575731 | ... AS19: =Storage_modulus_G!AS19/1000000 -> 0.024532199
A20: 5 | B20: 4 | C20: =Storage_modulus_G!C20/1000000 -> 7.3773048e-05 | D20: =Storage_modulus_G!D20/1000000 -> 8.9768713e-05 | E20: =Storage_modulus_G!E20/1000000 -> 0.0001092326 | F20: =Storage_modulus_G!F20/1000000 -> 0.00011853965 | G20: =Storage_modulus_G!G20/1000000 -> 0.00012863969 | H20: =Storage_modulus_G!H20/1000000 -> 0.0001396003 | I20: =Storage_modulus_G!I20/1000000 -> 0.0001514948 | J20: =Storage_modulus_G!J20/1000000 -> 0.00015911259 | ... AS20: =Storage_modulus_G!AS20/1000000 -> 0.016821018
A21: 5 | B21: 5 | C21: =Storage_modulus_G!C21/1000000 -> 5.4781808e-06 | D21: =Storage_modulus_G!D21/1000000 -> 7.850302e-06 | E21: =Storage_modulus_G!E21/1000000 -> 9.0950862e-06 | F21: =Storage_modulus_G!F21/1000000 -> 9.552425e-06 | G21: =Storage_modulus_G!G21/1000000 -> 1.0710988e-05 | H21: =Storage_modulus_G!H21/1000000 -> 1.1815257e-05 | I21: =Storage_modulus_G!I21/1000000 -> 1.2613984e-05 | J21: =Storage_modulus_G!J21/1000000 -> 1.3688745e-05 | ... AS21: =Storage_modulus_G!AS21/1000000 -> 0.015001558
A22: 5 | B22: 6 | C22: =Storage_modulus_G!C22/1000000 -> 3.1934591e-06 | D22: =Storage_modulus_G!D22/1000000 -> 4.0812712e-06 | E22: =Storage_modulus_G!E22/1000000 -> 4.8063809e-06 | F22: =Storage_modulus_G!F22/1000000 -> 5.4781808e-06 | G22: =Storage_modulus_G!G22/1000000 -> 6.5578483e-06 | H22: =Storage_modulus_G!H22/1000000 -> 6.8876042e-06 | I22: =Storage_modulus_G!I22/1000000 -> 7.5976943e-06 | J22: =Storage_modulus_G!J22/1000000 -> 7.850302e-06 | ... AS22: =Storage_modulus_G!AS22/1000000 -> 0.017098363
A23: 6 | B23: 1 | C23: =Storage_modulus_G!C23/1000000 -> 1.5091406e-05 | D23: =Storage_modulus_G!D23/1000000 -> 2.1789989e-05 | E23: =Storage_modulus_G!E23/1000000 -> 2.5135957e-05 | F23: =Storage_modulus_G!F23/1000000 -> 2.7273818e-05 | G23: =Storage_modulus_G!G23/1000000 -> 2.7836111e-05 | H23: =Storage_modulus_G!H23/1000000 -> 4.1865969e-05 | I23: =Storage_modulus_G!I23/1000000 -> 4.8294709e-05 | J23: =Storage_modulus_G!J23/1000000 -> 5.4585254e-05 | ... AK23: =Storage_modulus_G!AK23/1000000 -> 0.026996945
A24: 6 | B24: 2 | C24: =Storage_modulus_G!C24/1000000 -> 0.0011418448 | D24: =Storage_modulus_G!D24/1000000 -> 0.0014887483 | E24: =Storage_modulus_G!E24/1000000 -> 0.0017527594 | F24: =Storage_modulus_G!F24/1000000 -> 0.0020219048 | G24: =Storage_modulus_G!G24/1000000 -> 0.0020635896 | H24: =Storage_modulus_G!H24/1000000 -> 0.0022852646 | I24: =Storage_modulus_G!I24/1000000 -> 0.0025829278 | J24: =Storage_modulus_G!J24/1000000 -> 0.002690528 | ... AK24: =Storage_modulus_G!AK24/1000000 -> 0.069023276
A25: 6 | B25: 3 | C25: =Storage_modulus_G!C25/1000000 -> 0.0079351816 | D25: =Storage_modulus_G!D25/1000000 -> 0.0077748897 | E25: =Storage_modulus_G!E25/1000000 -> 0.0077748897 | F25: =Storage_modulus_G!F25/1000000 -> 0.008436159 | G25: =Storage_modulus_G!G25/1000000 -> 0.0087875946 | H25: =Storage_modulus_G!H25/1000000 -> 0.0093423881 | I25: =Storage_modulus_G!I25/1000000 -> 0.0093423881 | J25: =Storage_modulus_G!J25/1000000 -> 0.010345966 | ... AK25: =Storage_modulus_G!AK25/1000000 -> 0.16263949
A26: 6 | B26: 4 | C26: =Storage_modulus_G!C26/1000000 -> 0.021568786 | D26: =Storage_modulus_G!D26/1000000 -> 0.019083144 | E26: =Storage_modulus_G!E26/1000000 -> 0.020287934 | F26: =Storage_modulus_G!F26/1000000 -> 0.020706202 | G26: =Storage_modulus_G!G26/1000000 -> 0.022013461 | H26: =Storage_modulus_G!H26/1000000 -> 0.022930503 | I26: =Storage_modulus_G!I26/1000000 -> 0.024880787 | J26: =Storage_modulus_G!J26/1000000 -> 0.026451603 | ... AK26: =Storage_modulus_G!AK26/1000000 -> 0.14098977
A27: 7 | B27: 1 | C27: =Storage_modulus_G!C27/1000000 -> 1.8968234e-06 | D27: =Storage_modulus_G!D27/1000000 -> 5.2178163e-06 | E27: =Storage_modulus_G!E27/1000000 -> 1.5270614e-05 | F27: =Storage_modulus_G!F27/1000000 -> 4.5623944e-05 | G27: =Storage_modulus_G!G27/1000000 -> 0.00013352437 | H27: =Storage_modulus_G!H27/1000000 -> 0.00034523641 | I27: =Storage_modulus_G!I27/1000000 -> 0.0007412337 | J27: =Storage_modulus_G!J27/1000000 -> 0.0014652755 | ... X27: =Storage_modulus_G!X27/1000000 -> 0.15270614
A28: 7 | B28: 2 | C28: =Storage_modulus_G!C28/1000000 -> 0.0083039077 | D28: =Storage_modulus_G!D28/1000000 -> 0.0090189702 | E28: =Storage_modulus_G!E28/1000000 -> 0.012550317 | F28: =Storage_modulus_G!F28/1000000 -> 0.021031486 | G28: =Storage_modulus_G!G28/1000000 -> 0.036730126 | H28: =Storage_modulus_G!H28/1000000 -> 0.068246552 | I28: =Storage_modulus_G!I28/1000000 -> 0.12945166 | J28: =Storage_modulus_G!J28/1000000 -> 0.19564999 | ... M28: =Storage_modulus_G!M28/1000000 -> 0.67545499
A29: 8 | B29: 1 | C29: 6874.0686 | D29: 6236.9598 | E29: 5275.7079 | F29: 4359.1654 | G29: 3643.8152 | H29: 3163.1893 | I29: 2682.5633 | J29: 2201.9374 | K29: 1631.8927 | L29: 1151.2668 | M29: 815.94635 | N29: 558.86736 | O29: 402.3845 | P29: 223.54694
A30: 8 | B30: 2 | C30: 7522.3547 | D30: 6762.2951 | E30: 5678.0924 | F30: 4817.4367 | G30: 4102.0864 | H30: 3587.9285 | I30: 3040.2385 | J30: 2369.5976 | K30: 1732.4888 | L30: 1274.2176 | M30: 961.25186 | N30: 760.05961 | O30: 581.22206 | P30: 424.7392
A31: 8 | B31: 3 | C31: 7622.9508 | D31: 7108.7928 | E31: 6315.2012 | F31: 5208.6438 | G31: 4415.0522 | H31: 3856.1848 | I31: 3375.5589 | J31: 2894.9329 | K31: 2302.5335 | L31: 1643.07 | M31: 1274.2176 | N31: 994.7839 | O31: 793.59165 | P31: 558.86736
A32: 8 | B32: 4 | C32: 4046.1997 | D32: 3643.8152 | E32: 3084.9478 | F32: 2604.3219 | G32: 2257.8241 | H32: 1967.2131 | I32: 1687.7794 | J32: 1430.7004 | K32: 1117.7347 | L32: 894.18778 | M32: 670.64083 | N32: 536.51267 | O32: 357.67511 | P32: 212.3696
A33: 9 | B33: 1 | C33: 2779.4524 | D33: 2835.9128 | E33: 2742.4381 | F33: 2705.9166 | G33: 2616.7267 | H33: 2303.8034 | I33: 1490.105 | J33: 944.61477 | K33: 722.44769 | L33: 586.89303 | M33: 445.86093 | N33: 321.0334 | O33: 239.03256 | P33: 174.43365
A34: 9 | B34: 2 | C34: 3444.4343 | D34: 3375.8588 | E34: 3375.8588 | F34: 3286.544 | G34: 3052.9252 | H34: 2599.2447 | I34: 1658.8084 | J34: 1016.8995 | K34: 757.15512 | L34: 627.5828 | M34: 483.20778 | N34: 347.92426 | O34: 271.50011 | P34: 207.6451
A35: 9 | B35: 3 | C35: 3242.7766 | D35: 3199.5921 | E35: 3114.9407 | F35: 3156.9827 | G35: 2932.5735 | H35: 2530.4766 | I35: 1625.783 | J35: 1030.6244 | K35: 767.37435 | L35: 606.897 | M35: 470.42358 | N35: 329.75778 | O35: 250.51603 | P35: 181.59234
A36: 9 | B36: 4 | C36: 3398.5643 | D36: 3375.8588 | E36: 3286.544 | F36: 3242.7766 | G36: 3073.4586 | H36: 2652.0444 | I36: 1750.1928 | J36: 1080.1371 | K36: 777.73151 | L36: 644.63795 | M36: 493.02341 | N36: 329.75778 | O36: 125.59752
A37: 11 | B37: 1a
A38: 11 | B38: 2a
A39: 11 | B39: 3a
A40: 11 | B40: 4a
...

Sheet Loss_modulus_G
A1: Study_id | B1: Instance
A2: 1 | B2: 1
A3: 1 | B3: 2
A4: 1 | B4: 3
A5: 1 | B5: 4
A6: 1 | B6: 5
A7: 2 | B7: 1 | C7: 262.8283 | D7: 377.61495 | E7: 554.96078 | F7: 779.47695 | G7: 1094.8239 | H7: 1469.6473 | I7: 1972.795 | J7: 2474.2446 | K7: 2770.9134 | L7: 3475.2304 | M7: 3475.2304
A8: 2 | B8: 2 | C8: 35.015658 | D8: 49.181671 | E8: 67.53178 | F8: 90.651929 | G8: 136.27815 | H8: 209.56149 | I8: 301.08459 | J8: 432.57914 | K8: 680.43538 | L8: 1000 | M8: 1469.6473
A9: 2 | B9: 3 | C9: 1145.5562 | D9: 1469.6473 | E9: 2209.3387 | F9: 2965.7268 | G9: 4358.5724 | H9: 6262.1189 | I9: 8598.57 | J9: 12353.877 | K9: 16583.345 | L9: 25501.01 | M9: 40112.404
A10: 3 | B10: 1 | C10: 18.107198 | D10: 22.579744 | E10: 28.157026 | F10: 36.197426 | G10: 52.560702 | H10: 64.063634 | I10: 75.742362 | J10: 88.197149 | K10: 101.92118 | L10: 113.38235 | M10: 128.06723 | N10: 138.19613 | O10: 153.73645 | P10: 167.16313 | Q10: 176.31164 | R10: 180.38414 | S10: 187.38174 | T10: 194.6508 | U10: 199.1469 | V10: 203.74685 | W10: 199.1469 | X10: 203.74685 | Y10: 208.45306
A11: 3 | B11: 2 | C11: 65.543394 | D11: 62.142458 | E11: 65.543394 | F11: 70.727251 | G11: 82.357372 | H11: 93.734793 | I11: 106.68397 | J11: 124.22668 | K11: 138.19613 | L11: 156.0948 | M11: 169.72744 | N11: 183.15126 | O11: 206.87236 | P11: 218.19409 | Q11: 231.89386 | R11: 244.58496 | S11: 259.94175 | T11: 270.02561 | U11: 276.26274 | V11: 289.17252 | W11: 293.60848 | X11: 314.4276 | Y11: 321.69034
A12: 3 | B12: 3 | C12: 151.41374 | D12: 151.41374 | E12: 152.57068 | F12: 152.57068 | G12: 168.44041 | H12: 184.5507 | I12: 191.70994 | J12: 206.87236 | K12: 221.54122 | L12: 237.25021 | M12: 252.14647 | N12: 272.08885 | O12: 286.97974 | P12: 307.32883 | Q12: 321.69034 | R12: 334.1696 | S12: 341.88835 | T12: 355.15115 | U12: 363.35453 | V12: 371.74739 | W12: 371.74739 | X12: 380.33412 | Y12: 389.11919
