Workbook

Sheet Physchem_properties
A1: Study_id | B1: Instance | C1: initial_scl PHA ratio | D1: initial_3HB ratio | E1: initial_3HV ratio | F1: initial_mcl PHA ratio | G1: 3HHx ratio | H1: 3HHp ratio | I1: 3HO ratio | J1: 3HN ratio | K1: 3HD ratio | L1: 3HUD ratio | M1: 3HDD ratio | N1: 3HTriD ratio | O1: 3HTTD ratio | P1: Unsaturated monomer ratio | Q1: Uknown monomer ratio | R1: Mw | S1: Mn | T1: Density | U1: Density_units | V1: PDI | W1: Additive | X1: Additive1_type | Y1: Additive1_name | Z1: Additive1_percentage | AA1: Additive_2 | AB1: Additive2_type | AC1: Additive2_name | AD1: Additive2_percentage | AE1: final_PHA_percentage | AF1: formulation_scl PHA ratio | AG1: formulation_3HB ratio | AH1: formulation_3HV ratio | AI1: formulation_mcl PHA ratio | AJ1: formulation_3HHx ratio | AK1: formulation_3HHp ratio | AL1: formulation_3HO ratio | AM1: formulation_3HN ratio | AN1: formulation_3HD ratio | AO1: formulation_3HUD ratio | AP1: formulation_3HDD ratio | AQ1: formulation_3HTriD ratio | AR1: formulation_3HTTD ratio | AS1: formulation_Unsaturated monomer ratio | AT1: formulation_Uknown monomer ratio | AV1: Row No
A2: 1 | B2: 1 | C2: 0 | D2: 0 | E2: 0 | F2: 100 | G2: 7.6 | H2: 0 | I2: 92.4 | J2: 0 | K2: 0 | L2: 0 | M2: 0 | N2: 0 | O2: 0 | P2: 0 | Q2: 0 | R2: 396000 | S2: 216000 | V2: 1.8 | W2: No | AA2: No | AE2: 100 | AF2: 0 | AG2: 0 | AH2: 0 | AI2: 100 | AJ2: 7.6 | AK2: 0 | AL2: 92.4 | AM2: 0 | AN2: 0 | AO2: 0 | AP2: 0 | AQ2: 0 | AR2: 0 | AS2: 0 | AT2: 0 | AV2: 1
A3: 1 | B3: 2 | C3: 0 | D3: 0 | E3: 0 | F3: 100 | G3: 7.6 | H3: 0 | I3: 92.4 | J3: 0 | K3: 0 | L3: 0 | M3: 0 | N3: 0 | O3: 0 | P3: 0 | Q3: 0 | R3: 396000 | S3: 216000 | V3: 1.8 | W3: Yes | X3: Filler | Y3: C15A | Z3: 1 | AA3: No | AE3: 99 | AF3: 0 | AG3: 0 | AH3: 0 | AI3: 99 | AJ3: 7.524 | AK3: 0 | AL3: 91.476 | AM3: 0 | AN3: 0 | AO3: 0 | AP3: 0 | AQ3: 0 | AR3: 0 | AS3: 0 | AT3: 0 | AV3: 2
A4: 1 | B4: 3 | C4: 0 | D4: 0 | E4: 0 | F4: 100 | G4: 7.6 | H4: 0 | I4: 92.4 | J4: 0 | K4: 0 | L4: 0 | M4: 0 | N4: 0 | O4: 0 | P4: 0 | Q4: 0 | R4: 396000 | S4: 216000 | V4: 1.8 | W4: Yes | X4: Filler | Y4: C15A | Z4: 2.5 | AA4: No | AE4: 97.5 | AF4: 0 | AG4: 0 | AH4: 0 | AI4: 97.5 | AJ4: 7.41 | AK4: 0 | AL4: 90.09 | AM4: 0 | AN4: 0 | AO4: 0 | AP4: 0 | AQ4: 0 | AR4: 0 | AS4: 0 | AT4: 0 | AV4: 3
A5: 1 | B5: 4 | C5: 0 | D5: 0 | E5: 0 | F5: 100 | G5: 7.6 | H5: 0 | I5: 92.4 | J5: 0 | K5: 0 | L5: 0 | M5: 0 | N5: 0 | O5: 0 | P5: 0 | Q5: 0 | R5: 396000 | S5: 216000 | V5: 1.8 | W5: Yes | X5: Filler | Y5: C15A | Z5: 5 | AA5: No | AE5: 95 | AF5: 0 | AG5: 0 | AH5: 0 | AI5: 95 | AJ5: 7.22 | AK5: 0 | AL5: 87.78 | AM5: 0 | AN5: 0 | AO5: 0 | AP5: 0 | AQ5: 0 | AR5: 0 | AS5: 0 | AT5: 0 | AV5: 4
A6: 2 | B6: 1 | C6: 0 | D6: 0 | E6: 0 | F6: 100 | G6: 12 | H6: 0 | I6: 48 | J6: 0 | K6: 31 | L6: 0 | M6: 8 | N6: 0 | O6: 1 | P6: 0 | Q6: 0 | R6: 30000 | V6: 1.5 | W6: No | AA6: No | AE6: 100 | AF6: 0 | AG6: 0 | AH6: 0 | AI6: 100 | AJ6: 12 | AK6: 0 | AL6: 48 | AM6: 0 | AN6: 31 | AO6: 0 | AP6: 8 | AQ6: 0 | AR6: 1 | AS6: 0 | AT6: 0 | AV6: 5
A7: 3 | B7: 1a | C7: 0 | D7: 0 | E7: 0 | F7: 100 | H7: 0 | I7: 86 | J7: 0 | L7: 0 | M7: 0 | N7: 0 | O7: 0 | P7: 0 | Q7: 14 | W7: No | AA7: No | AE7: 100 | AF7: 0 | AG7: 0 | AH7: 0 | AI7: 100 | AJ7: 0 | AK7: 0 | AL7: 86 | AM7: 0 | AN7: 0 | AO7: 0 | AP7: 0 | AQ7: 0 | AR7: 0 | AS7: 0 | AT7: 14 | AV7: 6
A8: 3 | B8: 2a | C8: 0 | D8: 0 | E8: 0 | F8: 100 | H8: 0 | I8: 86 | J8: 0 | L8: 0 | M8: 0 | N8: 0 | O8: 0 | P8: 0 | Q8: 14 | W8: Yes | X8: Reinforcement | Y8: CNW | Z8: 1 | AA8: No | AE8: 99 | AF8: 0 | AG8: 0 | AH8: 0 | AI8: 99 | AJ8: 0 | AK8: 0 | AL8: 85.14 | AM8: 0 | AN8: 0 | AO8: 0 | AP8: 0 | AQ8: 0 | AR8: 0 | AS8: 0 | AT8: 13.86 | AV8: 7
A9: 3 | B9: 3a | C9: 0 | D9: 0 | E9: 0 | F9: 100 | H9: 0 | I9: 86 | J9: 0 | L9: 0 | M9: 0 | N9: 0 | O9: 0 | P9: 0 | Q9: 14 | W9: Yes | X9: Reinforcement | Y9: CNW | Z9: 3 | AA9: No | AE9: 97 | AF9: 0 | AG9: 0 | AH9: 0 | AI9: 97 | AJ9: 0 | AK9: 0 | AL9: 83.42 | AM9: 0 | AN9: 0 | AO9: 0 | AP9: 0 | AQ9: 0 | AR9: 0 | AS9: 0 | AT9: 13.58 | AV9: 8
A10: 3 | B10: 4a | C10: 0 | D10: 0 | E10: 0 | F10: 100 | H10: 0 | I10: 86 | J10: 0 | L10: 0 | M10: 0 | N10: 0 | O10: 0 | P10: 0 | Q10: 14 | W10: Yes | X10: Reinforcement | Y10: CNW | Z10: 6 | AA10: No | AE10: 94 | AF10: 0 | AG10: 0 | AH10: 0 | AI10: 94 | AJ10: 0 | AK10: 0 | AL10: 80.84 | AM10: 0 | AN10: 0 | AO10: 0 | AP10: 0 | AQ10: 0 | AR10: 0 | AS10: 0 | AT10: 13.16 | AV10: 9
A11: 3 | B11: 1b | C11: 0 | D11: 0 | E11: 0 | F11: 100 | H11: 0 | I11: 86 | J11: 0 | L11: 0 | M11: 0 | N11: 0 | O11: 0 | P11: 0 | Q11: 14 | W11: No | AA11: No | AE11: 100 | AF11: 0 | AG11: 0 | AH11: 0 | AI11: 100 | AJ11: 0 | AK11: 0 | AL11: 86 | AM11: 0 | AN11: 0 | AO11: 0 | AP11: 0 | AQ11: 0 | AR11: 0 | AS11: 0 | AT11: 14 | AV11: 10
A12: 3 | B12: 2b | C12: 0 | D12: 0 | E12: 0 | F12: 100 | H12: 0 | I12: 86 | J12: 0 | L12: 0 | M12: 0 | N12: 0 | O12: 0 | P12: 0 | Q12: 14 | W12: Yes | X12: Reinforcement | Y12: CNW | Z12: 1 | AA12: No | AE12: 99 | AF12: 0 | AG12: 0 | AH12: 0 | AI12: 99 | AJ12: 0 | AK12: 0 | AL12: 85.14 | AM12: 0 | AN12: 0 | AO12: 0 | AP12: 0 | AQ12: 0 | AR12: 0 | AS12: 0 | AT12: 13.86 | AV12: 11
A13: 3 | B13: 3b | C13: 0 | D13: 0 | E13: 0 | F13: 100 | H13: 0 | I13: 86 | J13: 0 | L13: 0 | M13: 0 | N13: 0 | O13: 0 | P13: 0 | Q13: 14 | W13: Yes | X13: Reinforcement | Y13: CNW | Z13: 3 | AA13: No | AE13: 97 | AF13: 0 | AG13: 0 | AH13: 0 | AI13: 97 | AJ13: 0 | AK13: 0 | AL13: 83.42 | AM13: 0 | AN13: 0 | AO13: 0 | AP13: 0 | AQ13: 0 | AR13: 0 | AS13: 0 | AT13: 13.58 | AV13: 12
A14: 3 | B14: 4b | C14: 0 | D14: 0 | E14: 0 | F14: 100 | H14: 0 | I14: 86 | J14: 0 | L14: 0 | M14: 0 | N14: 0 | O14: 0 | P14: 0 | Q14: 14 | W14: Yes | X14: Reinforcement | Y14: CNW | Z14: 6 | AA14: No | AE14: 94 | AF14: 0 | AG14: 0 | AH14: 0 | AI14: 94 | AJ14: 0 | AK14: 0 | AL14: 80.84 | AM14: 0 | AN14: 0 | AO14: 0 | AP14: 0 | AQ14: 0 | AR14: 0 | AS14: 0 | AT14: 13.16 | AV14: 13
A15: 4 | B15: 1 | C15: 0 | D15: 0 | E15: 0 | F15: 100 | G15: 3.3 | H15: 0 | I15: 32.2 | J15: 0 | K15: 64.5 | L15: 0 | M15: 0 | N15: 0 | O15: 0 | P15: 0 | Q15: 0 | W15: No | AA15: No | AE15: 100 | AF15: 0 | AG15: 0 | AH15: 0 | AI15: 100 | AJ15: 3.3 | AK15: 0 | AL15: 32.2 | AM15: 0 | AN15: 64.5 | AO15: 0 | AP15: 0 | AQ15: 0 | AR15: 0 | AS15: 0 | AT15: 0 | AV15: 14
A16: 5 | B16: 1 | C16: 94 | D16: 94 | E16: 0 | F16: 6 | G16: 6 | H16: 0 | I16: 0 | J16: 0 | K16: 0 | L16: 0 | M16: 0 | N16: 0 | O16: 0 | P16: 0 | Q16: 0 | R16: 163000 | T16: 1.2 | U16: g/cm3 | V16: 1.35 | W16: No | AA16: No | AE16: 100 | AF16: 94 | AG16: 94 | AH16: 0 | AI16: 6 | AJ16: 6 | AK16: 0 | AL16: 0 | AM16: 0 | AN16: 0 | AO16: 0 | AP16: 0 | AQ16: 0 | AR16: 0 | AS16: 0 | AT16: 0 | AV16: 15
A17: 6 | B17: 1 | C17: 0 | D17: 0 | E17: 0 | F17: 100 | G17: 2 | H17: 0 | I17: 98 | J17: 0 | K17: 0 | L17: 0 | M17: 0 | N17: 0 | O17: 0 | P17: 0 | Q17: 0 | R17: 172000 | V17: 1.75 | W17: No | AA17: No | AE17: 100 | AF17: 0 | AG17: 0 | AH17: 0 | AI17: 100 | AJ17: 2 | AK17: 0 | AL17: 98 | AM17: 0 | AN17: 0 | AO17: 0 | AP17: 0 | AQ17: 0 | AR17: 0 | AS17: 0 | AT17: 0 | AV17: 16
A18: 6 | B18: 2 | C18: 0 | D18: 0 | E18: 0 | F18: 100 | G18: 2 | H18: 0 | I18: 98 | J18: 0 | K18: 0 | L18: 0 | M18: 0 | N18: 0 | O18: 0 | P18: 0 | Q18: 0 | R18: 172000 | V18: 1.75 | W18: Yes | X18: Crosslinking_Agent | Y18: L-231 | Z18: 0.06 | AA18: No | AE18: 99.94 | AF18: 0 | AG18: 0 | AH18: 0 | AI18: 99.94 | AJ18: 1.9988 | AK18: 0 | AL18: 97.9412 | AM18: 0 | AN18: 0 | AO18: 0 | AP18: 0 | AQ18: 0 | AR18: 0 | AS18: 0 | AT18: 0 | AV18: 17
A19: 6 | B19: 3 | C19: 0 | D19: 0 | E19: 0 | F19: 100 | G19: 2 | H19: 0 | I19: 98 | J19: 0 | K19: 0 | L19: 0 | M19: 0 | N19: 0 | O19: 0 | P19: 0 | Q19: 0 | R19: 172000 | V19: 1.75 | W19: Yes | X19: Crosslinking_Agent | Y19: L-231 | Z19: 0.2 | AA19: No | AE19: 99.8 | AF19: 0 | AG19: 0 | AH19: 0 | AI19: 99.8 | AJ19: 1.996 | AK19: 0 | AL19: 97.804 | AM19: 0 | AN19: 0 | AO19: 0 | AP19: 0 | AQ19: 0 | AR19: 0 | AS19: 0 | AT19: 0 | AV19: 18
A20: 6 | B20: 4 | C20: 0 | D20: 0 | E20: 0 | F20: 100 | G20: 2 | H20: 0 | I20: 98 | J20: 0 | K20: 0 | L20: 0 | M20: 0 | N20: 0 | O20: 0 | P20: 0 | Q20: 0 | R20: 172000 | V20: 1.75 | W20: Yes | X20: Crosslinking_Agent | Y20: L-231 | Z20: 0.5 | AA20: No | AE20: 99.5 | AF20: 0 | AG20: 0 | AH20: 0 | AI20: 99.5 | AJ20: 1.99 | AK20: 0 | AL20: 97.51 | AM20: 0 | AN20: 0 | AO20: 0 | AP20: 0 | AQ20: 0 | AR20: 0 | AS20: 0 | AT20: 0 | AV20: 19
A21: 6 | B21: 5 | C21: 0 | D21: 0 | E21: 0 | F21: 100 | G21: 2 | H21: 0 | I21: 98 | J21: 0 | K21: 0 | L21: 0 | M21: 0 | N21: 0 | O21: 0 | P21: 0 | Q21: 0 | R21: 172000 | V21: 1.75 | W21: Yes | X21: Crosslinking_Agent | Y21: L-231 | Z21: 0.1 | AA21: No | AE21: 99.9 | AF21: 0 | AG21: 0 | AH21: 0 | AI21: 99.9 | AJ21: 1.998 | AK21: 0 | AL21: 97.902 | AM21: 0 | AN21: 0 | AO21: 0 | AP21: 0 | AQ21: 0 | AR21: 0 | AS21: 0 | AT21: 0 | AV21: 20
A22: 6 | B22: 6 | C22: 0 | D22: 0 | E22: 0 | F22: 100 | G22: 2 | H22: 0 | I22: 98 | J22: 0 | K22: 0 | L22: 0 | M22: 0 | N22: 0 | O22: 0 | P22: 0 | Q22: 0 | R22: 172000 | V22: 1.75 | W22: Yes | X22: Crosslinking_Agent | Y22: L-231 | Z22: 0.1 | AA22: No | AE22: 99.9 | AF22: 0 | AG22: 0 | AH22: 0 | AI22: 99.9 | AJ22: 1.998 | AK22: 0 | AL22: 97.902 | AM22: 0 | AN22: 0 | AO22: 0 | AP22: 0 | AQ22: 0 | AR22: 0 | AS22: 0 | AT22: 0 | AV22: 21
A23: 6 | B23: 7 | C23: 0 | D23: 0 | E23: 0 | F23: 100 | G23: 2 | H23: 0 | I23: 98 | J23: 0 | K23: 0 | L23: 0 | M23: 0 | N23: 0 | O23: 0 | P23: 0 | Q23: 0 | R23: 172000 | V23: 1.75 | W23: Yes | X23: Crosslinking_Agent | Y23: L-231 | Z23: 0.1 | AA23: No | AE23: 99.9 | AF23: 0 | AG23: 0 | AH23: 0 | AI23: 99.9 | AJ23: 1.998 | AK23: 0 | AL23: 97.902 | AM23: 0 | AN23: 0 | AO23: 0 | AP23: 0 | AQ23: 0 | AR23: 0 | AS23: 0 | AT23: 0 | AV23: 22
A24: 7 | B24: 1 | C24: =SUM(D24:E24) -> 86 | D24: 72.9 | E24: 13.1 | F24: 14 | G24: 0 | H24: 14 | I24: 0 | J24: 0 | K24: 0 | L24: 0 | M24: 0 | N24: 0 | O24: 0 | P24: 0 | Q24: 0 | W24: No | AA24: No | AE24: 100 | AF24: 86 | AG24: 72.9 | AH24: 13.1 | AI24: 14 | AJ24: 0 | AK24: 14 | AL24: 0 | AM24: 0 | AN24: 0 | AO24: 0 | AP24: 0 | AQ24: 0 | AR24: 0 | AS24: 0 | AT24: 0 | AV24: 23
A25: 7 | B25: 2 | C25: =SUM(D25:E25) -> 0 | D25: 0 | E25: 0 | F25: 100 | G25: 0 | H25: 100 | I25: 0 | J25: 0 | K25: 0 | L25: 0 | M25: 0 | N25: 0 | O25: 0 | P25: 0 | Q25: 0 | W25: Yes | X25: polymer matrix/blend | Y25: PHB | Z25: 71.5 | AA25: Yes | AB25: blend | AC25: PHV | AD25: 12.7 | AE25: 15.8 | AF25: 0 | AG25: 0 | AH25: 0 | AI25: 15.8 | AJ25: 0 | AK25: 15.8 | AL25: 0 | AM25: 0 | AN25: 0 | AO25: 0 | AP25: 0 | AQ25: 0 | AR25: 0 | AS25: 0 | AT25: 0 | AV25: 24
A26: 7 | B26: 3 | C26: 51.9 | D26: 0 | E26: 51.9 | F26: 49.1 | G26: 0 | H26: 49.1 | I26: 0 | J26: 0 | K26: 0 | L26: 0 | M26: 0 | N26: 0 | O26: 0 | P26: 0 | Q26: 0 | W26: Yes | X26: polymer matrix/blend | Y26: PHB | Z26: 71.5 | AA26: No | AE26: 28.5 | AF26: 14.7915 | AG26: 0 | AH26: 14.7915 | AI26: 13.9935 | AJ26: 0 | AK26: 13.9935 | AL26: 0 | AM26: 0 | AN26: 0 | AO26: 0 | AP26: 0 | AQ26: 0 | AR26: 0 | AS26: 0 | AT26: 0 | AV26: 25
A27: 8 | B27: 1 | C27: 0 | D27: 0 | E27: 0 | F27: 100 | G27: 3.8 | H27: 0 | I27: 85.9 | J27: 0 | K27: 8.5 | L27: 0 | M27: 0 | N27: 0 | O27: 0 | P27: 0 | Q27: 1.8 | R27: 140000 | V27: 2.1 | W27: Yes | X27: polymer matrix/blend | Y27: PHB | Z27: 90 | AA27: No | AE27: 10 | AF27: 0 | AG27: 0 | AH27: 0 | AI27: 10 | AJ27: 0.38 | AK27: 0 | AL27: 8.59 | AM27: 0 | AN27: 0.85 | AO27: 0 | AP27: 0 | AQ27: 0 | AR27: 0 | AS27: 0 | AT27: 0.18 | AV27: 26
A28: 8 | B28: 2 | C28: 0 | D28: 0 | E28: 0 | F28: 100 | G28: 0 | H28: 22.9 | I28: 0 | J28: 72.1 | K28: 0 | L28: 0 | M28: 0 | N28: 0 | O28: 0 | P28: 0 | Q28: 5 | R28: 110000 | V28: 2.2 | W28: Yes | X28: polymer matrix/blend | Y28: PHB | Z28: 90 | AA28: No | AE28: 10 | AF28: 0 | AG28: 0 | AH28: 0 | AI28: 10 | AJ28: 0 | AK28: 2.29 | AL28: 0 | AM28: 7.21 | AN28: 0 | AO28: 0 | AP28: 0 | AQ28: 0 | AR28: 0 | AS28: 0 | AT28: 0.5 | AV28: 27
A29: 8 | B29: 3 | C29: 0 | D29: 0 | E29: 0 | F29: 100 | G29: 3.8 | H29: 0 | I29: 85.9 | J29: 0 | K29: 8.5 | L29: 0 | M29: 0 | N29: 0 | O29: 0 | P29: 0 | Q29: 1.8 | R29: 140000 | V29: 2.1 | W29: Yes | X29: polymer matrix/blend | Y29: PHB | Z29: 85.5 | AA29: Yes | AB29: Reinforcing_Filler | AC29: NC | AD29: 5 | AE29: 9.5 | AF29: 0 | AG29: 0 | AH29: 0 | AI29: 9.5 | AJ29: 0.361 | AK29: 0 | AL29: 8.1605 | AM29: 0 | AN29: 0.8075 | AO29: 0 | AP29: 0 | AQ29: 0 | AR29: 0 | AS29: 0 | AT29: 0.171 | AV29: 28
A30: 8 | B30: 4 | C30: 0 | D30: 0 | E30: 0 | F30: 100 | G30: 0 | H30: 22.9 | I30: 0 | J30: 72.1 | K30: 0 | L30: 0 | M30: 0 | N30: 0 | O30: 0 | P30: 0 | Q30: 5 | R30: 110000 | V30: 2.2 | W30: Yes | X30: polymer matrix/blend | Y30: PHB | Z30: 85.5 | AA30: Yes | AB30: Reinforcing_Filler | AC30: NC | AD30: 5 | AE30: 9.5 | AF30: 0 | AG30: 0 | AH30: 0 | AI30: 9.5 | AJ30: 0 | AK30: 2.1755 | AL30: 0 | AM30: 6.8495 | AN30: 0 | AO30: 0 | AP30: 0 | AQ30: 0 | AR30: 0 | AS30: 0 | AT30: 0.475 | AV30: 29
A31: 9 | B31: 1 | C31: 0 | D31: 0 | E31: 0 | F31: 100 | H31: 0 | I31: 86 | J31: 0 | L31: 0 | M31: 0 | N31: 0 | O31: 0 | P31: 0 | Q31: 14 | W31: Yes | X31: polymer matrix/blend | Y31: PHB | Z31: 90 | AA31: No | AE31: 10 | AF31: 0 | AG31: 0 | AH31: 0 | AI31: 10 | AJ31: 0 | AK31: 0 | AL31: 8.6 | AM31: 0 | AN31: 0 | AO31: 0 | AP31: 0 | AQ31: 0 | AR31: 0 | AS31: 0 | AT31: 1.4 | AV31: 30
A32: 9 | B32: 2 | C32: 0 | D32: 0 | E32: 0 | F32: 100 | H32: 0 | I32: 86 | J32: 0 | L32: 0 | M32: 0 | N32: 0 | O32: 0 | P32: 0 | Q32: 14 | W32: Yes | X32: polymer matrix/blend | Y32: PHB | Z32: 80 | AA32: No | AE32: 20 | AF32: 0 | AG32: 0 | AH32: 0 | AI32: 20 | AJ32: 0 | AK32: 0 | AL32: 17.2 | AM32: 0 | AN32: 0 | AO32: 0 | AP32: 0 | AQ32: 0 | AR32: 0 | AS32: 0 | AT32: 2.8 | AV32: 31
A33: 9 | B33: 3 | C33: 0 | D33: 0 | E33: 0 | F33: 100 | H33: 0 | I33: 86 | J33: 0 | L33: 0 | M33: 0 | N33: 0 | O33: 0 | P33: 0 | Q33: 14 | W33: Yes | X33: polymer matrix/blend | Y33: PHB | Z33: 65 | AA33: No | AE33: 35 | AF33: 0 | AG33: 0 | AH33: 0 | AI33: 35 | AJ33: 0 | AK33: 0 | AL33: 30.1 | AM33: 0 | AN33: 0 | AO33: 0 | AP33: 0 | AQ33: 0 | AR33: 0 | AS33: 0 | AT33: 4.9 | AV33: 32
A34: 9 | B34: 4 | C34: 0 | D34: 0 | E34: 0 | F34: 100 | H34: 0 | I34: 86 | J34: 0 | L34: 0 | M34: 0 | N34: 0 | O34: 0 | P34: 0 | Q34: 14 | W34: Yes | X34: blend | Y34: PHB | Z34: 50 | AA34: No | AE34: 50 | AF34: 0 | AG34: 0 | AH34: 0 | AI34: 50 | AJ34: 0 | AK34: 0 | AL34: 43 | AM34: 0 | AN34: 0 | AO34: 0 | AP34: 0 | AQ34: 0 | AR34: 0 | AS34: 0 | AT34: 7 | AV34: 33
A35: 9 | B35: 5 | C35: 0 | D35: 0 | E35: 0 | F35: 100 | H35: 0 | I35: 86 | J35: 0 | L35: 0 | M35: 0 | N35: 0 | O35: 0 | P35: 0 | Q35: 14 | W35: Yes | X35: blend | Y35: PHB | Z35: 20 | AA35: No | AE35: 80 | AF35: 0 | AG35: 0 | AH35: 0 | AI35: 80 | AJ35: 0 | AK35: 0 | AL35: 68.8 | AM35: 0 | AN35: 0 | AO35: 0 | AP35: 0 | AQ35: 0 | AR35: 0 | AS35: 0 | AT35: 11.2 | AV35: 34
A36: 9 | B36: 6 | C36: 0 | D36: 0 | E36: 0 | F36: 100 | H36: 0 | I36: 86 | J36: 0 | L36: 0 | M36: 0 | N36: 0 | O36: 0 | P36: 0 | Q36: 14 | W36: Yes | X36: blend | Y36: PHB | Z36: 10 | AA36: No | AE36: 90 | AF36: 0 | AG36: 0 | AH36: 0 | AI36: 90 | AJ36: 0 | AK36: 0 | AL36: 77.4 | AM36: 0 | AN36: 0 | AO36: 0 | AP36: 0 | AQ36: 0 | AR36: 0 | AS36: 0 | AT36: 12.6 | AV36: 35
A37: 9 | B37: 7 | C37: 0 | D37: 0 | E37: 0 | F37: 100 | H37: 0 | I37: 86 | J37: 0 | L37: 0 | M37: 0 | N37: 0 | O37: 0 | P37: 0 | Q37: 14 | W37: No | AA37: No | AE37: 100 | AF37: 0 | AG37: 0 | AH37: 0 | AI37: 100 | AJ37: 0 | AK37: 0 | AL37: 86 | AM37: 0 | AN37: 0 | AO37: 0 | AP37: 0 | AQ37: 0 | AR37: 0 | AS37: 0 | AT37: 14 | AV37: 36
A38: 10 | B38: 1 | C38: 0 | D38: 0 | E38: 0 | F38: =SUM(G38:P38) -> 104 | G38: 5 | H38: 0 | I38: 20 | J38: 0 | K38: 49 | L38: 0 | M38: 16 | N38: 0 | O38: 3 | P38: 11 | Q38: 0 | R38: 415000 | S38: 147000 | V38: 2.8 | W38: No | AA38: No | AE38: 100 | AF38: 0 | AG38: 0 | AH38: 0 | AI38: 104 | AJ38: 5 | AK38: 0 | AL38: 20 | AM38: 0 | AN38: 49 | AO38: 0 | AP38: 16 | AQ38: 0 | AR38: 3 | AS38: 11 | AT38: 0 | AV38: 37
A39: 11 | B39: 1 | C39: 1 | D39: 1 | E39: 0 | F39: 99 | G39: 2 | H39: 0 | I39: 25 | J39: 0 | K39: 14 | L39: 0 | M39: 7 | N39: 0 | O39: 2 | P39: 49 | Q39: 0 | S39: 30000 | V39: 2 | W39: No | AA39: No | AE39: 100 | AF39: 1 | AG39: 1 | AH39: 0 | AI39: 99 | AJ39: 2 | AK39: 0 | AL39: 25 | AM39: 0 | AN39: 14 | AO39: 0 | AP39: 7 | AQ39: 0 | AR39: 2 | AS39: 49 | AT39: 0 | AV39: 38

Sheet Thermal_properties
A1: Study_id | B1: Instance | C1: Tg1 | D1: Tg2 | E1: Tc1 | F1: Tc2 | G1: Tmc | H1: Tm1 | I1: Tm2 | J1: Td5 | K1: Tdeg | L1: Temperature_units | M1: DΗm1 | N1: DΗm2 | O1: DHc1 | P1: DHc2 | Q1: Enthaply_units | R1: Crystallinity %
A2: 1 | B2: 1 | C2: -33 | H2: 61 | L2: celsius
A3: 1 | B3: 2 | C3: -33 | H3: 61 | L3: celsius
A4: 1 | B4: 3 | C4: -33 | H4: 61 | L4: celsius
A5: 1 | B5: 4 | C5: -32 | H5: 60 | L5: celsius
A6: 2 | B6: 1 | C6: -16 | H6: 36 | L6: celsius | R6: 6
A7: 3 | B7: 1a | C7: -37 | L7: celsius | R7: 0
A8: 3 | B8: 2a | C8: -37 | L8: celsius | R8: 0
A9: 3 | B9: 3a | C9: -37 | L9: celsius | R9: 0
A10: 3 | B10: 4a | C10: -37 | L10: celsius | R10: 0
A11: 3 | B11: 1b | C11: -34 | H11: 57 | L11: celsius | R11: 30
A12: 3 | B12: 2b | C12: -34 | H12: 57 | L12: celsius | R12: 30
A13: 3 | B13: 3b | C13: -34 | H13: 57 | L13: celsius | R13: 30
A14: 3 | B14: 4b | C14: -34 | H14: 57 | L14: celsius | R14: 30
A15: 4 | B15: 1 | C15: -49.35 | H15: 52.21 | L15: celsius | M15: 22.75 | Q15: J/g | R15: 15.6
A16: 5 | B16: 1 | G16: 50.2 | H16: 124.1 | I16: 143.5 | L16: celsius | M16: 60 | Q16: J/g | R16: 49
A17: 6 | B17: 1
A18: 6 | B18: 2
A19: 6 | B19: 3
A20: 6 | B20: 4
A21: 6 | B21: 5
A22: 6 | B22: 6
A23: 6 | B23: 7
A24: 7 | B24: 1
A25: 7 | B25: 2
A26: 7 | B26: 3
A27: 8 | B27: 1 | E27: 107 | H27: 152.1 | I27: 163.8 | J27: 257.1 | L27: celsius | R27: 46
A28: 8 | B28: 2 | C28: -42.8 | E28: 105.7 | H28: 154.4 | I28: 162.7 | J28: 235 | L28: celsius | R28: 46.3
A29: 8 | B29: 3 | C29: -39.7 | E29: 108.3 | H29: 155.9 | I29: 163.4 | J29: 224.4 | L29: celsius | R29: 48.7
A30: 8 | B30: 4 | C30: -40.5 | E30: 108.4 | H30: 155.3 | I30: 163.3 | J30: 222.8 | L30: celsius | R30: 47.5
A31: 9 | B31: 1
A32: 9 | B32: 2
A33: 9 | B33: 3
A34: 9 | B34: 4
A35: 9 | B35: 5
A36: 9 | B36: 6
A37: 9 | B37: 7
A38: 10 | B38: 1 | C38: -43.4 | H38: 43.5 | L38: celsius | M38: 9.6 | Q38: J/g
A39: 11 | B39: 1 | C39: -50 | L39: celsius

Sheet Rheological_experimental_detail
A1: Study_id | B1: Instance | C1: Test type | D1: constant parameters | E1: geometry | F1: plate diameter | G1: gap size | H1: morphology | I1: diameter | J1: thickness | K1: size units | L1: Angular_frequency_units | M1: Texp | N1: Texp_units | O1: Viscosity_units | P1: Modulus_units | Q1: Strain_fixed(%) | R1: Frequency_experimental_fixed (Hz)
A2: 1 | B2: 1 | C2: DFS | D2: stress,temp | E2: parallel plate | F2: 25 | K2: mm | L2: Hz | M2: 190 | N2: celsius | P2: Pa
A3: 1 | B3: 2 | C3: DFS | D3: stress,temp | E3: parallel plate | F3: 25 | K3: mm | L3: Hz | M3: 190 | N3: celsius | P3: Pa
A4: 1 | B4: 3 | C4: DFS | D4: stress,temp | E4: parallel plate | F4: 25 | K4: mm | L4: Hz | M4: 190 | N4: celsius | P4: Pa
A5: 1 | B5: 4 | C5: DFS | D5: stress,temp | E5: parallel plate | F5: 25 | K5: mm | L5: Hz | M5: 190 | N5: celsius | P5: Pa
A6: 2 | B6: 1 | C6: DFS | D6: stress,temp | E6: parallel plate | F6: 20 | G6: 1 | K6: mm | L6: Hz | M6: 20 | N6: celsius | P6: Pa
A7: 3 | B7: 1a | C7: DTS | D7: angular frequency,stress or strain | L7: Hz | N7: celsius | P7: Pa | R7: 1
A8: 3 | B8: 2a | C8: DTS | D8: angular frequency,stress or strain | L8: Hz | N8: celsius | P8: Pa | R8: 1
A9: 3 | B9: 3a | C9: DTS | D9: angular frequency,stress or strain | L9: Hz | N9: celsius | P9: Pa | R9: 1
A10: 3 | B10: 4a | C10: DTS | D10: angular frequency,stress or strain | L10: Hz | N10: celsius | P10: Pa | R10: 1
A11: 3 | B11: 1b | C11: DTS | D11: angular frequency,stress or strain | L11: Hz | N11: celsius | P11: Pa | R11: 1
A12: 3 | B12: 2b | C12: DTS | D12: angular frequency,stress or strain | L12: Hz | N12: celsius | P12: Pa | R12: 1
A13: 3 | B13: 3b | C13: DTS | D13: angular frequency,stress or strain | L13: Hz | N13: celsius | P13: Pa | R13: 1
A14: 3 | B14: 4b | C14: DTS | D14: angular frequency,stress or strain | L14: Hz | N14: celsius | P14: Pa | R14: 1
A15: 4 | B15: 1 | C15: DTS | D15: shear rate | N15: celsius | O15: Pa*s
A16: 5 | B16: 1 | C16: DFS | D16: stress,temp | E16: parallel plate | I16: 25 | J16: 1 | K16: mm | L16: rad/s | M16: 190 | N16: celsius | O16: Pa*s | P16: Pa
A17: 6 | B17: 1 | C17: DFS | D17: stress,temp | E17: cone-plate | F17: 25 | I17: 25 | J17: 2 | K17: mm | L17: rad/s | M17: 190 | N17: celsius | O17: Pa*s | P17: Pa | R17: 1
A18: 6 | B18: 2 | C18: DFS | D18: stress,temp | E18: cone-plate | F18: 25 | I18: 25 | J18: 2 | K18: mm | L18: rad/s | M18: 190 | N18: celsius | O18: Pa*s | P18: Pa | R18: 1
A19: 6 | B19: 3 | C19: DFS | D19: stress,temp | E19: cone-plate | F19: 25 | I19: 25 | J19: 2 | K19: mm | L19: rad/s | M19: 190 | N19: celsius | O19: Pa*s | P19: Pa | R19: 1
A20: 6 | B20: 4 | C20: DFS | D20: stress,temp | E20: cone-plate | F20: 25 | I20: 25 | J20: 2 | K20: mm | L20: rad/s | M20: 190 | N20: celsius | O20: Pa*s | P20: Pa | R20: 1
A21: 6 | B21: 5 | C21: time_sweep | D21: angular frequency,stress,temp | E21: cone-plate | F21: 25 | I21: 25 | J21: 2 | K21: mm | L21: rad/s | M21: 135 | N21: celsius | P21: Pa | R21: 1
A22: 6 | B22: 6 | C22: time_sweep | D22: angular frequency,stress,temp | E22: cone-plate | F22: 25 | I22: 25 | J22: 2 | K22: mm | L22: rad/s | M22: 145 | N22: celsius | P22: Pa | R22: 1
A23: 6 | B23: 7 | C23: time_sweep | D23: angular frequency,stress,temp | E23: cone-plate | F23: 25 | I23: 25 | J23: 2 | K23: mm | L23: rad/s | M23: 155 | N23: celsius | P23: Pa | R23: 1
A24: 7 | B24: 1 | C24: DTS | D24: angular frequency,strain | E24: cone-plate | F24: 25 | K24: mm | N24: celsius | P24: Mpa | Q24: 1 | R24: 1
A25: 7 | B25: 2 | C25: DTS | D25: angular frequency,strain | E25: cone-plate | F25: 25 | K25: mm | N25: celsius | P25: Mpa | Q25: 1 | R25: 1
A26: 7 | B26: 3 | C26: DTS | D26: angular frequency,strain | E26: cone-plate | F26: 25 | K26: mm | N26: celsius | P26: Mpa | Q26: 1 | R26: 1
A27: 8 | B27: 1 | C27: DTS | N27: celsius | P27: Mpa
A28: 8 | B28: 2 | C28: DTS | N28: celsius | P28: Mpa
A29: 8 | B29: 3 | C29: DTS | N29: celsius | P29: Mpa
A30: 8 | B30: 4 | C30: DTS | N30: celsius | P30: Mpa
A31: 9 | B31: 1 | C31: DTS | D31: angular frequency,stress or strain | L31: Hz | N31: celsius | P31: Pa | R31: 1
A32: 9 | B32: 2 | C32: DTS | D32: angular frequency,stress or strain | L32: Hz | N32: celsius | P32: Pa | R32: 1
A33: 9 | B33: 3 | C33: DTS | D33: angular frequency,stress or strain | L33: Hz | N33: celsius | P33: Pa | R33: 1
A34: 9 | B34: 4 | C34: DTS | D34: angular frequency,stress or strain | L34: Hz | N34: celsius | P34: Pa | R34: 1
A35: 9 | B35: 6 | C35: DTS | D35: angular frequency,stress or strain | L35: Hz | N35: celsius | P35: Pa | R35: 1
A36: 9 | B36: 7 | C36: DTS | D36: angular frequency,stress or strain | L36: Hz | N36: celsius | P36: Pa | R36: 1
A37: 10 | B37: 1 | C37: DTS | D37: angular frequency,strain | N37: celsius | R37: 1.6
A38: 11 | B38: 1 | C38: DTS | D38: angular frequency,strain | N38: celsius | R38: 1.6

Sheet Storage_modulus_G
A1: Study_id | B1: Instance
A2: 1 | B2: 1 | C2: 2.115 | D2: 4.472 | E2: 9.458 | F2: 20.353 | G2: 44.567 | H2: 97.591 | I2: 210.009 | J2: 407.083 | K2: 802.952 | L2: 1477.204 | M2: 2624.593 | N2: 4425.791 | O2: 6960.855 | P2: 10211.212 | Q2: 14466.489 | R2: 19451.64 | S2: 24823.113 | T2: 32234.468 | U2: 41858.634 | V2: 54356.262
A3: 1 | B3: 2 | C3: 1.321 | D3: 2.474 | E3: 4.879 | F3: 10.14 | G3: 21.074 | H3: 50.346 | I3: 104.633 | J3: 237.241 | K3: 484.534 | L3: 955.724 | M3: 1789.154 | N3: 3017.006 | O3: 5360.414 | P3: 7863.443 | Q3: 11737.934 | R3: 16921.616 | S3: 22752.802 | T3: 29546.05 | U3: 37705.021 | V3: 53417.717
A4: 1 | B4: 3 | C4: 1 | D4: 3.629 | E4: 7.411 | F4: 14.618 | G4: 29.856 | H4: 70.095 | I4: 145.676 | J4: 313.486 | K4: 662.952 | L4: 1262.879 | M4: 2364.158 | N4: 4127.941 | O4: 6840.665 | P4: 10758.955 | Q4: 14979.306 | R4: 22359.926 | S4: 21973.86 | T4: 29546.05 | U4: 39041.633 | V4: 56283.148
A5: 1 | B5: 4 | C5: 710.787 | D5: 1137.563 | E5: 1401.998 | F5: 1758.26 | G5: 2092.793 | H5: 2447.964 | I5: 3178.844 | J5: 4056.669 | K5: 5454.596 | L5: 6722.55 | M5: 9691.349 | N5: 11944.169 | O5: 16342.294 | P5: 20855.149 | Q5: 26154.658 | R5: 31130.94 | S5: 41135.904 | T5: 51588.93 | U5: 58278.306 | V5: 71825.456
A6: 2 | B6: 1 | C6: 146.255 | D6: 211.868 | E6: 285.672 | F6: 413.831 | G6: 592.36 | H6: 868.427 | I6: 1199.279 | J6: 1758.198 | K6: 2399.177 | L6: 3645.744 | M6: 4915.738 | N6: 6788.528 | O6: 9263.404 | P6: 12490.308 | Q6: 16641.168 | R6: 20884.977 | S6: 25899.533 | T6: 32504.386
A7: 3 | B7: 1 | C7: 1.9098533e+09 | D7: 1.7823788e+09 | E7: 1.7378008e+09 | F7: 1.6218101e+09 | G7: 1.5135612e+09 | H7: 1.4321879e+09 | I7: 1.374042e+09 | J7: 1.2823306e+09 | K7: 1.0568175e+09 | L7: 5.0933087e+08 | M7: 16904409 | N7: 1492794.4 | O7: 748169.5 | P7: 481947.8 | Q7: 381065.82 | R7: 309741.93
A8: 3 | B8: 2 | C8: 1.9633603e+09 | D8: 1.9906733e+09 | E8: 1.8578045e+09 | F8: 1.6218101e+09 | G8: 1.6672472e+09 | H8: 1.6443717e+09 | I8: 1.6218101e+09 | J8: 1.5776113e+09 | K8: 1.2133889e+09 | L8: 5.5335011e+08 | M8: 74816950 | N8: 31841975 | O8: 18323144 | P8: 11803206 | Q8: 8472274.1 | R8: 5997910.8 | S8: 4197589.8 | T8: 3013006 | U8: 2517676.9 | V8: 2133044.9 | W8: 1621810.1
A9: 3 | B9: 3 | C9: 2.2855988e+09 | D9: 2.2542392e+09 | E9: 2.1627185e+09 | F9: 2.1037784e+09 | G9: 1.9906733e+09 | H9: 1.9906733e+09 | I9: 1.936422e+09 | J9: 1.8836491e+09 | K9: 1.6904409e+09 | L9: 1.1324004e+09 | M9: 4.6881338e+08 | N9: 2.9308932e+08 | O9: 2.7352687e+08 | P9: 2.4154608e+08 | Q9: 2.3173946e+08 | R9: 2.1928049e+08 | S9: 2.2233099e+08 | T9: 2.1928049e+08 | U9: 2.0749135e+08 | V9: 1.936422e+08 | W9: 1.761976e+08
A10: 3 | B10: 4 | C10: 3.3189446e+09 | D10: 3.2284941e+09 | E10: 3.0549211e+09 | F10: 3.0974193e+09 | G10: 3.013006e+09 | H10: 2.9308932e+09 | I10: 2.8510183e+09 | J10: 2.6607251e+09 | K10: 2.5176769e+09 | L10: 1.5559656e+09 | M10: 7.277798e+08 | N10: 5.9979108e+08 | O10: 5.3826978e+08 | P10: 5.2360044e+08 | Q10: 4.8865236e+08 | R10: 4.819478e+08 | S10: 4.7533523e+08 | T10: 4.6238102e+08 | U10: 4.5603692e+08 | V10: 4.3752211e+08 | W10: 4.1399967e+08
A11: 3 | B11: 1 | C11: 1.4354894e+09 | D11: 1.4028137e+09 | E11: 1.3583134e+09 | F11: 1.3396767e+09 | G11: 1.2882496e+09 | H11: 1.250259e+09 | I11: 1.2022644e+09 | J11: 1.1142945e+09 | K11: 1.023293e+09 | L11: 7.0794578e+08 | M11: 1.8620871e+08 | N11: 1.0964782e+08 | O11: 85703785 | P11: 75335556 | Q11: 68706844 | R11: 62661386 | S11: 55335011 | T11: 43351088
A12: 3 | B12: 2 | C12: 1.6218101e+09 | D12: 1.5958791e+09 | E12: 1.5488166e+09 | F12: 1.4791084e+09 | G12: 1.4223288e+09 | H12: 1.3803843e+09 | I12: 1.3182567e+09 | J12: 1.2217997e+09 | K12: 1.064143e+09 | L12: 8.1283052e+08 | M12: 2.630268e+08 | N12: 1.7498467e+08 | O12: 1.4454398e+08 | P12: 1.3182567e+08 | Q12: 1.2105981e+08 | R12: 1.1668096e+08 | S12: 1.0543869e+08 | T12: 89742879
A13: 3 | B13: 3 | C13: 2.4717241e+09 | D13: 2.3988329e+09 | E13: 2.3442288e+09 | F13: 2.2908677e+09 | G13: 2.2542392e+09 | H13: 2.1877616e+09 | I13: 2.1232445e+09 | J13: 1.9952623e+09 | K13: 1.7906059e+09 | L13: 1.1748976e+09 | M13: 4.4977985e+08 | N13: 3.069022e+08 | O13: 2.5882129e+08 | P13: 2.3280913e+08 | Q13: 2.1379621e+08 | R13: 2.0090928e+08 | S13: 1.8620871e+08 | T13: 1.4893611e+08
A14: 3 | B14: 4 | C14: 2.9991625e+09 | D14: 2.7733201e+09 | E14: 2.7989813e+09 | F14: 2.8183829e+09 | G14: 2.6485001e+09 | H14: 2.630268e+09 | I14: 2.529298e+09 | J14: 2.4154608e+09 | K14: 2.2029265e+09 | L14: 1.5135612e+09 | M14: 8.1846479e+08 | N14: 6.3533093e+08 | O14: 5.7543994e+08 | P14: 5.333349e+08 | Q14: 4.931738e+08 | R14: 4.6025657e+08 | S14: 4.1975898e+08 | T14: 3.7153523e+08
A15: 4 | B15: 1
A16: 5 | B16: 1 | C16: 147.444 | D16: 287.623 | E16: 636.681 | F16: 1155.434 | G16: 2115.876 | H16: 4017.182 | I16: 6252.858 | J16: 7979.229 | K16: 13593.562 | L16: 20042.908 | M16: 26517.3 | N16: 33534.377 | O16: 42408.317 | P16: 68437.509 | Q16: 83477.322 | R16: 102745.97 | S16: 125325.4 | T16: 142213.64 | U16: 176627.7 | V16: 219369.63
A17: 6 | B17: 1 | E17: 0.113 | F17: 0.36 | G17: 0.74 | H17: 2.007 | I17: 3.388 | J17: 8.065 | K17: 48.789 | L17: 87.935
A18: 6 | B18: 2 | C18: 146.038 | D18: 183.637 | E18: 223.48 | F18: 267.554 | G18: 336.437 | H18: 444.34 | I18: 567.956 | J18: 702.588 | K18: 912.864 | L18: 1308.432
A19: 6 | B19: 3 | C19: 1491.434 | D19: 1516.04 | E19: 1645.295 | F19: 1815.028 | G19: 1937.803 | H19: 2172.979 | I19: 2358.244 | J19: 2644.446 | K19: 3014.309 | L19: 3668.317
A20: 6 | B20: 4 | C20: 29309.257 | D20: 29309.257 | E20: 30783.971 | F20: 29792.82 | G20: 31291.865 | H20: 31291.865 | I20: 31291.865 | J20: 30783.971 | K20: 30284.345 | L20: 32332.886
A21: 6 | B21: 5 | C21: 10.936 | D21: 22.718 | E21: 48.985 | F21: 103.285 | G21: 178.049 | H21: 291.315 | I21: 449.022 | J21: 609.673 | K21: 815.543 | L21: 1035.425 | M21: 1354.408 | N21: 1595.966 | O21: 1825.32 | P21: 2199.544 | Q21: 2813.481 | R21: 3441.257 | S21: 3848.692 | T21: 4535.106 | U21: 5034.355 | V21: 5225.675 | W21: 5424.27 | X21: 5630.409 | Y21: 5800.947 | Z21: 5800.947 | AA21: 5976.649 | AB21: 6111.911 | AC21: 6203.783
A22: 6 | B22: 6 | C22: 40.349 | D22: 140.239 | E22: 364.38 | F22: 729.207 | G22: 1202.025 | H22: 1694.11 | I22: 2216.013 | J22: 2751.217 | K22: 3680.228 | L22: 4146.776 | M22: 4637.743 | N22: 5072.051 | O22: 5383.956 | P22: 5424.27 | Q22: 5505.804 | R22: 5588.562
A23: 6 | B23: 7 | C23: 95.148 | D23: 582.987 | E23: 1492.334 | F23: 2515.637 | G23: 3415.68 | H23: 4501.401 | I23: 4922.94 | J23: 4922.94 | K23: 4959.802 | L23: 5225.675 | M23: 5547.029 | N23: 5630.409
A24: 7 | B24: 1 | C24: 271.104 | D24: 66.449 | E24: 46.882 | F24: 34.177 | G24: 26.89 | H24: 20.034 | I24: 16.11 | J24: 13.385 | K24: 10.647 | L24: 8.561 | M24: 6.174 | N24: 4.262 | O24: 3.465 | P24: 2.61 | Q24: 1.669 | R24: 1.313 | S24: 1.079
A25: 7 | B25: 2 | C25: 9496.826 | D25: 4288.317 | E25: 2018.054 | F25: 1031.461 | G25: 634.878 | H25: 437.78 | I25: 367.301 | J25: 386.762 | K25: 374.965 | L25: 292.663 | M25: 243.025 | N25: 230.796 | O25: 126.806 | P25: 22.608 | Q25: 3.417 | R25: 3.019 | S25: 2.695 | T25: 2.455 | U25: 2.261 | V25: 2.082 | W25: 1.977
A26: 7 | B26: 3 | C26: 16762.168 | D26: 16548.172 | E26: 16762.168 | F26: 16128.322 | G26: 12001.653 | H26: 7556.979 | I26: 4349.034 | J26: 1960.699 | K26: 1142.973 | L26: 701.427 | M26: 521.956 | N26: 199.116 | O26: 83.108 | P26: 16.463 | Q26: 2.522 | R26: 2.365 | S26: 2.027 | T26: 1.694 | U26: 1.452 | V26: 1.31 | W26: 1.137
A27: 8 | B27: 1 | C27: 4936.118 | D27: 4867.322 | E27: 4781.327 | F27: 4600.737 | G27: 4480.344 | H27: 4325.553 | I27: 4187.96 | J27: 4033.169 | K27: 3861.179 | L27: 3620.393 | M27: 3405.405 | N27: 3138.82 | O27: 2863.636 | P27: 2631.45 | Q27: 2399.263 | R27: 2141.277 | S27: 1934.889 | T27: 1737.101 | U27: 1565.11 | V27: 1453.317 | W27: 1358.722 | X27: 1264.127 | Y27: 1143.735 | Z27: 1031.941 | AA27: 902.948 | AB27: 799.754 | AC27: 705.159 | AD27: 670.761 | AE27: 610.565 | AF27: 558.968 | AG27: 533.169 | AH27: 524.57 | AI27: 472.973 | AJ27: 455.774 | AK27: 421.376 | AL27: 386.978
A28: 8 | B28: 2 | C28: 5417.69 | D28: 5374.693 | E28: 5280.098 | F28: 5090.909 | G28: 4807.125 | H28: 4583.538 | I28: 4402.948 | J28: 4222.358 | K28: 3998.771 | L28: 3792.383 | M28: 3517.199 | N28: 3250.614 | O28: 2932.432 | P28: 2622.849 | Q28: 2347.665 | R28: 2132.678 | S28: 1891.892 | T28: 1711.302 | U28: 1539.311 | V28: 1375.921 | W28: 1272.727 | X28: 1152.333 | Y28: 1040.54 | Z28: 911.548 | AA28: 791.154 | AB28: 644.963 | AC28: 541.769 | AD28: 472.973 | AE28: 464.373 | AF28: 421.376 | AG28: 395.577 | AH28: 378.378 | AI28: 378.378 | AJ28: 343.98 | AK28: 318.181 | AL28: 275.184
A29: 8 | B29: 3 | C29: 6054.054 | D29: 5933.661 | E29: 5770.27 | F29: 5598.28 | G29: 5391.892 | H29: 5108.108 | I29: 4815.725 | J29: 4583.538 | K29: 4334.152 | L29: 4093.366 | M29: 3826.781 | N29: 3585.995 | O29: 3379.607 | P29: 3138.82 | Q29: 2932.432 | R29: 2708.845 | S29: 2511.056 | T29: 2304.668 | U29: 2158.476 | V29: 2046.683 | W29: 1909.091 | X29: 1814.496 | Y29: 1668.304 | Z29: 1530.713 | AA29: 1410.319 | AB29: 1272.727 | AC29: 1195.332 | AD29: 1126.535 | AE29: 1092.137 | AF29: 997.542 | AG29: 945.945 | AH29: 859.951 | AI29: 825.553 | AJ29: 730.958 | AK29: 670.761 | AL29: 644.963
A30: 8 | B30: 4 | C30: 5546.683 | D30: 5512.285 | E30: 5383.292 | F30: 5194.103 | G30: 4936.118 | H30: 4600.737 | I30: 4291.155 | J30: 3921.376 | K30: 3646.191 | L30: 3448.403 | M30: 3181.818 | N30: 2984.029 | O30: 2777.64 | P30: 2588.452 | Q30: 2373.464 | R30: 2227.273 | S30: 2072.482 | T30: 1917.691 | U30: 1788.697 | V30: 1668.304 | W30: 1539.311 | X30: 1410.319 | Y30: 1307.124 | Z30: 1186.732 | AA30: 1066.339 | AB30: 928.747 | AC30: 859.951 | AD30: 791.154 | AE30: 748.157 | AF30: 679.361 | AG30: 619.165 | AH30: 610.565 | AI30: 576.167 | AJ30: 541.769 | AK30: 498.771 | AL30: 455.774
A31: 9 | B31: 1 | C31: 1.3001696e+15 | D31: 1.3365955e+15 | E31: 1.3365955e+15 | F31: 1.1117317e+15 | G31: 7.6913044e+14 | H31: 6.7452803e+14 | I31: 5.7543994e+14 | J31: 4.4258837e+14 | K31: 3.2284941e+14 | L31: 2.5468303e+14 | M31: 1.3551894e+14 | N31: 7.816278e+13 | O31: 4.1591061e+13 | P31: 1.4157938e+13 | Q31: 4.1114972e+12 | R31: 9.183326e+11
A32: 9 | B32: 2 | C32: 9.3972331e+13 | D32: 9.6382902e+13 | E32: 9.6382902e+13 | F32: 7.816278e+13 | G32: 6.0117374e+13 | H32: 6.3241185e+13 | I32: 5.8479008e+13 | J32: 5.2601727e+13 | K32: 4.0457589e+13 | L32: 3.1988951e+13 | M32: 2.3933158e+13 | N32: 1.840772e+13 | O32: 6.2661386e+12 | P32: 2.4945947e+12 | Q32: 4.4055486e+11 | R32: 1.0375284e+11
A33: 9 | B33: 3 | C33: 1.1168632e+13 | D33: 1.0592537e+13 | E33: 1.0327614e+13 | F33: 8.5901352e+12 | G33: 4.819478e+12 | H33: 3.6982818e+12 | I33: 2.8444611e+12 | J33: 2.2490546e+12 | K33: 1.8197009e+12 | L33: 1.4387986e+12 | M33: 1.2274392e+12 | N33: 9.4406088e+11 | O33: 6.0394863e+11 | P33: 2.6730064e+11 | Q33: 6.2950618e+10
A34: 9 | B34: 4 | C34: 1.5958791e+12 | D34: 1.4757065e+12 | E34: 1.3995873e+12 | F34: 9.4406088e+11 | G34: 4.1783037e+11 | H34: 2.4717241e+11 | I34: 1.9010783e+11 | J34: 1.4223288e+11 | K34: 8.4139514e+10 | L34: 7.7624712e+10 | M34: 6.4714262e+10 | N34: 5.5207744e+10 | O34: 3.62243e+10 | P34: 1.6032454e+10 | Q34: 1.0990058e+09
A35: 9 | B35: 5 | C35: 1.3867558e+11 | D35: 1.2133889e+11 | E35: 1.0375284e+11 | F35: 6.2950618e+10 | G35: 2.1777098e+09 | H35: 1.428894e+09 | I35: 8.4527885e+08 | J35: 4.7424199e+08 | K35: 12274392
A36: 9 | B36: 6 | C36: 2.6424088e+10 | D36: 2.5118864e+10 | E36: 2.3173946e+10 | F36: 1.4454398e+10 | G36: 8.2413812e+08 | H36: 4.2657952e+08 | I36: 3.3651157e+08 | J36: 1.0327614e+08
A37: 9 | B37: 7 | C37: 2.2961486e+09 | D37: 2.0653802e+09 | E37: 1.8578045e+09 | F37: 9.6382902e+08 | G37: 54954087 | H37: 30831880 | I37: 20749135 | J37: 5727960.3 | K37: 114024.98
A38: 10 | B38: 1 | C38: 3.6224205e+09 | D38: 3.5243559e+09 | E38: 3.2458096e+09 | F38: 2.9485376e+09 | G38: 2.7910567e+09 | H38: 2.5704652e+09 | I38: 2.2103332e+09 | J38: 1.7030506e+09 | K38: 3.6624052e+08 | L38: 74553360 | M38: 34101775 | N38: 24198590 | O38: 17408541 | P38: 11693326 | Q38: 7537628.8 | R38: 4178084.9 | S38: 721380.59
A39: 11 | B39: 1 | C39: 4.1156942e+09 | D39: 4.1156942e+09 | E39: 3.846514e+09 | F39: 3.6872899e+09 | G39: 3.5048993e+09 | H39: 3.3034813e+09 | I39: 3.1400747e+09 | J39: 3.0356532e+09 | K39: 2.8132247e+09 | L39: 2.7427639e+09 | M39: 2.607094e+09 | N39: 2.4781342e+09 | O39: 2.3357205e+09 | P39: 2.0401845e+09 | Q39: 1.7374088e+09 | R39: 1.3143985e+09 | S39: 5.8869408e+08 | T39: 1.1809061e+08 | U39: 24921423 | V39: 16192062

Sheet converted_MPa_Storage_modulus_G
A1: Study_id | B1: Instance
A2: 1 | B2: 1 | C2: =Storage_modulus_G!C2/1000000 -> 2.115e-06 | D2: =Storage_modulus_G!D2/1000000 -> 4.472e-06 | E2: =Storage_modulus_G!E2/1000000 -> 9.458e-06 | F2: =Storage_modulus_G!F2/1000000 -> 2.0353e-05 | G2: =Storage_modulus_G!G2/1000000 -> 4.4567e-05 | H2: =Storage_modulus_G!H2/1000000 -> 9.7591e-05 | I2: =Storage_modulus_G!I2/1000000 -> 0.000210009 | J2: =Storage_modulus_G!J2/1000000 -> 0.000407083 | ... V2: =Storage_modulus_G!V2/1000000 -> 0.054356262
A3: 1 | B3: 2 | C3: =Storage_modulus_G!C3/1000000 -> 1.321e-06 | D3: =Storage_modulus_G!D3/1000000 -> 2.474e-06 | E3: =Storage_modulus_G!E3/1000000 -> 4.879e-06 | F3: =Storage_modulus_G!F3/1000000 -> 1.014e-05 | G3: =Storage_modulus_G!G3/1000000 -> 2.1074e-05 | H3: =Storage_modulus_G!H3/1000000 -> 5.0346e-05 | I3: =Storage_modulus_G!I3/1000000 -> 0.000104633 | J3: =Storage_modulus_G!J3/1000000 -> 0.000237241 | ... V3: =Storage_modulus_G!V3/1000000 -> 0.053417717
A4: 1 | B4: 3 | C4: =Storage_modulus_G!C4/1000000 -> 1e-06 | D4: =Storage_modulus_G!D4/1000000 -> 3.629e-06 | E4: =Storage_modulus_G!E4/1000000 -> 7.411e-06 | F4: =Storage_modulus_G!F4/1000000 -> 1.4618e-05 | G4: =Storage_modulus_G!G4/1000000 -> 2.9856e-05 | H4: =Storage_modulus_G!H4/1000000 -> 7.0095e-05 | I4: =Storage_modulus_G!I4/1000000 -> 0.000145676 | J4: =Storage_modulus_G!J4/1000000 -> 0.000313486 | ... V4: =Storage_modulus_G!V4/1000000 -> 0.056283148
A5: 1 | B5: 4 | C5: =Storage_modulus_G!C5/1000000 -> 0.000710787 | D5: =Storage_modulus_G!D5/1000000 -> 0.001137563 | E5: =Storage_modulus_G!E5/1000000 -> 0.001401998 | F5: =Storage_modulus_G!F5/1000000 -> 0.00175826 | G5: =Storage_modulus_G!G5/1000000 -> 0.002092793 | H5: =Storage_modulus_G!H5/1000000 -> 0.002447964 | I5: =Storage_modulus_G!I5/1000000 -> 0.003178844 | J5: =Storage_modulus_G!J5/1000000 -> 0.004056669 | ... V5: =Storage_modulus_G!V5/1000000 -> 0.071825456
A6: 2 | B6: 1 | C6: =Storage_modulus_G!C6/1000000 -> 0.000146255 | D6: =Storage_modulus_G!D6/1000000 -> 0.000211868 | E6: =Storage_modulus_G!E6/1000000 -> 0.000285672 | F6: =Storage_modulus_G!F6/1000000 -> 0.000413831 | G6: =Storage_modulus_G!G6/1000000 -> 0.00059236 | H6: =Storage_modulus_G!H6/1000000 -> 0.000868427 | I6: =Storage_modulus_G!I6/1000000 -> 0.001199279 | J6: =Storage_modulus_G!J6/1000000 -> 0.001758198 | ... T6: =Storage_modulus_G!T6/1000000 -> 0.032504386
A7: 3 | B7: 1a | C7: =Storage_modulus_G!C7/1000000 -> 1909.8533 | D7: =Storage_modulus_G!D7/1000000 -> 1782.3788 | E7: =Storage_modulus_G!E7/1000000 -> 1737.8008 | F7: =Storage_modulus_G!F7/1000000 -> 1621.8101 | G7: =Storage_modulus_G!G7/1000000 -> 1513.5612 | H7: =Storage_modulus_G!H7/1000000 -> 1432.1879 | I7: =Storage_modulus_G!I7/1000000 -> 1374.042 | J7: =Storage_modulus_G!J7/1000000 -> 1282.3306 | ... R7: =Storage_modulus_G!R7/1000000 -> 0.30974193
A8: 3 | B8: 2a | C8: =Storage_modulus_G!C8/1000000 -> 1963.3603 | D8: =Storage_modulus_G!D8/1000000 -> 1990.6733 | E8: =Storage_modulus_G!E8/1000000 -> 1857.8045 | F8: =Storage_modulus_G!F8/1000000 -> 1621.8101 | G8: =Storage_modulus_G!G8/1000000 -> 1667.2472 | H8: =Storage_modulus_G!H8/1000000 -> 1644.3717 | I8: =Storage_modulus_G!I8/1000000 -> 1621.8101 | J8: =Storage_modulus_G!J8/1000000 -> 1577.6113 | ... W8: =Storage_modulus_G!W8/1000000 -> 1.6218101
A9: 3 | B9: 3a | C9: =Storage_modulus_G!C9/1000000 -> 2285.5988 | D9: =Storage_modulus_G!D9/1000000 -> 2254.2392 | E9: =Storage_modulus_G!E9/1000000 -> 2162.7185 | F9: =Storage_modulus_G!F9/1000000 -> 2103.7784 | G9: =Storage_modulus_G!G9/1000000 -> 1990.6733 | H9: =Storage_modulus_G!H9/1000000 -> 1990.6733 | I9: =Storage_modulus_G!I9/1000000 -> 1936.422 | J9: =Storage_modulus_G!J9/1000000 -> 1883.6491 | ... W9: =Storage_modulus_G!W9/1000000 -> 176.1976
A10: 3 | B10: 4a | C10: =Storage_modulus_G!C10/1000000 -> 3318.9446 | D10: =Storage_modulus_G!D10/1000000 -> 3228.4941 | E10: =Storage_modulus_G!E10/1000000 -> 3054.9211 | F10: =Storage_modulus_G!F10/1000000 -> 3097.4193 | G10: =Storage_modulus_G!G10/1000000 -> 3013.006 | H10: =Storage_modulus_G!H10/1000000 -> 2930.8932 | I10: =Storage_modulus_G!I10/1000000 -> 2851.0183 | J10: =Storage_modulus_G!J10/1000000 -> 2660.7251 | ... W10: =Storage_modulus_G!W10/1000000 -> 413.99967
A11: 3 | B11: 1b | C11: =Storage_modulus_G!C11/1000000 -> 1435.4894 | D11: =Storage_modulus_G!D11/1000000 -> 1402.8137 | E11: =Storage_modulus_G!E11/1000000 -> 1358.3134 | F11: =Storage_modulus_G!F11/1000000 -> 1339.6767 | G11: =Storage_modulus_G!G11/1000000 -> 1288.2496 | H11: =Storage_modulus_G!H11/1000000 -> 1250.259 | I11: =Storage_modulus_G!I11/1000000 -> 1202.2644 | J11: =Storage_modulus_G!J11/1000000 -> 1114.2945 | ... T11: =Storage_modulus_G!T11/1000000 -> 43.351088
A12: 3 | B12: 2b | C12: =Storage_modulus_G!C12/1000000 -> 1621.8101 | D12: =Storage_modulus_G!D12/1000000 -> 1595.8791 | E12: =Storage_modulus_G!E12/1000000 -> 1548.8166 | F12: =Storage_modulus_G!F12/1000000 -> 1479.1084 | G12: =Storage_modulus_G!G12/1000000 -> 1422.3288 | H12: =Storage_modulus_G!H12/1000000 -> 1380.3843 | I12: =Storage_modulus_G!I12/1000000 -> 1318.2567 | J12: =Storage_modulus_G!J12/1000000 -> 1221.7997 | ... T12: =Storage_modulus_G!T12/1000000 -> 89.742879
A13: 3 | B13: 3b | C13: =Storage_modulus_G!C13/1000000 -> 2471.7241 | D13: =Storage_modulus_G!D13/1000000 -> 2398.8329 | E13: =Storage_modulus_G!E13/1000000 -> 2344.2288 | F13: =Storage_modulus_G!F13/1000000 -> 2290.8677 | G13: =Storage_modulus_G!G13/1000000 -> 2254.2392 | H13: =Storage_modulus_G!H13/1000000 -> 2187.7616 | I13: =Storage_modulus_G!I13/1000000 -> 2123.2445 | J13: =Storage_modulus_G!J13/1000000 -> 1995.2623 | ... T13: =Storage_modulus_G!T13/1000000 -> 148.93611
A14: 3 | B14: 4b | C14: =Storage_modulus_G!C14/1000000 -> 2999.1625 | D14: =Storage_modulus_G!D14/1000000 -> 2773.3201 | E14: =Storage_modulus_G!E14/1000000 -> 2798.9813 | F14: =Storage_modulus_G!F14/1000000 -> 2818.3829 | G14: =Storage_modulus_G!G14/1000000 -> 2648.5001 | H14: =Storage_modulus_G!H14/1000000 -> 2630.268 | I14: =Storage_modulus_G!I14/1000000 -> 2529.298 | J14: =Storage_modulus_G!J14/1000000 -> 2415.4608 | ... T14: =Storage_modulus_G!T14/1000000 -> 371.53523
A15: 4 | B15: 1
A16: 5 | B16: 1 | C16: =Storage_modulus_G!C16/1000000 -> 0.000147444 | D16: =Storage_modulus_G!D16/1000000 -> 0.000287623 | E16: =Storage_modulus_G!E16/1000000 -> 0.000636681 | F16: =Storage_modulus_G!F16/1000000 -> 0.001155434 | G16: =Storage_modulus_G!G16/1000000 -> 0.002115876 | H16: =Storage_modulus_G!H16/1000000 -> 0.004017182 | I16: =Storage_modulus_G!I16/1000000 -> 0.006252858 | J16: =Storage_modulus_G!J16/1000000 -> 0.007979229 | ... V16: =Storage_modulus_G!V16/1000000 -> 0.21936963
A17: 6 | B17: 1 | E17: =Storage_modulus_G!E17/1000000 -> 1.13e-07 | F17: =Storage_modulus_G!F17/1000000 -> 3.6e-07 | G17: =Storage_modulus_G!G17/1000000 -> 7.4e-07 | H17: =Storage_modulus_G!H17/1000000 -> 2.007e-06 | I17: =Storage_modulus_G!I17/1000000 -> 3.388e-06 | J17: =Storage_modulus_G!J17/1000000 -> 8.065e-06 | K17: =Storage_modulus_G!K17/1000000 -> 4.8789e-05 | L17: =Storage_modulus_G!L17/1000000 -> 8.7935e-05
A18: 6 | B18: 2 | C18: =Storage_modulus_G!C18/1000000 -> 0.000146038 | D18: =Storage_modulus_G!D18/1000000 -> 0.000183637 | E18: =Storage_modulus_G!E18/1000000 -> 0.00022348 | F18: =Storage_modulus_G!F18/1000000 -> 0.000267554 | G18: =Storage_modulus_G!G18/1000000 -> 0.000336437 | H18: =Storage_modulus_G!H18/1000000 -> 0.00044434 | I18: =Storage_modulus_G!I18/1000000 -> 0.000567956 | J18: =Storage_modulus_G!J18/1000000 -> 0.000702588 | ... L18: =Storage_modulus_G!L18/1000000 -> 0.001308432
A19: 6 | B19: 3 | C19: =Storage_modulus_G!C19/1000000 -> 0.001491434 | D19: =Storage_modulus_G!D19/1000000 -> 0.00151604 | E19: =Storage_modulus_G!E19/1000000 -> 0.001645295 | F19: =Storage_modulus_G!F19/1000000 -> 0.001815028 | G19: =Storage_modulus_G!G19/1000000 -> 0.001937803 | H19: =Storage_modulus_G!H19/1000000 -> 0.002172979 | I19: =Storage_modulus_G!I19/1000000 -> 0.002358244 | J19: =Storage_modulus_G!J19/1000000 -> 0.002644446 | ... L19: =Storage_modulus_G!L19/1000000 -> 0.003668317
A20: 6 | B20: 4 | C20: =Storage_modulus_G!C20/1000000 -> 0.029309257 | D20: =Storage_modulus_G!D20/1000000 -> 0.029309257 | E20: =Storage_modulus_G!E20/1000000 -> 0.030783971 | F20: =Storage_modulus_G!F20/1000000 -> 0.02979282 | G20: =Storage_modulus_G!G20/1000000 -> 0.031291865 | H20: =Storage_modulus_G!H20/1000000 -> 0.031291865 | I20: =Storage_modulus_G!I20/1000000 -> 0.031291865 | J20: =Storage_modulus_G!J20/1000000 -> 0.030783971 | ... L20: =Storage_modulus_G!L20/1000000 -> 0.032332886
A21: 6 | B21: 5 | C21: =Storage_modulus_G!C21/1000000 -> 1.0936e-05 | D21: =Storage_modulus_G!D21/1000000 -> 2.2718e-05 | E21: =Storage_modulus_G!E21/1000000 -> 4.8985e-05 | F21: =Storage_modulus_G!F21/1000000 -> 0.000103285 | G21: =Storage_modulus_G!G21/1000000 -> 0.000178049 | H21: =Storage_modulus_G!H21/1000000 -> 0.000291315 | I21: =Storage_modulus_G!I21/1000000 -> 0.000449022 | J21: =Storage_modulus_G!J21/1000000 -> 0.000609673 | ... AC21: =Storage_modulus_G!AC21/1000000 -> 0.006203783
A22: 6 | B22: 6 | C22: =Storage_modulus_G!C22/1000000 -> 4.0349e-05 | D22: =Storage_modulus_G!D22/1000000 -> 0.000140239 | E22: =Storage_modulus_G!E22/1000000 -> 0.00036438 | F22: =Storage_modulus_G!F22/1000000 -> 0.000729207 | G22: =Storage_modulus_G!G22/1000000 -> 0.001202025 | H22: =Storage_modulus_G!H22/1000000 -> 0.00169411 | I22: =Storage_modulus_G!I22/1000000 -> 0.002216013 | J22: =Storage_modulus_G!J22/1000000 -> 0.002751217 | ... R22: =Storage_modulus_G!R22/1000000 -> 0.005588562
A23: 6 | B23: 7 | C23: =Storage_modulus_G!C23/1000000 -> 9.5148e-05 | D23: =Storage_modulus_G!D23/1000000 -> 0.000582987 | E23: =Storage_modulus_G!E23/1000000 -> 0.001492334 | F23: =Storage_modulus_G!F23/1000000 -> 0.002515637 | G23: =Storage_modulus_G!G23/1000000 -> 0.00341568 | H23: =Storage_modulus_G!H23/1000000 -> 0.004501401 | I23: =Storage_modulus_G!I23/1000000 -> 0.00492294 | J23: =Storage_modulus_G!J23/1000000 -> 0.00492294 | ... N23: =Storage_modulus_G!N23/1000000 -> 0.005630409
A24: 7 | B24: 1 | C24: 271.104 | D24: 66.449 | E24: 46.882 | F24: 34.177 | G24: 26.89 | H24: 20.034 | I24: 16.11 | J24: 13.385 | K24: 10.647 | L24: 8.561 | M24: 6.174 | N24: 4.262 | O24: 3.465 | P24: 2.61 | Q24: 1.669 | R24: 1.313 | S24: 1.079
A25: 7 | B25: 2 | C25: 9496.826 | D25: 4288.317 | E25: 2018.054 | F25: 1031.461 | G25: 634.878 | H25: 437.78 | I25: 367.301 | J25: 386.762 | K25: 374.965 | L25: 292.663 | M25: 243.025 | N25: 230.796 | O25: 126.806 | P25: 22.608 | Q25: 3.417 | R25: 3.019 | S25: 2.695 | T25: 2.455 | U25: 2.261 | V25: 2.082 | W25: 1.977
A26: 7 | B26: 3 | C26: 16762.168 | D26: 16548.172 | E26: 16762.168 | F26: 16128.322 | G26: 12001.653 | H26: 7556.979 | I26: 4349.034 | J26: 1960.699 | K26: 1142.973 | L26: 701.427 | M26: 521.956 | N26: 199.116 | O26: 83.108 | P26: 16.463 | Q26: 2.522 | R26: 2.365 | S26: 2.027 | T26: 1.694 | U26: 1.452 | V26: 1.31 | W26: 1.137
A27: 8 | B27: 1 | C27: 4936.118 | D27: 4867.322 | E27: 4781.327 | F27: 4600.737 | G27: 4480.344 | H27: 4325.553 | I27: 4187.96 | J27: 4033.169 | K27: 3861.179 | L27: 3620.393 | M27: 3405.405 | N27: 3138.82 | O27: 2863.636 | P27: 2631.45 | Q27: 2399.263 | R27: 2141.277 | S27: 1934.889 | T27: 1737.101 | U27: 1565.11 | V27: 1453.317 | W27: 1358.722 | X27: 1264.127 | Y27: 1143.735 | Z27: 1031.941 | AA27: 902.948 | AB27: 799.754 | AC27: 705.159 | AD27: 670.761 | AE27: 610.565 | AF27: 558.968 | AG27: 533.169 | AH27: 524.57 | AI27: 472.973 | AJ27: 455.774 | AK27: 421.376 | AL27: 386.978
A28: 8 | B28: 2 | C28: 5417.69 | D28: 5374.693 | E28: 5280.098 | F28: 5090.909 | G28: 4807.125 | H28: 4583.538 | I28: 4402.948 | J28: 4222.358 | K28: 3998.771 | L28: 3792.383 | M28: 3517.199 | N28: 3250.614 | O28: 2932.432 | P28: 2622.849 | Q28: 2347.665 | R28: 2132.678 | S28: 1891.892 | T28: 1711.302 | U28: 1539.311 | V28: 1375.921 | W28: 1272.727 | X28: 1152.333 | Y28: 1040.54 | Z28: 911.548 | AA28: 791.154 | AB28: 644.963 | AC28: 541.769 | AD28: 472.973 | AE28: 464.373 | AF28: 421.376 | AG28: 395.577 | AH28: 378.378 | AI28: 378.378 | AJ28: 343.98 | AK28: 318.181 | AL28: 275.184
A29: 8 | B29: 3 | C29: 6054.054 | D29: 5933.661 | E29: 5770.27 | F29: 5598.28 | G29: 5391.892 | H29: 5108.108 | I29: 4815.725 | J29: 4583.538 | K29: 4334.152 | L29: 4093.366 | M29: 3826.781 | N29: 3585.995 | O29: 3379.607 | P29: 3138.82 | Q29: 2932.432 | R29: 2708.845 | S29: 2511.056 | T29: 2304.668 | U29: 2158.476 | V29: 2046.683 | W29: 1909.091 | X29: 1814.496 | Y29: 1668.304 | Z29: 1530.713 | AA29: 1410.319 | AB29: 1272.727 | AC29: 1195.332 | AD29: 1126.535 | AE29: 1092.137 | AF29: 997.542 | AG29: 945.945 | AH29: 859.951 | AI29: 825.553 | AJ29: 730.958 | AK29: 670.761 | AL29: 644.963
A30: 8 | B30: 4 | C30: 5546.683 | D30: 5512.285 | E30: 5383.292 | F30: 5194.103 | G30: 4936.118 | H30: 4600.737 | I30: 4291.155 | J30: 3921.376 | K30: 3646.191 | L30: 3448.403 | M30: 3181.818 | N30: 2984.029 | O30: 2777.64 | P30: 2588.452 | Q30: 2373.464 | R30: 2227.273 | S30: 2072.482 | T30: 1917.691 | U30: 1788.697 | V30: 1668.304 | W30: 1539.311 | X30: 1410.319 | Y30: 1307.124 | Z30: 1186.732 | AA30: 1066.339 | AB30: 928.747 | AC30: 859.951 | AD30: 791.154 | AE30: 748.157 | AF30: 679.361 | AG30: 619.165 | AH30: 610.565 | AI30: 576.167 | AJ30: 541.769 | AK30: 498.771 | AL30: 455.774
A31: 9 | B31: 1 | C31: =Storage_modulus_G!C31/1000000 -> 1.3001696e+09 | D31: =Storage_modulus_G!D31/1000000 -> 1.3365955e+09 | E31: =Storage_modulus_G!E31/1000000 -> 1.3365955e+09 | F31: =Storage_modulus_G!F31/1000000 -> 1.1117317e+09 | G31: =Storage_modulus_G!G31/1000000 -> 7.6913044e+08 | H31: =Storage_modulus_G!H31/1000000 -> 6.7452803e+08 | I31: =Storage_modulus_G!I31/1000000 -> 5.7543994e+08 | J31: =Storage_modulus_G!J31/1000000 -> 4.4258837e+08 | ... R31: =Storage_modulus_G!R31/1000000 -> 918332.6
A32: 9 | B32: 2 | C32: =Storage_modulus_G!C32/1000000 -> 93972331 | D32: =Storage_modulus_G!D32/1000000 -> 96382902 | E32: =Storage_modulus_G!E32/1000000 -> 96382902 | F32: =Storage_modulus_G!F32/1000000 -> 78162780 | G32: =Storage_modulus_G!G32/1000000 -> 60117374 | H32: =Storage_modulus_G!H32/1000000 -> 63241185 | I32: =Storage_modulus_G!I32/1000000 -> 58479008 | J32: =Storage_modulus_G!J32/1000000 -> 52601727 | ... R32: =Storage_modulus_G!R32/1000000 -> 103752.84
A33: 9 | B33: 3 | C33: =Storage_modulus_G!C33/1000000 -> 11168632 | D33: =Storage_modulus_G!D33/1000000 -> 10592537 | E33: =Storage_modulus_G!E33/1000000 -> 10327614 | F33: =Storage_modulus_G!F33/1000000 -> 8590135.2 | G33: =Storage_modulus_G!G33/1000000 -> 4819478 | H33: =Storage_modulus_G!H33/1000000 -> 3698281.8 | I33: =Storage_modulus_G!I33/1000000 -> 2844461.1 | J33: =Storage_modulus_G!J33/1000000 -> 2249054.6 | ... Q33: =Storage_modulus_G!Q33/1000000 -> 62950.618
A34: 9 | B34: 4 | C34: =Storage_modulus_G!C34/1000000 -> 1595879.1 | D34: =Storage_modulus_G!D34/1000000 -> 1475706.5 | E34: =Storage_modulus_G!E34/1000000 -> 1399587.3 | F34: =Storage_modulus_G!F34/1000000 -> 944060.88 | G34: =Storage_modulus_G!G34/1000000 -> 417830.37 | H34: =Storage_modulus_G!H34/1000000 -> 247172.41 | I34: =Storage_modulus_G!I34/1000000 -> 190107.83 | J34: =Storage_modulus_G!J34/1000000 -> 142232.88 | ... Q34: =Storage_modulus_G!Q34/1000000 -> 1099.0058
A35: 9 | B35: 5 | C35: =Storage_modulus_G!C35/1000000 -> 138675.58 | D35: =Storage_modulus_G!D35/1000000 -> 121338.89 | E35: =Storage_modulus_G!E35/1000000 -> 103752.84 | F35: =Storage_modulus_G!F35/1000000 -> 62950.618 | G35: =Storage_modulus_G!G35/1000000 -> 2177.7098 | H35: =Storage_modulus_G!H35/1000000 -> 1428.894 | I35: =Storage_modulus_G!I35/1000000 -> 845.27885 | J35: =Storage_modulus_G!J35/1000000 -> 474.24199 | K35: =Storage_modulus_G!K35/1000000 -> 12.274392
A36: 9 | B36: 6 | C36: =Storage_modulus_G!C36/1000000 -> 26424.088 | D36: =Storage_modulus_G!D36/1000000 -> 25118.864 | E36: =Storage_modulus_G!E36/1000000 -> 23173.946 | F36: =Storage_modulus_G!F36/1000000 -> 14454.398 | G36: =Storage_modulus_G!G36/1000000 -> 824.13812 | H36: =Storage_modulus_G!H36/1000000 -> 426.57952 | I36: =Storage_modulus_G!I36/1000000 -> 336.51157 | J36: =Storage_modulus_G!J36/1000000 -> 103.27614
A37: 9 | B37: 7 | C37: =Storage_modulus_G!C37/1000000 -> 2296.1486 | D37: =Storage_modulus_G!D37/1000000 -> 2065.3802 | E37: =Storage_modulus_G!E37/1000000 -> 1857.8045 | F37: =Storage_modulus_G!F37/1000000 -> 963.82902 | G37: =Storage_modulus_G!G37/1000000 -> 54.954087 | H37: =Storage_modulus_G!H37/1000000 -> 30.83188 | I37: =Storage_modulus_G!I37/1000000 -> 20.749135 | J37: =Storage_modulus_G!J37/1000000 -> 5.7279603 | K37: =Storage_modulus_G!K37/1000000 -> 0.11402498
A38: 10 | B38: 1 | C38: =Storage_modulus_G!C38/1000000 -> 3622.4205 | D38: =Storage_modulus_G!D38/1000000 -> 3524.3559 | E38: =Storage_modulus_G!E38/1000000 -> 3245.8096 | F38: =Storage_modulus_G!F38/1000000 -> 2948.5376 | G38: =Storage_modulus_G!G38/1000000 -> 2791.0567 | H38: =Storage_modulus_G!H38/1000000 -> 2570.4652 | I38: =Storage_modulus_G!I38/1000000 -> 2210.3332 | J38: =Storage_modulus_G!J38/1000000 -> 1703.0506 | ... S38: =Storage_modulus_G!S38/1000000 -> 0.72138059
A39: 11 | B39: 1 | C39: =Storage_modulus_G!C39/1000000 -> 4115.6942 | D39: =Storage_modulus_G!D39/1000000 -> 4115.6942 | E39: =Storage_modulus_G!E39/1000000 -> 3846.514 | F39: =Storage_modulus_G!F39/1000000 -> 3687.2899 | G39: =Storage_modulus_G!G39/1000000 -> 3504.8993 | H39: =Storage_modulus_G!H39/1000000 -> 3303.4813 | I39: =Storage_modulus_G!I39/1000000 -> 3140.0747 | J39: =Storage_modulus_G!J39/1000000 -> 3035.6532 | ... V39: =Storage_modulus_G!V39/1000000 -> 16.192062

Sheet Loss_modulus_G
A1: Study_id | B1: Instance
A2: 1 | B2: 1
A3: 1 | B3: 2
A4: 1 | B4: 3
A5: 1 | B5: 4
A6: 2 | B6: 1 | C6: 73.988 | D6: 100.961 | E6: 136.131 | F6: 183.552 | G6: 256.53 | H6: 358.523 | I6: 507.094 | J6: 708.708 | K6: 1026.651 | L6: 1541.539 | M6: 2399.177 | N6: 3434.2 | O6: 4915.738 | P6: 7469.863 | Q6: 10821.013 | R6: 14765.996 | S6: 19909.726 | T6: 28160.253
A7: 3 | B7: 1
A8: 3 | B8: 2
A9: 3 | B9: 3
A10: 3 | B10: 4
A11: 3 | B11: 1
A12: 3 | B12: 2
A13: 3 | B13: 3
A14: 3 | B14: 4
A15: 4 | B15: 1
A16: 5 | B16: 1 | C16: 1898.591 | D16: 2724.545 | E16: 4127.493 | F16: 6031.038 | G16: 8973.069 | H16: 12876.681 | I16: 17036.191 | J16: 18478.682 | K16: 26757.837 | L16: 33232.924 | M16: 39098.214 | N16: 47261.752 | O16: 53148.411 | P16: 60310.395 | Q16: 69058.257 | R16: 78364.187 | S16: 83477.322 | T16: 87332.631 | U16: 96452.562 | V16: 100907.06
A17: 6 | B17: 1
A18: 6 | B18: 2
A19: 6 | B19: 3
A20: 6 | B20: 4
A21: 6 | B21: 5
A22: 6 | B22: 6
A23: 6 | B23: 7
A24: 7 | B24: 1 | C24: 1220.086 | D24: 918.996 | E24: 669.939 | F24: 556.624 | G24: 452.503 | H24: 388.463 | I24: 322.757 | J24: 271.104 | K24: 222.807 | L24: 195.49 | M24: 171.522 | N24: 150.493 | O24: 126.408 | P24: 113.354 | Q24: 98.378 | R24: 86.317 | S24: 74.101 | T24: 62.924 | U24: 50.599 | V24: 42.501 | W24: 33.077
A25: 7 | B25: 2 | C25: 7039.366 | D25: 4244.266 | E25: 2722.561 | F25: 1465.276 | G25: 979.561 | H25: 634.878 | I25: 572.595 | J25: 538.197 | K25: 490.437 | L25: 411.481 | M25: 382.789 | N25: 334.706 | O25: 208.154 | P25: 64.813 | Q25: 7.567 | R25: 6.349 | S25: 5.551 | T25: 4.706 | U25: 4.115 | V25: 3.382 | W25: 2.867
A26: 7 | B26: 3 | C26: 46257.123 | D26: 33119.923 | E26: 24331.041 | F26: 15719.137 | G26: 7654.707 | H26: 4819.874 | I26: 3451.012 | J26: 2535.234 | K26: 1659.075 | L26: 1187.892 | M26: 942.607 | N26: 495.807 | O26: 308.205 | P26: 65.105 | Q26: 14.478 | R26: 12.732 | S26: 11.054 | T26: 8.332 | U26: 6.872 | V26: 5.314 | W26: 4.163
A27: 8 | B27: 1
A28: 8 | B28: 2
A29: 8 | B29: 3
A30: 8 | B30: 4
A31: 9 | B31: 1 | C31: 4.0831939e+13 | D31: 3.9994475e+13 | E31: 4.2756289e+13 | F31: 5.2119471e+13 | G31: 6.2373484e+13 | H31: 7.9615935e+13 | I31: 4.9888449e+13 | J31: 4.5708819e+13 | K31: 3.6559479e+13 | L31: 3.7411059e+13 | M31: 3.0619634e+13 | N31: 2.1928049e+13 | O31: 1.2882496e+13 | P31: 5.1880004e+12 | Q31: 1.8663797e+12
A32: 9 | B32: 2 | C32: 2.7227013e+12 | D32: 3.1117163e+12 | E32: 3.801894e+12 | F32: 4.9545019e+12 | G32: 3.8815037e+12 | H32: 5.1880004e+12 | I32: 3.5563132e+12 | J32: 2.2284351e+12 | K32: 2.3823195e+12 | L32: 2.7861212e+12 | M32: 3.4753616e+12 | N32: 3.1117163e+12 | O32: 1.3995873e+12 | P32: 4.7097733e+11 | Q32: 3.4276779e+10
A33: 9 | B33: 3 | C33: 1.3273945e+11 | D33: 1.6595869e+11 | E33: 2.6424088e+11 | F33: 7.6736149e+11 | G33: 3.8547836e+11 | H33: 3.0199517e+11 | I33: 2.529298e+11 | J33: 1.6982437e+11 | K33: 1.6218101e+11 | L33: 1.8113401e+11 | M33: 2.1183611e+11 | N33: 2.0276827e+11 | O33: 1.4521116e+11 | P33: 4.6773514e+10 | Q33: 7.2443596e+09
A34: 9 | B34: 4 | C34: 2.5703958e+10 | D34: 2.9376497e+10 | E34: 3.8282474e+10 | F34: 1.4859356e+11 | G34: 3.4276779e+10 | H34: 1.5066071e+10 | I34: 1.5776113e+10 | J34: 1.2618275e+10 | K34: 1.3803843e+10 | L34: 1.2618275e+10 | M34: 1.2912193e+10 | N34: 1.2912193e+10 | O34: 9.8855309e+09 | P34: 3.5645113e+09 | Q34: 8.0352612e+08 | R34: 1.4223288e+08
A35: 9 | B35: 5 | C35: 3.1188896e+09 | D35: 3.1188896e+09 | E35: 4.0644333e+09 | F35: 3.3573761e+10 | G35: 9.6161228e+08 | H35: 3.0269134e+08 | I35: 1.5559656e+08 | J35: 73113908 | K35: 6353309.3
A36: 9 | B36: 6 | C36: 5.5207744e+08 | D36: 4.7206304e+08 | E36: 6.886523e+08 | F36: 3.7239171e+09 | G36: 2.4774221e+08 | H36: 59841160 | I36: 25763212 | J36: 11324004 | K36: 4073802.8
A37: 9 | B37: 7 | C37: 57279603 | D37: 76383578 | E37: 97498964 | F37: 3.3806484e+08 | G37: 17258379 | H37: 3491403.2 | I37: 1342765 | J37: 494310.69 | K37: 116949.94
A38: 10 | B38: 1 | C38: 1.0082671e+08 | D38: 1.0506405e+08 | E38: 1.0506405e+08 | F38: 1.0221985e+08 | G38: 1.0082671e+08 | H38: 99452646 | I38: 1.4806114e+08 | J38: 2.9810838e+08 | K38: 2.6711505e+08 | L38: 55126301 | M38: 13413218 | N38: 5807710.2 | O38: 2884505.8 | P38: 1911117.7 | Q38: 1119097.1 | R38: 721380.59 | S38: 105642.29
A39: 11 | B39: 1

Sheet converted_MPa_Loss_modulus_G
A1: Study_id | B1: Instance
A2: 1 | B2: 1
A3: 1 | B3: 2
A4: 1 | B4: 3
A5: 1 | B5: 4
A6: 2 | B6: 1 | C6: =IF(ISBLANK(Loss_modulus_G!C6),Tandelta!C6*converted_MPa_Storage_modulus_G!C6,Loss_modulus_G!C6/1000000) -> 7.3988e-05 | D6: =Loss_modulus_G!D6/1000000 -> 0.000100961 | E6: =Loss_modulus_G!E6/1000000 -> 0.000136131 | F6: =Loss_modulus_G!F6/1000000 -> 0.000183552 | G6: =Loss_modulus_G!G6/1000000 -> 0.00025653 | H6: =Loss_modulus_G!H6/1000000 -> 0.000358523 | I6: =Loss_modulus_G!I6/1000000 -> 0.000507094 | J6: =Loss_modulus_G!J6/1000000 -> 0.000708708 | K6: =Loss_modulus_G!K6/1000000 -> 0.001026651 | ... T6: =Loss_modulus_G!T6/1000000 -> 0.028160253
A7: 3 | B7: 1a
A8: 3 | B8: 2a
A9: 3 | B9: 3a
A10: 3 | B10: 4a
A11: 3 | B11: 1b
A12: 3 | B12: 2b
A13: 3 | B13: 3b
A14: 3 | B14: 4b
A15: 4 | B15: 1
A16: 5 | B16: 1 | C16: =IF(ISBLANK(Loss_modulus_G!C16),Tandelta!C16*converted_MPa_Storage_modulus_G!C16,Loss_modulus_G!C16/1000000) -> 0.001898591 | D16: =Loss_modulus_G!D16/1000000 -> 0.002724545 | E16: =Loss_modulus_G!E16/1000000 -> 0.004127493 | F16: =Loss_modulus_G!F16/1000000 -> 0.006031038 | G16: =Loss_modulus_G!G16/1000000 -> 0.008973069 | H16: =Loss_modulus_G!H16/1000000 -> 0.012876681 | I16: =Loss_modulus_G!I16/1000000 -> 0.017036191 | J16: =Loss_modulus_G!J16/1000000 -> 0.018478682 | K16: =Loss_modulus_G!K16/1000000 -> 0.026757837 | ... V16: =Loss_modulus_G!V16/1000000 -> 0.10090706
A17: 6 | B17: 1
