Workbook

Sheet Ang_freq_converted_f2
A1: Study_id | B1: Instance | C1: fill
A2: 1 | B2: 1 | D2: 1 | E2: 1.2656305 | F2: 1.579777 | G2: 1.9994139 | H2: 2.4956954 | I2: 3.1368191 | J2: 3.9426422 | K2: 5.0595552 | L2: 6.2284954 | M2: 7.8285448 | N2: 10.046297 | O2: 12.45334 | P2: 15.652501 | Q2: 19.810283 | R2: 25.072497 | S2: 31.732516 | T2: 40.16164 | U2: 50.1303 | V2: 63.887552 | W2: 78.104856 | X2: 99.539162 | Y2: 124.24612 | Z2: 157.24968 | AA2: 199.01999 | AB2: 250.14659 | AC2: 316.59314 | AD2: 395.17583 | AE2: 496.69326
A3: 1 | B3: 2 | D3: 1 | E3: 1.2656305 | F3: 1.579777 | G3: 1.9994139 | H3: 2.4956954 | I3: 3.1368191 | J3: 3.9426422 | K3: 5.0595552 | L3: 6.2284954 | M3: 7.8285448 | N3: 10.046297 | O3: 12.45334 | P3: 15.652501 | Q3: 19.810283 | R3: 25.072497 | S3: 31.732516 | T3: 40.16164 | U3: 50.1303 | V3: 63.887552 | W3: 78.104856 | X3: 99.539162 | Y3: 124.24612 | Z3: 157.24968 | AA3: 199.01999 | AB3: 250.14659 | AC3: 316.59314 | AD3: 395.17583 | AE3: 496.69326
A4: 1 | B4: 3 | D4: 1 | E4: 1.2656305 | F4: 1.579777 | G4: 1.9994139 | H4: 2.4956954 | I4: 3.1368191 | J4: 3.9426422 | K4: 5.0595552 | L4: 6.2284954 | M4: 7.8285448 | N4: 10.046297 | O4: 12.45334 | P4: 15.652501 | Q4: 19.810283 | R4: 25.072497 | S4: 31.732516 | T4: 40.16164 | U4: 50.1303 | V4: 63.887552 | W4: 78.104856 | X4: 99.539162 | Y4: 124.24612 | Z4: 157.24968 | AA4: 199.01999 | AB4: 250.14659 | AC4: 316.59314 | AD4: 395.17583 | AE4: 496.69326
A5: 1 | B5: 4 | D5: 1 | E5: 1.2656305 | F5: 1.579777 | G5: 1.9994139 | H5: 2.4956954 | I5: 3.1368191 | J5: 3.9426422 | K5: 5.0595552 | L5: 6.2284954 | M5: 7.8285448 | N5: 10.046297 | O5: 12.45334 | P5: 15.652501 | Q5: 19.810283 | R5: 25.072497 | S5: 31.732516 | T5: 40.16164 | U5: 50.1303 | V5: 63.887552 | W5: 78.104856 | X5: 99.539162 | Y5: 124.24612 | Z5: 157.24968 | AA5: 199.01999 | AB5: 250.14659 | AC5: 316.59314 | AD5: 395.17583 | AE5: 496.69326
A6: 1 | B6: 5 | D6: 1 | E6: 1.2656305 | F6: 1.579777 | G6: 1.9994139 | H6: 2.4956954 | I6: 3.1368191 | J6: 3.9426422 | K6: 5.0595552 | L6: 6.2284954 | M6: 7.8285448 | N6: 10.046297 | O6: 12.45334 | P6: 15.652501 | Q6: 19.810283 | R6: 25.072497 | S6: 31.732516 | T6: 40.16164 | U6: 50.1303 | V6: 63.887552 | W6: 78.104856 | X6: 99.539162 | Y6: 124.24612 | Z6: 157.24968 | AA6: 199.01999 | AB6: 250.14659 | AC6: 316.59314 | AD6: 395.17583 | AE6: 496.69326
A7: 2 | B7: 1 | C7: loss | D7: 0.99574896 | E7: 1.5977737 | F7: 2.5097472 | G7: 3.975987 | H7: 6.3257217 | I7: 9.9787222 | J7: 15.808473 | K7: 24.937606 | L7: 39.506609 | M7: 62.587087 | N7: 100
A8: 2 | B8: 2 | C8: loss | D8: 0.99574896 | E8: 1.5977737 | F8: 2.5097472 | G8: 3.975987 | H8: 6.3257217 | I8: 9.9787222 | J8: 15.808473 | K8: 24.937606 | L8: 39.506609 | M8: 62.587087 | N8: 100
A9: 2 | B9: 3 | C9: loss | D9: 0.99574896 | E9: 1.5977737 | F9: 2.5097472 | G9: 3.975987 | H9: 6.3257217 | I9: 9.9787222 | J9: 15.808473 | K9: 24.937606 | L9: 39.506609 | M9: 62.587087 | N9: 100
A10: 2 | B10: 4 | C10: loss | D10: 0.99574896 | E10: 1.5977737 | F10: 2.5097472 | G10: 3.975987 | H10: 6.3257217 | I10: 9.9787222 | J10: 15.808473 | K10: 24.937606 | L10: 39.506609 | M10: 62.587087 | N10: 100
A11: 3 | B11: 1 | C11: loss | D11: 0.10346139 | E11: 0.15043189 | F11: 0.22122163 | G11: 0.32532338 | H11: 0.46240725 | I11: 0.71968567 | J11: 1 | K11: 1.5043189 | L11: 2.2374518 | M11: 3.2532338 | N11: 4.6768209 | O11: 7.0354299 | P11: 10.346139 | Q11: 15.214792 | R11: 22.122163 | S11: 32.532338 | T11: 47.301711 | U11: 68.776239 | V11: 102.29448 | W11: 148.73521 | X11: 218.72654 | Y11: 329.03446 | Z11: 473.01711
A12: 3 | B12: 2 | C12: loss | D12: 0.10346139 | E12: 0.15043189 | F12: 0.22122163 | G12: 0.32532338 | H12: 0.46240725 | I12: 0.71968567 | J12: 1 | K12: 1.5043189 | L12: 2.2374518 | M12: 3.2532338 | N12: 4.6768209 | O12: 7.0354299 | P12: 10.346139 | Q12: 15.214792 | R12: 22.122163 | S12: 32.532338 | T12: 47.301711 | U12: 68.776239 | V12: 102.29448 | W12: 148.73521 | X12: 218.72654 | Y12: 329.03446 | Z12: 473.01711
A13: 3 | B13: 3 | C13: loss | D13: 0.10346139 | E13: 0.15043189 | F13: 0.22122163 | G13: 0.32532338 | H13: 0.46240725 | I13: 0.71968567 | J13: 1 | K13: 1.5043189 | L13: 2.2374518 | M13: 3.2532338 | N13: 4.6768209 | O13: 7.0354299 | P13: 10.346139 | Q13: 15.214792 | R13: 22.122163 | S13: 32.532338 | T13: 47.301711 | U13: 68.776239 | V13: 102.29448 | W13: 148.73521 | X13: 218.72654 | Y13: 329.03446 | Z13: 473.01711
A14: 3 | B14: 4 | C14: loss | D14: 0.10346139 | E14: 0.15043189 | F14: 0.22122163 | G14: 0.32532338 | H14: 0.46240725 | I14: 0.71968567 | J14: 1 | K14: 1.5043189 | L14: 2.2374518 | M14: 3.2532338 | N14: 4.6768209 | O14: 7.0354299 | P14: 10.346139 | Q14: 15.214792 | R14: 22.122163 | S14: 32.532338 | T14: 47.301711 | U14: 68.776239 | V14: 102.29448 | W14: 148.73521 | X14: 218.72654 | Y14: 329.03446 | Z14: 473.01711
A15: 4 | B15: 1 | C15: loss | D15: =6.283185*Angular_frequency!C15 -> 0.061572762 | E15: =6.283185*Angular_frequency!D15 -> 0.12254335 | F15: =6.283185*Angular_frequency!E15 -> 0.18370201 | G15: =6.283185*Angular_frequency!F15 -> 0.24636922 | H15: =6.283185*Angular_frequency!G15 -> 0.36932662 | I15: =6.283185*Angular_frequency!H15 -> 0.63150624 | J15: =6.283185*Angular_frequency!I15 -> 0.98578962 | K15: =6.283185*Angular_frequency!J15 -> 1.5702979 | ... X15: =6.283185*Angular_frequency!W15 -> 621.9912
A16: 4 | B16: 2 | C16: loss | D16: =6.283185*Angular_frequency!C16 -> 0.061572762 | E16: =6.283185*Angular_frequency!D16 -> 0.12254335 | F16: =6.283185*Angular_frequency!E16 -> 0.18370201 | G16: =6.283185*Angular_frequency!F16 -> 0.24636922 | H16: =6.283185*Angular_frequency!G16 -> 0.36932662 | I16: =6.283185*Angular_frequency!H16 -> 0.63150624 | J16: =6.283185*Angular_frequency!I16 -> 0.98578962 | K16: =6.283185*Angular_frequency!J16 -> 1.5702979 | ... X16: =6.283185*Angular_frequency!W16 -> 621.9912
A17: 4 | B17: 3 | C17: loss | D17: =6.283185*Angular_frequency!C17 -> 0.061572762 | E17: =6.283185*Angular_frequency!D17 -> 0.12254335 | F17: =6.283185*Angular_frequency!E17 -> 0.18370201 | G17: =6.283185*Angular_frequency!F17 -> 0.24636922 | H17: =6.283185*Angular_frequency!G17 -> 0.36932662 | I17: =6.283185*Angular_frequency!H17 -> 0.63150624 | J17: =6.283185*Angular_frequency!I17 -> 0.98578962 | K17: =6.283185*Angular_frequency!J17 -> 1.5702979 | ... X17: =6.283185*Angular_frequency!W17 -> 621.9912
A18: 5 | B18: 1 | C18: loss | D18: 0.1 | E18: 0.12017735 | F18: 0.14442595 | G18: 0.17224313 | H18: 0.2134363 | I18: 0.24876378 | J18: 0.29895771 | K18: 0.36762937 | L18: 0.44180723 | M18: 0.53503399 | N18: 0.63808429 | O18: 0.76098259 | P18: 0.92155929 | Q18: 1.1160196 | R18: 1.3515135 | S18: 1.6242131 | T18: 1.9669421 | U18: 2.3638188 | V18: 2.7975955 | W18: 3.4402133 | X18: 4.0404539 | Y18: 4.9685607 | Z18: 5.925531 | AA18: 7.175891 | AB18: 8.5580044 | AC18: 10.363849 | AD18: 12.647234 | AE18: 15.199111 | AF18: 18.265888 | AG18: 22.120216 | AH18: 26.787854 | AI18: 31.947332 | AJ18: 38.688612 | AK18: 46.852385 | AL18: 56.305954 | AM18: 68.711404 | AN18: 80.084353 | AO18: 97.728712 | AP18: 115.66259 | AQ18: 143.32412 | AR18: 170.92908 | AS18: 206.99722 | AT18: 276.91746
A19: 5 | B19: 2 | C19: loss | D19: 0.1 | E19: 0.12017735 | F19: 0.14442595 | G19: 0.17224313 | H19: 0.2134363 | I19: 0.24876378 | J19: 0.29895771 | K19: 0.36762937 | L19: 0.44180723 | M19: 0.53503399 | N19: 0.63808429 | O19: 0.76098259 | P19: 0.92155929 | Q19: 1.1160196 | R19: 1.3515135 | S19: 1.6242131 | T19: 1.9669421 | U19: 2.3638188 | V19: 2.7975955 | W19: 3.4402133 | X19: 4.0404539 | Y19: 4.9685607 | Z19: 5.925531 | AA19: 7.175891 | AB19: 8.5580044 | AC19: 10.363849 | AD19: 12.647234 | AE19: 15.199111 | AF19: 18.265888 | AG19: 22.120216 | AH19: 26.787854 | AI19: 31.947332 | AJ19: 38.688612 | AK19: 46.852385 | AL19: 56.305954 | AM19: 68.711404 | AN19: 80.084353 | AO19: 97.728712 | AP19: 115.66259 | AQ19: 143.32412 | AR19: 170.92908 | AS19: 206.99722 | AT19: 276.91746
A20: 5 | B20: 3 | C20: loss | D20: 0.1 | E20: 0.12017735 | F20: 0.14442595 | G20: 0.17224313 | H20: 0.2134363 | I20: 0.24876378 | J20: 0.29895771 | K20: 0.36762937 | L20: 0.44180723 | M20: 0.53503399 | N20: 0.63808429 | O20: 0.76098259 | P20: 0.92155929 | Q20: 1.1160196 | R20: 1.3515135 | S20: 1.6242131 | T20: 1.9669421 | U20: 2.3638188 | V20: 2.7975955 | W20: 3.4402133 | X20: 4.0404539 | Y20: 4.9685607 | Z20: 5.925531 | AA20: 7.175891 | AB20: 8.5580044 | AC20: 10.363849 | AD20: 12.647234 | AE20: 15.199111 | AF20: 18.265888 | AG20: 22.120216 | AH20: 26.787854 | AI20: 31.947332 | AJ20: 38.688612 | AK20: 46.852385 | AL20: 56.305954 | AM20: 68.711404 | AN20: 80.084353 | AO20: 97.728712 | AP20: 115.66259 | AQ20: 143.32412 | AR20: 170.92908 | AS20: 206.99722 | AT20: 276.91746
A21: 5 | B21: 4 | C21: loss | D21: 0.1 | E21: 0.12017735 | F21: 0.14442595 | G21: 0.17224313 | H21: 0.2134363 | I21: 0.24876378 | J21: 0.29895771 | K21: 0.36762937 | L21: 0.44180723 | M21: 0.53503399 | N21: 0.63808429 | O21: 0.76098259 | P21: 0.92155929 | Q21: 1.1160196 | R21: 1.3515135 | S21: 1.6242131 | T21: 1.9669421 | U21: 2.3638188 | V21: 2.7975955 | W21: 3.4402133 | X21: 4.0404539 | Y21: 4.9685607 | Z21: 5.925531 | AA21: 7.175891 | AB21: 8.5580044 | AC21: 10.363849 | AD21: 12.647234 | AE21: 15.199111 | AF21: 18.265888 | AG21: 22.120216 | AH21: 26.787854 | AI21: 31.947332 | AJ21: 38.688612 | AK21: 46.852385 | AL21: 56.305954 | AM21: 68.711404 | AN21: 80.084353 | AO21: 97.728712 | AP21: 115.66259 | AQ21: 143.32412 | AR21: 170.92908 | AS21: 206.99722 | AT21: 276.91746
A22: 5 | B22: 5 | C22: loss | D22: 0.1 | E22: 0.12017735 | F22: 0.14442595 | G22: 0.17224313 | H22: 0.2134363 | I22: 0.24876378 | J22: 0.29895771 | K22: 0.36762937 | L22: 0.44180723 | M22: 0.53503399 | N22: 0.63808429 | O22: 0.76098259 | P22: 0.92155929 | Q22: 1.1160196 | R22: 1.3515135 | S22: 1.6242131 | T22: 1.9669421 | U22: 2.3638188 | V22: 2.7975955 | W22: 3.4402133 | X22: 4.0404539 | Y22: 4.9685607 | Z22: 5.925531 | AA22: 7.175891 | AB22: 8.5580044 | AC22: 10.363849 | AD22: 12.647234 | AE22: 15.199111 | AF22: 18.265888 | AG22: 22.120216 | AH22: 26.787854 | AI22: 31.947332 | AJ22: 38.688612 | AK22: 46.852385 | AL22: 56.305954 | AM22: 68.711404 | AN22: 80.084353 | AO22: 97.728712 | AP22: 115.66259 | AQ22: 143.32412 | AR22: 170.92908 | AS22: 206.99722 | AT22: 276.91746
A23: 5 | B23: 6 | C23: loss | D23: 0.1 | E23: 0.12017735 | F23: 0.14442595 | G23: 0.17224313 | H23: 0.2134363 | I23: 0.24876378 | J23: 0.29895771 | K23: 0.36762937 | L23: 0.44180723 | M23: 0.53503399 | N23: 0.63808429 | O23: 0.76098259 | P23: 0.92155929 | Q23: 1.1160196 | R23: 1.3515135 | S23: 1.6242131 | T23: 1.9669421 | U23: 2.3638188 | V23: 2.7975955 | W23: 3.4402133 | X23: 4.0404539 | Y23: 4.9685607 | Z23: 5.925531 | AA23: 7.175891 | AB23: 8.5580044 | AC23: 10.363849 | AD23: 12.647234 | AE23: 15.199111 | AF23: 18.265888 | AG23: 22.120216 | AH23: 26.787854 | AI23: 31.947332 | AJ23: 38.688612 | AK23: 46.852385 | AL23: 56.305954 | AM23: 68.711404 | AN23: 80.084353 | AO23: 97.728712 | AP23: 115.66259 | AQ23: 143.32412 | AR23: 170.92908 | AS23: 206.99722 | AT23: 276.91746
A24: 6 | B24: 1 | C24: visc | D24: 0.1029831 | E24: 0.12901443 | F24: 0.16644724 | G24: 0.21899063 | H24: 0.27977475 | I24: 0.3609498 | J24: 0.45218812 | K24: 0.60670661 | L24: 0.77510708 | M24: 0.99024961 | N24: 1.2775649 | O24: 1.6004987 | P24: 2.1685539 | Q24: 2.7977475 | R24: 3.574304 | S24: 4.7026258 | T24: 6.1268048 | U24: 7.7510708 | V24: 10.29831 | W24: 13.028476 | X24: 16.644724 | Y24: 21.899063 | Z24: 27.704683 | AA24: 35.049421 | AB24: 45.664054 | AC24: 59.493304 | AD24: 77.510708 | AE24: 99.024961 | AF24: 129.01443 | AG24: 163.21721 | AH24: 212.64715 | AI24: 277.04683 | AJ24: 364.50386 | AK24: 465.67734 | AL24: 594.93304
A25: 6 | B25: 2 | C25: visc | D25: 0.1029831 | E25: 0.12901443 | F25: 0.16644724 | G25: 0.21899063 | H25: 0.27977475 | I25: 0.3609498 | J25: 0.45218812 | K25: 0.60670661 | L25: 0.77510708 | M25: 0.99024961 | N25: 1.2775649 | O25: 1.6004987 | P25: 2.1685539 | Q25: 2.7977475 | R25: 3.574304 | S25: 4.7026258 | T25: 6.1268048 | U25: 7.7510708 | V25: 10.29831 | W25: 13.028476 | X25: 16.644724 | Y25: 21.899063 | Z25: 27.704683 | AA25: 35.049421 | AB25: 45.664054 | AC25: 59.493304 | AD25: 77.510708 | AE25: 99.024961 | AF25: 129.01443 | AG25: 163.21721 | AH25: 212.64715 | AI25: 277.04683 | AJ25: 364.50386 | AK25: 465.67734 | AL25: 594.93304
A26: 6 | B26: 3 | C26: visc | D26: 0.1029831 | E26: 0.12901443 | F26: 0.16644724 | G26: 0.21899063 | H26: 0.27977475 | I26: 0.3609498 | J26: 0.45218812 | K26: 0.60670661 | L26: 0.77510708 | M26: 0.99024961 | N26: 1.2775649 | O26: 1.6004987 | P26: 2.1685539 | Q26: 2.7977475 | R26: 3.574304 | S26: 4.7026258 | T26: 6.1268048 | U26: 7.7510708 | V26: 10.29831 | W26: 13.028476 | X26: 16.644724 | Y26: 21.899063 | Z26: 27.704683 | AA26: 35.049421 | AB26: 45.664054 | AC26: 59.493304 | AD26: 77.510708 | AE26: 99.024961 | AF26: 129.01443 | AG26: 163.21721 | AH26: 212.64715 | AI26: 277.04683 | AJ26: 364.50386 | AK26: 465.67734 | AL26: 594.93304
A27: 6 | B27: 4 | C27: visc | D27: 0.1029831 | E27: 0.12901443 | F27: 0.16644724 | G27: 0.21899063 | H27: 0.27977475 | I27: 0.3609498 | J27: 0.45218812 | K27: 0.60670661 | L27: 0.77510708 | M27: 0.99024961 | N27: 1.2775649 | O27: 1.6004987 | P27: 2.1685539 | Q27: 2.7977475 | R27: 3.574304 | S27: 4.7026258 | T27: 6.1268048 | U27: 7.7510708 | V27: 10.29831 | W27: 13.028476 | X27: 16.644724 | Y27: 21.899063 | Z27: 27.704683 | AA27: 35.049421 | AB27: 45.664054 | AC27: 59.493304 | AD27: 77.510708 | AE27: 99.024961 | AF27: 129.01443 | AG27: 163.21721 | AH27: 212.64715 | AI27: 277.04683 | AJ27: 364.50386 | AK27: 465.67734 | AL27: 594.93304
A28: 7 | B28: 1 | C28: loss | D28: 0.07106809 | E28: 0.1 | F28: 0.14704969 | G28: 0.21152361 | H28: 0.31449059 | I28: 0.45739044 | J28: 0.68004223 | K28: 0.98904331 | L28: 1.4704969 | M28: 2.1386688 | N28: 3.1797454 | O28: 4.6245744 | P28: 6.8757579 | Q28: 10 | R28: 14.543851 | S28: 21.152361 | T28: 31.449059 | U28: 46.758057 | V28: 65.793322 | W28: 101.10781 | X28: 140.71013 | Y28: 213.86688
A29: 7 | B29: 2 | C29: loss | D29: 0.14543851 | E29: 0.32505865 | F29: 0.6951928 | G29: 1.5032579 | H29: 3.2149708 | I29: 6.951928 | J29: 14.543851 | K29: 32.149708 | L29: 67.259122 | M29: 148.67872 | N29: 314.49059
A30: 8 | B30: 1 | C30: tan
A31: 8 | B31: 2 | C31: tan
A32: 8 | B32: 3 | C32: tan
A33: 8 | B33: 4 | C33: tan
A34: 9 | B34: 1 | C34: tan
A35: 9 | B35: 2 | C35: tan
A36: 9 | B36: 3 | C36: tan
A37: 9 | B37: 4 | C37: tan
A38: 11 | B38: 1a | D38: =6.283185*Angular_frequency!C38 -> 6.283185 | E38: =6.283185*Angular_frequency!D38 -> 62.83185 | F38: =6.283185*Angular_frequency!E38 -> 125.6637 | G38: =6.283185*Angular_frequency!F38 -> 188.49555 | H38: =6.283185*Angular_frequency!G38 -> 251.3274 | I38: =6.283185*Angular_frequency!H38 -> 314.15925 | J38: =6.283185*Angular_frequency!I38 -> 376.9911 | K38: =6.283185*Angular_frequency!J38 -> 439.82295 | ... N38: =6.283185*Angular_frequency!M38 -> 628.3185
A39: 11 | B39: 2a | D39: =6.283185*Angular_frequency!C39 -> 6.283185 | E39: =6.283185*Angular_frequency!D39 -> 62.83185 | F39: =6.283185*Angular_frequency!E39 -> 125.6637 | G39: =6.283185*Angular_frequency!F39 -> 188.49555 | H39: =6.283185*Angular_frequency!G39 -> 251.3274 | I39: =6.283185*Angular_frequency!H39 -> 314.15925 | J39: =6.283185*Angular_frequency!I39 -> 376.9911 | K39: =6.283185*Angular_frequency!J39 -> 439.82295 | ... N39: =6.283185*Angular_frequency!M39 -> 628.3185
A40: 11 | B40: 3a | D40: =6.283185*Angular_frequency!C40 -> 6.283185 | E40: =6.283185*Angular_frequency!D40 -> 62.83185 | F40: =6.283185*Angular_frequency!E40 -> 125.6637 | G40: =6.283185*Angular_frequency!F40 -> 188.49555 | H40: =6.283185*Angular_frequency!G40 -> 251.3274 | I40: =6.283185*Angular_frequency!H40 -> 314.15925 | J40: =6.283185*Angular_frequency!I40 -> 376.9911 | K40: =6.283185*Angular_frequency!J40 -> 439.82295 | ... N40: =6.283185*Angular_frequency!M40 -> 628.3185
...

Sheet Physchem_properties
A1: Study_id | B1: Instance | C1: Monomer_A | D1: Monomer_B | E1: HB_ratio | F1: HV_ratio | G1: Mw_PHBV | H1: Mn_PHBV | I1: Density | J1: Density_units | K1: PDI | L1: Additive_1 | M1: Additive1_type | N1: Additive1_name | O1: Additive1_percentage | P1: Additive_2 | Q1: Additive2_type | R1: Additive2_name | S1: Additive2_percentage | T1: final_PHA_percentage | V1: HB_ratio_formulation | W1: HV_ratio_formulation | Y1: Row No.
A2: 1 | B2: 1 | C2: 3HB | D2: 3HV | E2: 97 | F2: 3 | I2: 1.24 | J2: g/cm3 | L2: No | P2: No | T2: 100 | V2: 97 | W2: 3 | Y2: 1
A3: 1 | B3: 2 | C3: 3HB | D3: 3HV | E3: 97 | F3: 3 | I3: 1.24 | J3: g/cm3 | L3: No | P3: No | T3: 100 | V3: 97 | W3: 3 | Y3: 2
A4: 1 | B4: 3 | C4: 3HB | D4: 3HV | E4: 97 | F4: 3 | I4: 1.24 | J4: g/cm3 | L4: No | P4: No | T4: 100 | V4: 97 | W4: 3 | Y4: 3
A5: 1 | B5: 4 | C5: 3HB | D5: 3HV | E5: 97 | F5: 3 | I5: 1.24 | J5: g/cm3 | L5: No | P5: No | T5: 100 | V5: 97 | W5: 3 | Y5: 4
A6: 1 | B6: 5 | C6: 3HB | D6: 3HV | E6: 97 | F6: 3 | I6: 1.24 | J6: g/cm3 | L6: No | P6: No | T6: 100 | V6: 97 | W6: 3 | Y6: 5
A7: 2 | B7: 1 | C7: 3HB | D7: 3HV | E7: 100 | F7: 0 | G7: 440000 | H7: 260000 | L7: No | P7: No | T7: 100 | V7: 100 | W7: 0 | Y7: 6
A8: 2 | B8: 2 | C8: 3HB | D8: 3HV | E8: 100 | F8: 0 | G8: 440000 | H8: 260000 | L8: Yes | M8: Plasticizer | N8: lignin | O8: 10 | P8: No | T8: 90 | V8: 90 | W8: 0 | Y8: 7
A9: 2 | B9: 3 | C9: 3HB | D9: 3HV | E9: 100 | F9: 0 | G9: 440000 | H9: 260000 | L9: Yes | M9: Filler | N9: lignin | O9: 60 | P9: No | T9: 40 | V9: 40 | W9: 0 | Y9: 8
A10: 2 | B10: 4 | C10: 3HB | D10: 3HV | E10: 100 | F10: 0 | G10: 440000 | H10: 260000 | L10: Yes | M10: Filler | N10: lignin | O10: 90 | P10: No | T10: 10 | V10: 10 | W10: 0 | Y10: 9
A11: 3 | B11: 1 | C11: 3HB | D11: 3HV | E11: 100 | F11: 0 | G11: 223000 | K11: 1.23 | L11: No | P11: No | T11: 100 | V11: 100 | W11: 0 | Y11: 10
A12: 3 | B12: 2 | C12: 3HB | D12: 3HV | E12: 100 | F12: 0 | G12: 223000 | K12: 1.23 | L12: Yes | M12: Filler | N12: LCB | O12: 30 | P12: No | T12: 70 | V12: 70 | W12: 0 | Y12: 11
A13: 3 | B13: 3 | C13: 3HB | D13: 3HV | E13: 100 | F13: 0 | G13: 223000 | K13: 1.23 | L13: Yes | M13: Antioxidant | N13: IL | O13: 30 | P13: No | T13: 70 | V13: 70 | W13: 0 | Y13: 12
A14: 3 | B14: 4 | C14: 3HB | D14: 3HV | E14: 100 | F14: 0 | G14: 223000 | K14: 1.23 | L14: Yes | M14: Filler | N14: HC | O14: 30 | P14: No | T14: 70 | V14: 70 | W14: 0 | Y14: 13
A15: 4 | B15: 1 | C15: 3HB | D15: 3HV | E15: 97 | F15: 3 | I15: 1.23 | J15: g/cm3 | L15: No | P15: No | T15: 100 | V15: 97 | W15: 3 | Y15: 14
A16: 4 | B16: 2 | C16: 3HB | D16: 3HV | E16: 97 | F16: 3 | I16: 1.23 | J16: g/cm3 | L16: Yes | M16: Reinforcement | N16: wood_fiber | O16: 15 | P16: No | T16: 85 | V16: 82.45 | W16: 2.55 | Y16: 15
A17: 4 | B17: 3 | C17: 3HB | D17: 3HV | E17: 97 | F17: 3 | I17: 1.23 | J17: g/cm3 | L17: Yes | M17: Filler | N17: cellulose | O17: 15 | P17: No | T17: 85 | V17: 82.45 | W17: 2.55 | Y17: 16
A18: 5 | B18: 1 | C18: 3HB | D18: 3HV | E18: 92 | F18: 8 | G18: 443000 | L18: No | P18: No | T18: 100 | V18: 92 | W18: 8 | Y18: 17
A19: 5 | B19: 2 | C19: 3HB | D19: 3HV | E19: 92 | F19: 8 | G19: 443000 | L19: Yes | M19: Reinforcement | N19: IN | O19: 30 | P19: No | T19: 70 | V19: 64.4 | W19: 5.6 | Y19: 18
A20: 5 | B20: 3 | C20: 3HB | D20: 3HV | E20: 92 | F20: 8 | G20: 443000 | L20: Yes | M20: Compatibilizer | N20: IN-AC | O20: 30 | P20: No | T20: 70 | V20: 64.4 | W20: 5.6 | Y20: 19
A21: 5 | B21: 4 | C21: 3HB | D21: 3HV | E21: 92 | F21: 8 | G21: 443000 | L21: Yes | M21: Compatibilizer | N21: IN-PR | O21: 30 | P21: No | T21: 70 | V21: 64.4 | W21: 5.6 | Y21: 20
A22: 5 | B22: 5 | C22: 3HB | D22: 3HV | E22: 92 | F22: 8 | G22: 443000 | L22: Yes | M22: Compatibilizer | N22: IN-BU | O22: 30 | P22: No | T22: 70 | V22: 64.4 | W22: 5.6 | Y22: 21
A23: 5 | B23: 6 | C23: 3HB | D23: 3HV | E23: 92 | F23: 8 | G23: 443000 | L23: Yes | M23: Plasticizer | N23: IN-HE | O23: 30 | P23: No | T23: 70 | V23: 64.4 | W23: 5.6 | Y23: 22
A24: 6 | B24: 1 | C24: 3HB | D24: 3HV | E24: 100 | F24: 0 | G24: 117869 | H24: 49078 | L24: No | P24: No | T24: 100 | V24: 100 | W24: 0 | Y24: 23
A25: 6 | B25: 2 | C25: 3HB | D25: 3HV | E25: 100 | F25: 0 | G25: 117869 | H25: 49078 | L25: Yes | M25: Reinforcement | N25: lignin | O25: 5 | P25: No | T25: 95 | V25: 95 | W25: 0 | Y25: 24
A26: 6 | B26: 3 | C26: 3HB | D26: 3HV | E26: 100 | F26: 0 | G26: 117869 | H26: 49078 | L26: Yes | M26: Reinforcement | N26: lignin | O26: 7 | P26: No | T26: 93 | V26: 93 | W26: 0 | Y26: 25
A27: 6 | B27: 4 | C27: 3HB | D27: 3HV | E27: 100 | F27: 0 | G27: 117869 | H27: 49078 | L27: Yes | M27: Reinforcement | N27: lignin | O27: 9 | P27: No | T27: 91 | V27: 91 | W27: 0 | Y27: 26
A28: 7 | B28: 1 | C28: 3HB | D28: 3HV | E28: 100 | F28: 0 | G28: 890000 | H28: 462000 | L28: No | P28: No | T28: 100 | V28: 100 | W28: 0 | Y28: 27
A29: 7 | B29: 2 | C29: 3HB | D29: 3HV | E29: 100 | F29: 0 | G29: 890000 | H29: 462000 | L29: Yes | M29: Reinforcement | N29: LRR | O29: 30 | P29: No | T29: 70 | V29: 70 | W29: 0 | Y29: 28
A30: 8 | B30: 1 | C30: 3HB | D30: 3HB | E30: 100 | F30: 0 | G30: 490000 | I30: 1.25 | J30: g/cm3 | L30: Yes | M30: Plasticizer | N30: ATBC | O30: 10 | P30: No | T30: 90 | V30: 90 | W30: 0 | Y30: 29
A31: 8 | B31: 2 | C31: 3HB | D31: 3HV | E31: 100 | F31: 0 | G31: 490000 | I31: 1.25 | J31: g/cm3 | L31: Yes | M31: Plasticizer | N31: ATBC | O31: 10 | P31: Yes | Q31: Reinforcement | R31: CLF | S31: 5 | T31: 85 | V31: 85 | W31: 0 | Y31: 30
A32: 8 | B32: 3 | C32: 3HB | D32: 3HV | E32: 100 | F32: 0 | G32: 490000 | I32: 1.25 | J32: g/cm3 | L32: Yes | M32: Plasticizer | N32: ATBC | O32: 10 | P32: Yes | Q32: Reinforcement | R32: CLF | S32: 10 | T32: 80 | V32: 80 | W32: 0 | Y32: 31
A33: 8 | B33: 4 | C33: 3HB | D33: 3HV | E33: 100 | F33: 0 | G33: 490000 | I33: 1.25 | J33: g/cm3 | L33: Yes | M33: Plasticizer | N33: ATBC | O33: 20 | P33: Yes | Q33: Reinforcement | R33: CLF | S33: 5 | T33: 75 | V33: 75 | W33: 0 | Y33: 32
A34: 9 | B34: 1 | C34: 3HB | D34: 3HV | E34: 22.9 | F34: 77.1 | G34: 286000 | K34: 2.5 | L34: No | P34: No | T34: 100 | V34: 22.9 | W34: 77.1 | Y34: 33
A35: 9 | B35: 2 | C35: 3HB | D35: 3HV | E35: 22.9 | F35: 77.1 | G35: 286000 | K35: 2.5 | L35: Yes | M35: Reinforcement | N35: lignin | O35: 1 | P35: No | T35: 99 | V35: 22.671 | W35: 76.329 | Y35: 34
A36: 9 | B36: 3 | C36: 3HB | D36: 3HV | E36: 22.9 | F36: 77.1 | G36: 286000 | K36: 2.5 | L36: Yes | M36: Reinforcement | N36: lignin | O36: 5 | P36: No | T36: 95 | V36: 21.755 | W36: 73.245 | Y36: 35
A37: 9 | B37: 4 | C37: 3HB | D37: 3HV | E37: 22.9 | F37: 77.1 | G37: 286000 | K37: 2.5 | L37: Yes | M37: Reinforcement | N37: lignin | O37: 10 | P37: No | T37: 90 | V37: 20.61 | W37: 69.39 | Y37: 36
A38: 11 | B38: 1a | C38: 3HB | D38: 3HV | E38: 100 | F38: 0 | G38: 450000 | L38: No | P38: No | T38: 100 | V38: 100 | W38: 0 | Y38: 37
A39: 11 | B39: 2a | C39: 3HB | D39: 3HV | E39: 100 | F39: 0 | G39: 450000 | L39: Yes | M39: Filler | N39: biorefinery_lignin | O39: 10 | P39: No | T39: 90 | V39: 90 | W39: 0 | Y39: 38
A40: 11 | B40: 3a | C40: 3HB | D40: 3HV | E40: 100 | F40: 0 | G40: 450000 | L40: Yes | M40: Filler | N40: biorefinery_lignin | O40: 20 | P40: No | T40: 80 | V40: 80 | W40: 0 | Y40: 39
...

Sheet Thermal_properties
A1: Study_id | B1: Instance | C1: Tg1 | D1: Tg2 | E1: Tc1 | F1: Tc2 | G1: Tmc | H1: Tm1 | I1: Tm2 | J1: Td5 | K1: Tdeg | L1: Temperature_units | M1: DΗm1 | N1: DΗm2 | O1: DHc1 | P1: DHc2 | Q1: Enthaply_units | R1: Crystallinity_%
A2: 1 | B2: 1 | E2: 125 | H2: 168 | L2: celsius
A3: 1 | B3: 2 | E3: 125 | H3: 168 | L3: celsius
A4: 1 | B4: 3 | E4: 125 | H4: 168 | L4: celsius
A5: 1 | B5: 4 | E5: 125 | H5: 168 | L5: celsius
A6: 1 | B6: 5 | E6: 125 | H6: 168 | L6: celsius
A7: 2 | B7: 1 | C7: 3 | G7: 89 | H7: 172 | L7: celsius | M7: 92 | Q7: J/g | R7: 63
A8: 2 | B8: 2 | C8: 7 | G8: 132 | H8: 174 | L8: celsius | M8: 90 | Q8: J/g | R8: 61
A9: 2 | B9: 3 | C9: 17 | G9: 86 | H9: 165 | L9: celsius | M9: 31 | Q9: J/g | R9: 21
A10: 2 | B10: 4 | C10: 43 | H10: 158 | L10: celsius | M10: 3 | Q10: J/g
A11: 3 | B11: 1 | C11: 3.8 | E11: 46.6 | G11: 63.2 | L11: celsius | M11: 83.3 | O11: 72.8 | P11: 15.3 | Q11: J/g
A12: 3 | B12: 2 | C12: 4.6 | E12: 46.7 | G12: 62.9 | L12: celsius | M12: 83.1 | O12: 30 | P12: 45 | Q12: J/g
A13: 3 | B13: 3 | C13: 3.8 | E13: 41.6 | G13: 47.3 | L13: celsius | M13: 83.7 | O13: 50 | P13: 27.9 | Q13: J/g
A14: 3 | B14: 4 | C14: 4.7 | E14: 41.2 | G14: 62.2 | L14: celsius | M14: 82.3 | O14: 15.7 | P14: 49.7 | Q14: J/g
A15: 4 | B15: 1
A16: 4 | B16: 2
A17: 4 | B17: 3
A18: 5 | B18: 1 | E18: 91 | I18: 170 | L18: celsius | O18: 74 | Q18: J/g | R18: 64.3
A19: 5 | B19: 2 | E19: 71 | H19: 163 | I19: 172 | L19: celsius | O19: 47 | Q19: J/g | R19: 62.3
A20: 5 | B20: 3 | E20: 60 | H20: 160 | I20: 170 | L20: celsius | O20: 34 | Q20: J/g | R20: 64.2
A21: 5 | B21: 4 | E21: 66 | H21: 158 | I21: 170 | L21: celsius | O21: 33 | Q21: J/g | R21: 64.8
A22: 5 | B22: 5 | E22: 71 | H22: 158 | I22: 170 | L22: celsius | O22: 34 | Q22: J/g | R22: 64.8
A23: 5 | B23: 6 | E23: 77 | H23: 167 | I23: 174 | L23: celsius | O23: 49 | Q23: J/g | R23: 64.5
A24: 6 | B24: 1 | C24: -1.3 | G24: 53 | H24: 167.8 | J24: 265.5 | L24: celsius | M24: 74.1 | Q24: J/g | R24: 50.8
A25: 6 | B25: 2 | C25: 0.2 | G25: 72.9 | H25: 167.7 | J25: 265.1 | L25: celsius | M25: 71.3 | Q25: J/g | R25: 48.8
A26: 6 | B26: 3 | C26: 1.3 | G26: 69.4 | H26: 168.6 | J26: 267.5 | L26: celsius | M26: 65.1 | Q26: J/g | R26: 44.6
A27: 6 | B27: 4 | C27: 2 | G27: 68.4 | H27: 169.2 | J27: 266.5 | L27: celsius | M27: 62.3 | Q27: J/g | R27: 42.7
A28: 7 | B28: 1 | C28: 3.9 | E28: 47.4 | H28: 175 | L28: celsius | M28: 87.4 | O28: 68.7 | Q28: J/g
A29: 7 | B29: 2 | C29: 3.8 | E29: 42.9 | H29: 171.4 | L29: celsius | M29: 87.8 | O29: 25.1 | Q29: J/g
A30: 8 | B30: 1 | C30: -13.4 | E30: 85.7 | H30: 161.3 | I30: 170.3 | J30: 215.7 | K30: 279.1 | L30: celsius | M30: 86 | N30: 88.7 | O30: 73.9 | Q30: J/g | R30: 58.9
A31: 8 | B31: 2 | C31: -10.1 | E31: 87.5 | H31: 161.8 | I31: 170.4 | J31: 226.5 | K31: 287.2 | L31: celsius | M31: 83.7 | N31: 85.4 | O31: 68.5 | Q31: J/g | R31: 60.4
A32: 8 | B32: 3 | C32: -6.3 | E32: 83.8 | H32: 161.2 | I32: 170 | J32: 229.3 | K32: 288.9 | L32: celsius | M32: 84.5 | N32: 79.9 | O32: 61.9 | Q32: J/g | R32: 64.3
A33: 8 | B33: 4 | C33: -21 | E33: 77 | H33: 155.5 | I33: 166.7 | J33: 203 | K33: 287.4 | L33: celsius | M33: 79 | N33: 73.7 | O33: 57.5 | Q33: J/g | R33: 63.6
A34: 9 | B34: 1 | C34: −3.7 | E34: 104.2 | H34: 150.8 | I34: 162.3 | L34: celsius | M34: 20.1 | N34: 17.3 | O34: 28.6 | Q34: J/g
A35: 9 | B35: 2 | C35: −2.6 | E35: 100.8 | H35: 149.4 | I35: 161.7 | L35: celsius | M35: 18.3 | N35: 19 | O35: 32.5 | Q35: J/g
A36: 9 | B36: 3 | C36: −2.2 | E36: 96 | H36: 148.2 | I36: 161.4 | L36: celsius | M36: 15.6 | N36: 20.3 | O36: 30.7 | Q36: J/g
A37: 9 | B37: 4 | C37: −1.5 | E37: 107.2 | H37: 151.1 | I37: 161.9 | L37: celsius | M37: 20.5 | N37: 13.5 | O37: 26.9 | Q37: J/g
A38: 11 | B38: 1a | L38: celsius
A39: 11 | B39: 2a | L39: celsius
A40: 11 | B40: 3a | L40: celsius
...

Sheet Rheological_experimental_detail
A1: Study_id | B1: Instance | C1: Test type | D1: constant parameters | E1: geometry | F1: plate diameter | G1: gap size | H1: morphology | I1: diameter | J1: thickness | K1: size units | L1: Angular_frequency_units | M1: Texp | N1: Texp_units | O1: Viscosity_units | P1: Modulus_units | Q1: Strain_fixed(%) | R1: Frequency_experimental_fixed (Hz) | V1: Row No.
A2: 1 | B2: 1 | C2: DFS | D2: strain,temp | E2: parallel plate | G2: 1.8 | K2: mm | L2: rad/s | M2: 180 | N2: celsius | O2: Pa*s | Q2: 1 | V2: 1
A3: 1 | B3: 2 | C3: DFS | D3: strain,temp | E3: parallel plate | G3: 1.8 | K3: mm | L3: rad/s | M3: 170 | N3: celsius | O3: Pa*s | Q3: 1 | V3: 2
A4: 1 | B4: 3 | C4: DFS | D4: strain,temp | E4: parallel plate | G4: 1.8 | K4: mm | L4: rad/s | M4: 160 | N4: celsius | O4: Pa*s | Q4: 1 | V4: 3
A5: 1 | B5: 4 | C5: DFS | D5: strain,temp | E5: parallel plate | G5: 1.8 | K5: mm | L5: rad/s | M5: 150 | N5: celsius | O5: Pa*s | Q5: 1 | V5: 4
A6: 1 | B6: 5 | C6: DFS | D6: strain,temp | E6: parallel plate | G6: 1.8 | K6: mm | L6: rad/s | M6: 145 | N6: celsius | O6: Pa*s | Q6: 1 | V6: 5
A7: 2 | B7: 1 | C7: DFS | D7: strain,temp | E7: parallel plate | F7: 25 | G7: 0.75 | H7: disc | I7: 25 | J7: 0.5 | K7: mm | L7: rad/s | M7: 175 | N7: celsius | O7: Pa*s | P7: Pa | V7: 6
A8: 2 | B8: 2 | C8: DFS | D8: strain,temp | E8: parallel plate | F8: 25 | G8: 0.75 | H8: disc | I8: 25 | J8: 0.5 | K8: mm | L8: rad/s | M8: 175 | N8: celsius | O8: Pa*s | P8: Pa | V8: 7
A9: 2 | B9: 3 | C9: DFS | D9: strain,temp | E9: parallel plate | F9: 25 | G9: 0.75 | H9: disc | I9: 25 | J9: 0.5 | K9: mm | L9: rad/s | M9: 175 | N9: celsius | O9: Pa*s | P9: Pa | V9: 8
A10: 2 | B10: 4 | C10: DFS | D10: strain,temp | E10: parallel plate | F10: 25 | G10: 0.75 | H10: disc | I10: 25 | J10: 0.5 | K10: mm | L10: rad/s | M10: 175 | N10: celsius | O10: Pa*s | P10: Pa | V10: 9
A11: 3 | B11: 1 | C11: DFS | D11: strain,temp | E11: parallel plate | F11: 25 | G11: 0.8 | K11: mm | L11: rad/s | M11: 190 | N11: celsius | O11: Pa*s | P11: Pa | V11: 10
A12: 3 | B12: 2 | C12: DFS | D12: strain,temp | E12: parallel plate | F12: 25 | G12: 0.8 | K12: mm | L12: rad/s | M12: 190 | N12: celsius | O12: Pa*s | P12: Pa | V12: 11
A13: 3 | B13: 3 | C13: DFS | D13: strain,temp | E13: parallel plate | F13: 25 | G13: 0.8 | K13: mm | L13: rad/s | M13: 190 | N13: celsius | O13: Pa*s | P13: Pa | V13: 12
A14: 3 | B14: 4 | C14: DFS | D14: strain,temp | E14: parallel plate | F14: 25 | G14: 0.8 | K14: mm | L14: rad/s | M14: 190 | N14: celsius | O14: Pa*s | P14: Pa | V14: 13
A15: 4 | B15: 1 | C15: DFS | D15: strain,temp | E15: parallel plate | F15: 25 | G15: 1.5 | K15: mm | L15: hz | M15: 180 | N15: celsius | O15: Pa*s | P15: Pa | Q15: 0.1 | V15: 14
A16: 4 | B16: 2 | C16: DFS | D16: strain,temp | E16: parallel plate | F16: 25 | G16: 1.5 | K16: mm | L16: hz | M16: 180 | N16: celsius | O16: Pa*s | P16: Pa | Q16: 0.1 | V16: 15
A17: 4 | B17: 3 | C17: DFS | D17: strain,temp | E17: parallel plate | F17: 25 | G17: 1.5 | K17: mm | L17: hz | M17: 180 | N17: celsius | O17: Pa*s | P17: Pa | Q17: 0.1 | V17: 16
A18: 5 | B18: 1 | C18: DFS | D18: strain,temp | E18: parallel plate | H18: disc | I18: 25 | J18: 2 | K18: mm | L18: rad/s | M18: 175 | N18: celsius | P18: Pa | Q18: 1 | V18: 17
A19: 5 | B19: 2 | C19: DFS | D19: strain,temp | E19: parallel plate | H19: disc | I19: 25 | J19: 2 | K19: mm | L19: rad/s | M19: 175 | N19: celsius | P19: Pa | Q19: 1 | V19: 18
A20: 5 | B20: 3 | C20: DFS | D20: strain,temp | E20: parallel plate | H20: disc | I20: 25 | J20: 2 | K20: mm | L20: rad/s | M20: 175 | N20: celsius | P20: Pa | Q20: 1 | V20: 19
A21: 5 | B21: 4 | C21: DFS | D21: strain,temp | E21: parallel plate | H21: disc | I21: 25 | J21: 2 | K21: mm | L21: rad/s | M21: 175 | N21: celsius | P21: Pa | Q21: 1 | V21: 20
A22: 5 | B22: 5 | C22: DFS | D22: strain,temp | E22: parallel plate | H22: disc | I22: 25 | J22: 2 | K22: mm | L22: rad/s | M22: 175 | N22: celsius | P22: Pa | Q22: 1 | V22: 21
A23: 5 | B23: 6 | C23: DFS | D23: strain,temp | E23: parallel plate | H23: disc | I23: 25 | J23: 2 | K23: mm | L23: rad/s | M23: 175 | N23: celsius | P23: Pa | Q23: 1 | V23: 22
A24: 6 | B24: 1 | C24: DFS | D24: strain,temp | E24: parallel plate | F24: 25 | K24: mm | L24: rad/s | M24: 175 | N24: celsius | O24: Pa*s | P24: Pa | Q24: 1 | V24: 23
A25: 6 | B25: 2 | C25: DFS | D25: strain,temp | E25: parallel plate | F25: 25 | K25: mm | L25: rad/s | M25: 175 | N25: celsius | O25: Pa*s | P25: Pa | Q25: 1 | V25: 24
A26: 6 | B26: 3 | C26: DFS | D26: strain,temp | E26: parallel plate | F26: 25 | K26: mm | L26: rad/s | M26: 175 | N26: celsius | O26: Pa*s | P26: Pa | Q26: 1 | V26: 25
A27: 6 | B27: 4 | C27: DFS | D27: strain,temp | E27: parallel plate | F27: 25 | K27: mm | L27: rad/s | M27: 175 | N27: celsius | O27: Pa*s | P27: Pa | Q27: 1 | V27: 26
A28: 7 | B28: 1 | C28: DFS | D28: strain,temp | E28: parallel plate | F28: 20 | K28: mm | L28: rad/s | M28: 190 | N28: celsius | P28: Pa | Q28: 0.3 | V28: 27
A29: 7 | B29: 2 | C29: DFS | D29: strain,temp | E29: parallel plate | F29: 20 | K29: mm | L29: rad/s | M29: 190 | N29: celsius | P29: Pa | Q29: 0.3 | V29: 28
A30: 8 | B30: 1 | C30: DTS | D30: angular frequency,stress or strain | L30: hz | N30: celsius | O30: Pa*s | P30: MPa | R30: 1 | V30: 29
A31: 8 | B31: 2 | C31: DTS | D31: angular frequency,stress or strain | L31: hz | N31: celsius | O31: Pa*s | P31: MPa | R31: 1 | V31: 30
A32: 8 | B32: 3 | C32: DTS | D32: angular frequency,stress or strain | L32: hz | N32: celsius | O32: Pa*s | P32: MPa | R32: 1 | V32: 31
A33: 8 | B33: 4 | C33: DTS | D33: angular frequency,stress or strain | L33: hz | N33: celsius | O33: Pa*s | P33: MPa | R33: 1 | V33: 32
A34: 9 | B34: 1 | C34: DTS | D34: angular frequency,strain | L34: hz | N34: celsius | P34: MPa | R34: 1 | V34: 33
A35: 9 | B35: 2 | C35: DTS | D35: angular frequency,strain | L35: hz | N35: celsius | P35: MPa | R35: 1 | V35: 34
A36: 9 | B36: 3 | C36: DTS | D36: angular frequency,strain | L36: hz | N36: celsius | P36: MPa | R36: 1 | V36: 35
A37: 9 | B37: 4 | C37: DTS | D37: angular frequency,strain | L37: hz | N37: celsius | P37: MPa | R37: 1 | V37: 36
A38: 11 | B38: 1a | C38: DFS | D38: strain,temp | F38: 25 | G38: 0.5 | K38: mm | L38: hz | M38: 190 | N38: celsius | O38: Pa*s | V38: 37
A39: 11 | B39: 2a | C39: DFS | D39: strain,temp | F39: 25 | G39: 0.5 | K39: mm | L39: hz | M39: 190 | N39: celsius | O39: Pa*s | V39: 38
A40: 11 | B40: 3a | C40: DFS | D40: strain,temp | F40: 25 | G40: 0.5 | K40: mm | L40: hz | M40: 190 | N40: celsius | O40: Pa*s | V40: 39
...

Sheet Φύλλο2
A1: Study_id | B1: Instance | C1: Test type | D1: storage | E1: loss | F1: loss 2 | G1: visco | I1: storage | J1: (Πολλά στοιχεία) | L1: loss | M1: (Πολλά στοιχεία) | P1: loss 2 | Q1: (Πολλά στοιχεία) | S1: visco | T1: (Πολλά στοιχεία)
A2: 1 | B2: 1 | C2: DFS | G2: 1334.6154
A3: 1 | B3: 2 | C3: DFS | G3: 1635.5929 | I3: Ετικέτες γραμμής | J3: Καταμέτρηση από Study_id | L3: Ετικέτες γραμμής | M3: Καταμέτρηση από Study_id | P3: Ετικέτες γραμμής | Q3: Καταμέτρηση από loss 2 | S3: Ετικέτες γραμμής | T3: Καταμέτρηση από visco
A4: 1 | B4: 3 | C4: DFS | G4: 1965.3834 | I4: DFS | J4: 120 | L4: DFS | M4: 57 | P4: DFS | Q4: 101 | S4: DFS | T4: 159
A5: 1 | B5: 4 | C5: DFS | G5: 2346.2288 | I5: DTS | J5: 116 | L5: DTS | M5: 38 | P5: DTS | Q5: 92 | S5: DTS | T5: 11
A6: 1 | B6: 5 | C6: DFS | G6: 2990.7732 | I6: Γενικό Άθροισμα | J6: 236 | L6: Γενικό Άθροισμα | M6: 95 | P6: Γενικό Άθροισμα | Q6: 193 | S6: Γενικό Άθροισμα | T6: 170
A7: 2 | B7: 1 | C7: DFS | D7: 7.8116806e-05 | E7: 0.0002628283 | F7: 0.0002628283 | G7: 322.45905
A8: 2 | B8: 2 | C8: DFS | D8: 2.2640686e-06 | E8: 3.5015658e-05 | F8: 3.5015658e-05 | G8: 34.41305
A9: 2 | B9: 3 | C9: DFS | D9: 0.00069042533 | E9: 0.0011455562 | F9: 0.0011455562 | J9: =GETPIVOTDATA("Study_id",$I$3)+GETPIVOTDATA("Study_id",$L$3) -> 331
A10: 2 | B10: 4 | C10: DFS | D10: 0.00092320827 | E10: 0.003719562 | F10: 0.003719562
A11: 3 | B11: 1 | C11: DFS | D11: 2.3747494e-05 | E11: 1.8107198e-05 | F11: 1.8107198e-05 | G11: 656.66395
A12: 3 | B12: 2 | C12: DFS | D12: 0.0021517122 | E12: 6.5543394e-05 | F12: 6.5543394e-05 | G12: 35017.121 | J12: {=_xlfn.UNIQUE(A:A)} -> Study_id | L12: study | M12: instance | N12: dfs | O12: dts
A13: 3 | B13: 3 | C13: DFS | D13: 0.13240703 | E13: 0.00015141374 | F13: 0.00015141374 | G13: 1465722.2 | J13: 1 | L13: =COUNT(J13:J72) -> 60 | M13: 348 | N13: 213 | O13: 135
A14: 3 | B14: 4 | C14: DFS | D14: 0.00016815128 | E14: 4.2796175e-05 | F14: 4.2796175e-05 | G14: 7782.9441 | J14: 2
A15: 4 | B15: 1 | C15: DFS | D15: 6.6089431e-07 | E15: 6.0388241e-06 | F15: 6.0388241e-06 | G15: 193.7551 | J15: 3 | M15: dfs
A16: 4 | B16: 2 | C16: DFS | D16: 1.936996e-05 | E16: 2.3519526e-05 | F16: 2.3519526e-05 | G16: 1037.9059 | J16: 4 | L16: storage | M16: loss | N16: viscosity | P16: storage only | Q16: =COUNTIFS(L18:L500,"<>",M18:M500,"",N18:N500,"") -> 3
A17: 4 | B17: 3 | C17: DFS | D17: 7.5203426e-05 | E17: 6.0388241e-05 | F17: 6.0388241e-05 | G17: 3168.8207 | J17: 5 | L17: =COUNT(L18:L500) -> 26 | M17: =COUNT(M18:M500) -> 13 | N17: =COUNT(N18:N500) -> 30 | P17: loss only | Q17: =COUNTIFS(L18:L500,"",M18:M500,"<>",N18:N500,"") -> 0
A18: 5 | B18: 1 | C18: DFS | D18: 8.3623838e-06 | E18: 3.408738e-05 | F18: 3.408738e-05 | J18: 6 | N18: 1 | P18: visco only | Q18: =COUNTIFS(L18:L500,"",M18:M500,"",N18:N500,"<>") -> 12
A19: 5 | B19: 2 | C19: DFS | D19: 0.00036219788 | E19: 0.00035646024 | F19: 0.00035646024 | J19: 7 | L19: 2 | M19: 2 | N19: 2 | P19: Storage ∩ Loss (only) | Q19: =COUNTIFS(L18:L500,"<>",M18:M500,"<>",N18:N500,"") -> 5
A20: 5 | B20: 3 | C20: DFS | D20: 0.00016829643 | E20: 0.00018819955 | F20: 0.00018819955 | J20: 8 | L20: 3 | M20: 3 | N20: 3 | P20: Storage ∩ Viscosity (only) | Q20: =COUNTIFS(L18:L500,"<>",M18:M500,"",N18:N500,"<>") -> 10
A21: 5 | B21: 4 | C21: DFS | D21: 7.3773048e-05 | E21: 3.8986037e-05 | F21: 3.8986037e-05 | J21: 9 | L21: 4 | M21: 4 | N21: 4 | P21: Loss ∩ Viscosity (only) | Q21: =COUNTIFS(L18:L500,"",M18:M500,"<>",N18:N500,"<>") -> 0
A22: 5 | B22: 5 | C22: DFS | D22: 5.4781808e-06 | E22: 6.0429639e-06 | F22: 6.0429639e-06 | J22: 11 | L22: 5 | M22: 5 | P22: Storage ∩ Loss ∩ Viscosity | Q22: =COUNTIFS(L18:L500,"<>",M18:M500,"<>",N18:N500,"<>") -> 8
A23: 5 | B23: 6 | C23: DFS | D23: 3.1934591e-06 | E23: 7.9797381e-06 | F23: 7.9797381e-06 | J23: 12 | L23: 6 | N23: 6
A24: 6 | B24: 1 | C24: DFS | D24: 1.5091406e-05 | F24: 7.7097756e-05 | G24: 762.85233 | J24: 13 | L24: 7 | M24: 7
A25: 6 | B25: 2 | C25: DFS | D25: 0.0011418448 | F25: 0.0007629862 | G25: 13335.214 | J25: 14 | N25: 11
A26: 6 | B26: 3 | C26: DFS | D26: 0.0079351816 | F26: 0.0046500131 | G26: 89308.513 | J26: 15 | L26: 12 | N26: 12
A27: 6 | B27: 4 | C27: DFS | D27: 0.021568786 | F27: 0.013990956 | G27: 249644.17 | J27: 16 | N27: 13
A28: 7 | B28: 1 | C28: DFS | D28: 1.8968234e-06 | E28: 3.9483219e-05 | F28: 3.9483219e-05 | J28: 17 | L28: 14 | M28: 14
A29: 7 | B29: 2 | C29: DFS | D29: 0.0083039077 | E29: 0.0071862487 | F29: 0.0071862487 | J29: 18 | N29: 15
A30: 8 | B30: 1 | C30: DTS | D30: 6874.0686 | F30: 436.89378 | J30: 19
A31: 8 | B31: 2 | C31: DTS | D31: 7522.3547 | F31: 459.88623 | J31: 20
A32: 8 | B32: 3 | C32: DTS | D32: 7622.9508 | F32: 404.28611 | J32: 21
A33: 8 | B33: 4 | C33: DTS | D33: 4046.1997 | F33: 232.29858 | J33: 22
A34: 9 | B34: 1 | C34: DTS | D34: 2779.4524 | F34: 283.09238 | J34: 23
A35: 9 | B35: 2 | C35: DTS | D35: 3444.4343 | F35: 69.919072 | J35: 24
A36: 9 | B36: 3 | C36: DTS | D36: 3242.7766 | F36: 207.87029 | J36: 25
A37: 9 | B37: 4 | C37: DTS | D37: 3398.5643 | F37: 187.59881 | J37: 26
A38: 11 | B38: 1a | C38: DFS | G38: 655.64185 | J38: 27 | L38: 17
A39: 11 | B39: 2a | C39: DFS | G39: 318.25686 | J39: 28 | L39: 18 | M39: 18
A40: 11 | B40: 3a | C40: DFS | G40: 240.19035 | J40: 29 | N40: 20
...

Sheet Storage_modulus_G
A1: Study_id | B1: Instance
A2: 1 | B2: 1
A3: 1 | B3: 2
A4: 1 | B4: 3
A5: 1 | B5: 4
A6: 1 | B6: 5
A7: 2 | B7: 1 | C7: 78.116806 | D7: 110.30285 | E7: 161.51092 | F7: 240.82605 | G7: 365.67181 | H7: 545.24672 | I7: 756.04718 | J7: 1010.9551 | K7: 1453.6524 | L7: 2015.6559 | M7: 2552.349
A8: 2 | B8: 2 | C8: 2.2640686 | D8: 2.4346432 | E8: 2.7646514 | F8: 2.9729398 | G8: 3.4377762 | H8: 3.9037559 | I8: 4.5968525 | J8: 6.2593606 | K8: 8.2191423 | L8: 11.605631 | M8: 28.773357
A9: 2 | B9: 3 | C9: 690.42533 | D9: 843.07752 | E9: 1067.5572 | F9: 1453.6524 | G9: 2015.6559 | H9: 2599.121 | I9: 3670.0229 | J9: 4819.0929 | K9: 7317.3413 | L9: 11947.776 | M9: 12616.717
A10: 2 | B10: 4 | C10: 923.20827 | D10: 1190.4462 | E10: 1650.6904 | F10: 2373.5278 | G10: 3539.125 | H10: 5472.3057 | I10: 8309.1837 | J10: 13815.88 | K10: 22152.659 | L10: 35520.019 | M10: 63509.562
A11: 3 | B11: 1 | C11: 23.747494 | D11: 14.724465 | E11: 21.193096 | F11: 40.083479 | G11: 164.36732 | H11: 332.84384 | I11: 906.07968 | J11: 1675.1462 | K11: 3241.2192 | L11: 6130.2672 | M11: 10114.452 | N11: 17465.243 | O11: 26914.327 | P11: 39629.908 | Q11: 57039.791 | R11: 78444.668 | S11: 96277.662 | T11: 115505.58 | U11: 138573.57 | V11: 166248.53 | W11: 194962.27 | X11: 218461.03 | Y11: 233898.81
A12: 3 | B12: 2 | C12: 2151.7122 | D12: 2009.695 | E12: 1529.3751 | F12: 1564.5833 | G12: 2959.1684 | H12: 4163.3207 | I12: 6869.1468 | J12: 10829.2 | K12: 16312.503 | L12: 24019.288 | M12: 34571.243 | N12: 47544.523 | O12: 71618.416 | P12: 98494.1 | Q12: 138573.57 | R12: 177996.66 | S12: 223490.28 | T12: 307357.74 | U12: 377230.03 | V12: 462986.54 | W12: 581319.85 | X12: 651386.2 | Y12: 781476.6
A13: 3 | B13: 3 | C13: 132407.03 | D13: 138573.57 | E13: 145027.3 | F13: 148366.01 | G13: 158850.46 | H13: 170075.79 | I13: 182094.38 | J13: 199450.56 | K13: 218461.03 | L13: 244792.08 | M13: 287071.52 | N13: 344403.49 | O13: 413185.41 | P13: 473645.1 | Q13: 581319.85 | R13: 713472.54 | S13: 855962.41 | T13: 1050550.2 | U13: 1231996.7 | V13: 1380489 | W13: 1618921.2 | X13: 1656190.8 | Y13: 1855811.1
A14: 3 | B14: 4 | C14: 168.15128 | D14: 1364.8679 | E14: 5227.4111 | F14: 8823.3654 | G14: 17072.218 | H14: 29479.644 | I14: 43407.201 | J14: 63914.783 | K14: 87899.584 | L14: 110365.57 | M14: 170075.79 | N14: 228635.32 | O14: 280611.48 | P14: 336653.29 | Q14: 403887.39 | R14: 484549.03 | S14: 608393.43 | T14: 697417.09 | U14: 763890.84 | V14: 855962.41 | W14: 1003800.6 | X14: 959131.36 | Y14: 1150682.5
A15: 4 | B15: 1 | C15: 0.66089431 | D15: 0.7961412 | E15: 1.5479929 | F15: 2.0741095 | G15: 3.8239152 | H15: 6.684709 | I15: 14.846263 | J15: 20.978874 | K15: 45.369676 | L15: 93.035108 | M15: 195.9202 | N15: 423.70414 | O15: 966.38129 | P15: 2035.0771 | Q15: 3557.5836 | R15: 6917.2583 | S15: 11164.899 | T15: 17547.871 | U15: 27579.987 | V15: 41101.852 | W15: 59645.483
A16: 4 | B16: 2 | C16: 19.36996 | D16: 26.652784 | E16: 50.462678 | F16: 67.613435 | G16: 100.76282 | H16: 146.22327 | I16: 206.62436 | J16: 291.97558 | K16: 423.70414 | L16: 702.31938 | M16: 1074.8631 | N16: 1689.3622 | O16: 2655.1705 | P16: 4519.7614 | Q16: 7295.1849 | R16: 12418.222 | S16: 20043.806 | T16: 35039.222 | U16: 52218.186 | V16: 75777.095 | W16: 109964.91
A17: 4 | B17: 3 | C17: 75.203426 | D17: 83.645435 | E17: 162.63766 | F17: 185.77056 | G17: 206.62436 | H17: 299.84561 | I17: 401.75417 | J17: 583.01076 | K17: 846.04359 | L17: 1195.5225 | M17: 1829.6846 | N17: 2655.1705 | O17: 4285.6155 | P17: 6917.2583 | Q17: 11164.899 | R17: 18020.863 | S17: 26856.097 | T17: 46948.007 | U17: 68129.207 | V17: 98866.579 | W17: 139705.83
A18: 5 | B18: 1 | C18: 8.3623838 | D18: 9.6548029 | E18: 10.970386 | F18: 11.146967 | G18: 12.465233 | H18: 14.623406 | I18: 17.711947 | J18: 19.806603 | K18: 22.505491 | L18: 25.983748 | M18: 29.524347 | N18: 31.978226 | O18: 36.335645 | P18: 38.118632 | Q18: 41.951374 | R18: 46.169488 | S18: 51.629599 | T18: 58.664754 | U18: 63.540601 | V18: 71.055059 | W18: 82.036726 | X18: 88.855105 | Y18: 104.23907 | Z18: 116.56662 | AA18: 138.94955 | AB18: 163.00663 | AC18: 191.22884 | AD18: 227.94829 | AE18: 276.09217 | AF18: 339.78692 | AG18: 424.90715 | AH18: 514.64978 | AI18: 653.93409 | AJ18: 792.04842 | AK18: 1022.6069 | AL18: 1299.3643 | AM18: 1651.023 | AN18: 2064.6218 | AO18: 2752.1185 | AP18: 3910.5065 | AQ18: 5468.4479 | AR18: 8828.9379 | AS18: 16991.659
A19: 5 | B19: 2 | C19: 362.19788 | D19: 418.17611 | E19: 460.22277 | F19: 490.57719 | G19: 514.64978 | H19: 514.64978 | I19: 575.51345 | J19: 603.75386 | K19: 633.38001 | L19: 633.38001 | M19: 643.575 | N19: 719.68567 | O19: 708.285 | P19: 708.285 | Q19: 731.26985 | R19: 767.15321 | S19: 792.04842 | T19: 792.04842 | U19: 830.91418 | V19: 885.7179 | W19: 899.97457 | X19: 857.87853 | Y19: 857.87853 | Z19: 871.68708 | AA19: 914.46071 | AB19: 929.18002 | AC19: 1039.067 | AD19: 1039.067 | AE19: 990.46495 | AF19: 1107.5996 | AG19: 1143.5428 | AH19: 1180.6524 | AI19: 1299.3643 | AJ19: 1299.3643 | AK19: 1320.2791 | AL19: 1453.0301 | AM19: 1524.3302 | AN19: 1817.0296 | AO19: 2200.7958 | AP19: 2933.637 | AQ19: 4372.972 | AR19: 7770.1599 | AS19: 16991.659
A20: 5 | B20: 3 | C20: 168.29643 | D20: 217.28608 | E20: 246.89392 | F20: 280.5362 | G20: 323.89349 | H20: 362.19788 | I20: 418.17611 | J20: 445.75731 | K20: 490.57719 | L20: 539.90361 | M20: 584.77701 | N20: 633.38001 | O20: 767.15321 | P20: 817.75152 | Q20: 899.97457 | R20: 1006.4076 | S20: 1072.7862 | T20: 1180.6524 | U20: 1407.3593 | V20: 1599.129 | W20: 1677.5981 | X20: 1817.0296 | Y20: 2131.6217 | Z20: 2272.2148 | AA20: 2422.0808 | AB20: 2933.637 | AC20: 3077.5904 | AD20: 3333.3804 | AE20: 4037.408 | AF20: 4372.972 | AG20: 4661.3955 | AH20: 5381.8212 | AI20: 6115.1592 | AJ20: 6623.4129 | AK20: 7406.7131 | AL20: 7895.2297 | AM20: 8828.9379 | AN20: 9411.2587 | AO20: 10357.539 | AP20: 12150.796 | AQ20: 12952.213 | AR20: 17265.16 | AS20: 24532.199
A21: 5 | B21: 4 | C21: 73.773048 | D21: 89.768713 | E21: 109.2326 | F21: 118.53965 | G21: 128.63969 | H21: 139.6003 | I21: 151.4948 | J21: 159.11259 | K21: 172.66961 | L21: 184.3423 | M21: 190.4713 | N21: 206.70021 | O21: 224.31188 | P21: 235.59121 | Q21: 251.51749 | R21: 272.94777 | S21: 282.02272 | T21: 301.08782 | U21: 316.22777 | V21: 348.82985 | W21: 378.55152 | X21: 384.7931 | Y21: 417.57899 | Z21: 468.22494 | AA21: 491.76924 | AB21: 551.41335 | AC21: 588.6896 | AD21: 660.08866 | AE21: 704.71151 | AF21: 728.14171 | AG21: 829.91591 | AH21: 915.47761 | AI21: 977.36508 | AJ21: 1113.9739 | AK21: 1208.8888 | AL21: 1377.8583 | AM21: 1570.445 | AN21: 1789.95 | AO21: 2287.5732 | AP21: 3172.6375 | AQ21: 4546.4294 | AR21: 7927.7095 | AS21: 16821.018
A22: 5 | B22: 5 | C22: 5.4781808 | D22: 7.850302 | E22: 9.0950862 | F22: 9.552425 | G22: 10.710988 | H22: 11.815257 | I22: 12.613984 | J22: 13.688745 | K22: 15.100011 | L22: 15.602055 | M22: 16.931412 | N22: 18.374035 | O22: 19.939576 | P22: 22.357942 | Q22: 23.869367 | R22: 25.069619 | S22: 28.110181 | T22: 31.519516 | U22: 31.519516 | V22: 33.650276 | W22: 38.986037 | X22: 43.005374 | Y22: 48.221269 | Z22: 51.481089 | AA22: 57.724959 | AB22: 63.67622 | AC22: 71.399173 | AD22: 76.225849 | AE22: 88.312611 | AF22: 105.71771 | AG22: 118.53965 | AH22: 139.6003 | AI22: 159.11259 | AJ22: 190.4713 | AK22: 243.42414 | AL22: 311.09836 | AM22: 372.41119 | AN22: 569.7467 | AO22: 843.5996 | AP22: 1570.445 | AQ22: 2694.0008 | AR22: 5623.4133 | AS22: 15001.558
A23: 5 | B23: 6 | C23: 3.1934591 | D23: 4.0812712 | E23: 4.8063809 | F23: 5.4781808 | G23: 6.5578483 | H23: 6.8876042 | I23: 7.5976943 | J23: 7.850302 | K23: 8.5191787 | L23: 8.9475585 | M23: 9.397479 | N23: 9.552425 | O23: 9.8700234 | P23: 10.366329 | Q23: 10.53725 | R23: 11.623607 | S23: 12.409378 | T23: 13.248268 | U23: 13.914446 | V23: 15.348981 | W23: 16.120792 | X23: 17.494347 | Y23: 18.676987 | Z23: 20.94222 | AA23: 23.869367 | AB23: 26.330223 | AC23: 29.044786 | AD23: 34.769079 | AE23: 42.307801 | AF23: 49.016343 | AG23: 61.627241 | AH23: 74.989421 | AI23: 91.248823 | AJ23: 114.72527 | AK23: 151.4948 | AL23: 210.10829 | AM23: 301.08782 | AN23: 453.15836 | AO23: 764.75571 | AP23: 1570.445 | AQ23: 2876.1188 | AR23: 6622.5116 | AS23: 17098.363
A24: 6 | B24: 1 | C24: 15.091406 | D24: 21.789989 | E24: 25.135957 | F24: 27.273818 | G24: 27.836111 | H24: 41.865969 | I24: 48.294709 | J24: 54.585254 | K24: 62.967107 | L24: 68.322579 | M24: 66.942453 | N24: 72.636037 | O24: 102.75828 | P24: 116.14289 | Q24: 148.36934 | R24: 189.53775 | S24: 252.21594 | T24: 322.19892 | U24: 465.21253 | V24: 644.84223 | W24: 875.77574 | X24: 1165.3858 | Y24: 1582.7385 | Z24: 2106.1338 | AA24: 2979.5499 | AB24: 3884.7658 | AC24: 4862.4345 | AD24: 6470.3918 | AE24: 8265.7474 | AF24: 10559.265 | AG24: 13216.687 | AH24: 16883.954 | AI24: 21133.093 | AJ24: 22930.503 | AK24: 26996.945
A25: 6 | B25: 2 | C25: 1141.8448 | D25: 1488.7483 | E25: 1752.7594 | F25: 2021.9048 | G25: 2063.5896 | H25: 2285.2646 | I25: 2582.9278 | J25: 2690.528 | K25: 2802.6107 | L25: 2979.5499 | M25: 3167.6599 | N25: 3367.6461 | O25: 3654.0708 | P25: 4130.0255 | Q25: 4573.6811 | R25: 5169.418 | S25: 5963.2094 | T25: 6603.7893 | U25: 7165.4542 | V25: 7935.1816 | W25: 8787.5946 | X25: 10345.966 | Y25: 11934.644 | Z25: 13489.17 | AA25: 15560.503 | AB25: 18319.966 | AC25: 21568.786 | AD25: 24378.191 | AE25: 29293.087 | AF25: 35924.558 | AG25: 42295.335 | AH25: 46838.784 | AI25: 55145.064 | AJ25: 59835.257 | AK25: 69023.276
A26: 6 | B26: 3 | C26: 7935.1816 | D26: 7774.8897 | E26: 7774.8897 | F26: 8436.159 | G26: 8787.5946 | H26: 9342.3881 | I26: 9342.3881 | J26: 10345.966 | K26: 10999.145 | L26: 12431.82 | M26: 14340.791 | N26: 15560.503 | O26: 17949.9 | P26: 19083.144 | Q26: 21133.093 | R26: 23403.253 | S26: 25917.277 | T26: 29293.087 | U26: 32439.809 | V26: 35198.877 | W26: 38980.01 | X26: 44057.284 | Y26: 49795.89 | Z26: 54031.126 | AA26: 61068.857 | AB26: 67628.996 | AC26: 78013.784 | AD26: 86394.181 | AE26: 101715.12 | AF26: 112641.56 | AG26: 127313.5 | AH26: 146863.15 | AI26: 152981.22 | AJ26: 156135.17 | AK26: 162639.49
A27: 6 | B27: 4 | C27: 21568.786 | D27: 19083.144 | E27: 20287.934 | F27: 20706.202 | G27: 22013.461 | H27: 22930.503 | I27: 24880.787 | J27: 26451.603 | K27: 27553.53 | L27: 29293.087 | M27: 31142.468 | N27: 35198.877 | O27: 37421.112 | P27: 38980.01 | Q27: 40603.849 | R27: 44965.596 | S27: 46838.784 | T27: 47804.441 | U27: 56281.968 | V27: 56281.968 | W27: 62327.89 | X27: 66262.88 | Y27: 74893.838 | Z27: 81263.702 | AA27: 84649.006 | AB27: 89993.211 | AC27: 105952.4 | AD27: 122221.94 | AE27: 132617.15 | AF27: 140989.77 | AG27: 162639.49 | AH27: 180110.55 | AI27: 191481.59 | AJ27: 156135.17 | AK27: 140989.77
A28: 7 | B28: 1 | C28: 1.8968234 | D28: 5.2178163 | E28: 15.270614 | F28: 45.623944 | G28: 133.52437 | H28: 345.23641 | I28: 741.2337 | J28: 1465.2755 | K28: 2666.9137 | L28: 4657.5919 | M28: 7645.5384 | N28: 11555.275 | O28: 17828.757 | P28: 24809.547 | Q28: 35244.001 | R28: 47059.33 | S28: 59060.953 | T28: 75670.006 | U28: 91125.779 | V28: 109738.43 | W28: 129451.66 | X28: 152706.14
A29: 7 | B29: 2 | C29: 8303.9077 | D29: 9018.9702 | E29: 12550.317 | F29: 21031.486 | G29: 36730.126 | H29: 68246.552 | I29: 129451.66 | J29: 195649.99 | K29: 314599.37 | L29: 465759.19 | M29: 675454.99
A30: 8 | B30: 1 | C30: 6874.0686 | D30: 6236.9598 | E30: 5275.7079 | F30: 4359.1654 | G30: 3643.8152 | H30: 3163.1893 | I30: 2682.5633 | J30: 2201.9374 | K30: 1631.8927 | L30: 1151.2668 | M30: 815.94635 | N30: 558.86736 | O30: 402.3845 | P30: 223.54694
A31: 8 | B31: 2 | C31: 7522.3547 | D31: 6762.2951 | E31: 5678.0924 | F31: 4817.4367 | G31: 4102.0864 | H31: 3587.9285 | I31: 3040.2385 | J31: 2369.5976 | K31: 1732.4888 | L31: 1274.2176 | M31: 961.25186 | N31: 760.05961 | O31: 581.22206 | P31: 424.7392
A32: 8 | B32: 3 | C32: 7622.9508 | D32: 7108.7928 | E32: 6315.2012 | F32: 5208.6438 | G32: 4415.0522 | H32: 3856.1848 | I32: 3375.5589 | J32: 2894.9329 | K32: 2302.5335 | L32: 1643.07 | M32: 1274.2176 | N32: 994.7839 | O32: 793.59165 | P32: 558.86736
A33: 8 | B33: 4 | C33: 4046.1997 | D33: 3643.8152 | E33: 3084.9478 | F33: 2604.3219 | G33: 2257.8241 | H33: 1967.2131 | I33: 1687.7794 | J33: 1430.7004 | K33: 1117.7347 | L33: 894.18778 | M33: 670.64083 | N33: 536.51267 | O33: 357.67511 | P33: 212.3696
A34: 9 | B34: 1 | C34: 2779.4524 | D34: 2835.9128 | E34: 2742.4381 | F34: 2705.9166 | G34: 2616.7267 | H34: 2303.8034 | I34: 1490.105 | J34: 944.61477 | K34: 722.44769 | L34: 586.89303 | M34: 445.86093 | N34: 321.0334 | O34: 239.03256 | P34: 174.43365
A35: 9 | B35: 2 | C35: 3444.4343 | D35: 3375.8588 | E35: 3375.8588 | F35: 3286.544 | G35: 3052.9252 | H35: 2599.2447 | I35: 1658.8084 | J35: 1016.8995 | K35: 757.15512 | L35: 627.5828 | M35: 483.20778 | N35: 347.92426 | O35: 271.50011 | P35: 207.6451
A36: 9 | B36: 3 | C36: 3242.7766 | D36: 3199.5921 | E36: 3114.9407 | F36: 3156.9827 | G36: 2932.5735 | H36: 2530.4766 | I36: 1625.783 | J36: 1030.6244 | K36: 767.37435 | L36: 606.897 | M36: 470.42358 | N36: 329.75778 | O36: 250.51603 | P36: 181.59234
A37: 9 | B37: 4 | C37: 3398.5643 | D37: 3375.8588 | E37: 3286.544 | F37: 3242.7766 | G37: 3073.4586 | H37: 2652.0444 | I37: 1750.1928 | J37: 1080.1371 | K37: 777.73151 | L37: 644.63795 | M37: 493.02341 | N37: 329.75778 | O37: 125.59752
A38: 11 | B38: 1a
A39: 11 | B39: 2a
A40: 11 | B40: 3a
...

Sheet converted_MPa_Storage_modulus_G
A1: Study_id | B1: Instance
A2: 1 | B2: 1
A3: 1 | B3: 2
A4: 1 | B4: 3
A5: 1 | B5: 4
A6: 1 | B6: 5
A7: 2 | B7: 1 | C7: =Storage_modulus_G!C7/1000000 -> 7.8116806e-05 | D7: =Storage_modulus_G!D7/1000000 -> 0.00011030285 | E7: =Storage_modulus_G!E7/1000000 -> 0.00016151092 | F7: =Storage_modulus_G!F7/1000000 -> 0.00024082605 | G7: =Storage_modulus_G!G7/1000000 -> 0.00036567181 | H7: =Storage_modulus_G!H7/1000000 -> 0.00054524672 | I7: =Storage_modulus_G!I7/1000000 -> 0.00075604718 | J7: =Storage_modulus_G!J7/1000000 -> 0.0010109551 | ... M7: =Storage_modulus_G!M7/1000000 -> 0.002552349
A8: 2 | B8: 2 | C8: =Storage_modulus_G!C8/1000000 -> 2.2640686e-06 | D8: =Storage_modulus_G!D8/1000000 -> 2.4346432e-06 | E8: =Storage_modulus_G!E8/1000000 -> 2.7646514e-06 | F8: =Storage_modulus_G!F8/1000000 -> 2.9729398e-06 | G8: =Storage_modulus_G!G8/1000000 -> 3.4377762e-06 | H8: =Storage_modulus_G!H8/1000000 -> 3.9037559e-06 | I8: =Storage_modulus_G!I8/1000000 -> 4.5968525e-06 | J8: =Storage_modulus_G!J8/1000000 -> 6.2593606e-06 | ... M8: =Storage_modulus_G!M8/1000000 -> 2.8773357e-05
A9: 2 | B9: 3 | C9: =Storage_modulus_G!C9/1000000 -> 0.00069042533 | D9: =Storage_modulus_G!D9/1000000 -> 0.00084307752 | E9: =Storage_modulus_G!E9/1000000 -> 0.0010675572 | F9: =Storage_modulus_G!F9/1000000 -> 0.0014536524 | G9: =Storage_modulus_G!G9/1000000 -> 0.0020156559 | H9: =Storage_modulus_G!H9/1000000 -> 0.002599121 | I9: =Storage_modulus_G!I9/1000000 -> 0.0036700229 | J9: =Storage_modulus_G!J9/1000000 -> 0.0048190929 | ... M9: =Storage_modulus_G!M9/1000000 -> 0.012616717
A10: 2 | B10: 4 | C10: =Storage_modulus_G!C10/1000000 -> 0.00092320827 | D10: =Storage_modulus_G!D10/1000000 -> 0.0011904462 | E10: =Storage_modulus_G!E10/1000000 -> 0.0016506904 | F10: =Storage_modulus_G!F10/1000000 -> 0.0023735278 | G10: =Storage_modulus_G!G10/1000000 -> 0.003539125 | H10: =Storage_modulus_G!H10/1000000 -> 0.0054723057 | I10: =Storage_modulus_G!I10/1000000 -> 0.0083091837 | J10: =Storage_modulus_G!J10/1000000 -> 0.01381588 | ... M10: =Storage_modulus_G!M10/1000000 -> 0.063509562
A11: 3 | B11: 1 | C11: =Storage_modulus_G!C11/1000000 -> 2.3747494e-05 | D11: =Storage_modulus_G!D11/1000000 -> 1.4724465e-05 | E11: =Storage_modulus_G!E11/1000000 -> 2.1193096e-05 | F11: =Storage_modulus_G!F11/1000000 -> 4.0083479e-05 | G11: =Storage_modulus_G!G11/1000000 -> 0.00016436732 | H11: =Storage_modulus_G!H11/1000000 -> 0.00033284384 | I11: =Storage_modulus_G!I11/1000000 -> 0.00090607968 | J11: =Storage_modulus_G!J11/1000000 -> 0.0016751462 | ... Y11: =Storage_modulus_G!Y11/1000000 -> 0.23389881
A12: 3 | B12: 2 | C12: =Storage_modulus_G!C12/1000000 -> 0.0021517122 | D12: =Storage_modulus_G!D12/1000000 -> 0.002009695 | E12: =Storage_modulus_G!E12/1000000 -> 0.0015293751 | F12: =Storage_modulus_G!F12/1000000 -> 0.0015645833 | G12: =Storage_modulus_G!G12/1000000 -> 0.0029591684 | H12: =Storage_modulus_G!H12/1000000 -> 0.0041633207 | I12: =Storage_modulus_G!I12/1000000 -> 0.0068691468 | J12: =Storage_modulus_G!J12/1000000 -> 0.0108292 | ... Y12: =Storage_modulus_G!Y12/1000000 -> 0.7814766
A13: 3 | B13: 3 | C13: =Storage_modulus_G!C13/1000000 -> 0.13240703 | D13: =Storage_modulus_G!D13/1000000 -> 0.13857357 | E13: =Storage_modulus_G!E13/1000000 -> 0.1450273 | F13: =Storage_modulus_G!F13/1000000 -> 0.14836601 | G13: =Storage_modulus_G!G13/1000000 -> 0.15885046 | H13: =Storage_modulus_G!H13/1000000 -> 0.17007579 | I13: =Storage_modulus_G!I13/1000000 -> 0.18209438 | J13: =Storage_modulus_G!J13/1000000 -> 0.19945056 | ... Y13: =Storage_modulus_G!Y13/1000000 -> 1.8558111
A14: 3 | B14: 4 | C14: =Storage_modulus_G!C14/1000000 -> 0.00016815128 | D14: =Storage_modulus_G!D14/1000000 -> 0.0013648679 | E14: =Storage_modulus_G!E14/1000000 -> 0.0052274111 | F14: =Storage_modulus_G!F14/1000000 -> 0.0088233654 | G14: =Storage_modulus_G!G14/1000000 -> 0.017072218 | H14: =Storage_modulus_G!H14/1000000 -> 0.029479644 | I14: =Storage_modulus_G!I14/1000000 -> 0.043407201 | J14: =Storage_modulus_G!J14/1000000 -> 0.063914783 | ... Y14: =Storage_modulus_G!Y14/1000000 -> 1.1506825
A15: 4 | B15: 1 | C15: =Storage_modulus_G!C15/1000000 -> 6.6089431e-07 | D15: =Storage_modulus_G!D15/1000000 -> 7.961412e-07 | E15: =Storage_modulus_G!E15/1000000 -> 1.5479929e-06 | F15: =Storage_modulus_G!F15/1000000 -> 2.0741095e-06 | G15: =Storage_modulus_G!G15/1000000 -> 3.8239152e-06 | H15: =Storage_modulus_G!H15/1000000 -> 6.684709e-06 | I15: =Storage_modulus_G!I15/1000000 -> 1.4846263e-05 | J15: =Storage_modulus_G!J15/1000000 -> 2.0978874e-05 | ... W15: =Storage_modulus_G!W15/1000000 -> 0.059645483
A16: 4 | B16: 2 | C16: =Storage_modulus_G!C16/1000000 -> 1.936996e-05 | D16: =Storage_modulus_G!D16/1000000 -> 2.6652784e-05 | E16: =Storage_modulus_G!E16/1000000 -> 5.0462678e-05 | F16: =Storage_modulus_G!F16/1000000 -> 6.7613435e-05 | G16: =Storage_modulus_G!G16/1000000 -> 0.00010076282 | H16: =Storage_modulus_G!H16/1000000 -> 0.00014622327 | I16: =Storage_modulus_G!I16/1000000 -> 0.00020662436 | J16: =Storage_modulus_G!J16/1000000 -> 0.00029197558 | ... W16: =Storage_modulus_G!W16/1000000 -> 0.10996491
A17: 4 | B17: 3 | C17: =Storage_modulus_G!C17/1000000 -> 7.5203426e-05 | D17: =Storage_modulus_G!D17/1000000 -> 8.3645435e-05 | E17: =Storage_modulus_G!E17/1000000 -> 0.00016263766 | F17: =Storage_modulus_G!F17/1000000 -> 0.00018577056 | G17: =Storage_modulus_G!G17/1000000 -> 0.00020662436 | H17: =Storage_modulus_G!H17/1000000 -> 0.00029984561 | I17: =Storage_modulus_G!I17/1000000 -> 0.00040175417 | J17: =Storage_modulus_G!J17/1000000 -> 0.00058301076 | ... W17: =Storage_modulus_G!W17/1000000 -> 0.13970583
A18: 5 | B18: 1 | C18: =Storage_modulus_G!C18/1000000 -> 8.3623838e-06 | D18: =Storage_modulus_G!D18/1000000 -> 9.6548029e-06 | E18: =Storage_modulus_G!E18/1000000 -> 1.0970386e-05 | F18: =Storage_modulus_G!F18/1000000 -> 1.1146967e-05 | G18: =Storage_modulus_G!G18/1000000 -> 1.2465233e-05 | H18: =Storage_modulus_G!H18/1000000 -> 1.4623406e-05 | I18: =Storage_modulus_G!I18/1000000 -> 1.7711947e-05 | J18: =Storage_modulus_G!J18/1000000 -> 1.9806603e-05 | ... AS18: =Storage_modulus_G!AS18/1000000 -> 0.016991659
A19: 5 | B19: 2 | C19: =Storage_modulus_G!C19/1000000 -> 0.00036219788 | D19: =Storage_modulus_G!D19/1000000 -> 0.00041817611 | E19: =Storage_modulus_G!E19/1000000 -> 0.00046022277 | F19: =Storage_modulus_G!F19/1000000 -> 0.00049057719 | G19: =Storage_modulus_G!G19/1000000 -> 0.00051464978 | H19: =Storage_modulus_G!H19/1000000 -> 0.00051464978 | I19: =Storage_modulus_G!I19/1000000 -> 0.00057551345 | J19: =Storage_modulus_G!J19/1000000 -> 0.00060375386 | ... AS19: =Storage_modulus_G!AS19/1000000 -> 0.016991659
A20: 5 | B20: 3 | C20: =Storage_modulus_G!C20/1000000 -> 0.00016829643 | D20: =Storage_modulus_G!D20/1000000 -> 0.00021728608 | E20: =Storage_modulus_G!E20/1000000 -> 0.00024689392 | F20: =Storage_modulus_G!F20/1000000 -> 0.0002805362 | G20: =Storage_modulus_G!G20/1000000 -> 0.00032389349 | H20: =Storage_modulus_G!H20/1000000 -> 0.00036219788 | I20: =Storage_modulus_G!I20/1000000 -> 0.00041817611 | J20: =Storage_modulus_G!J20/1000000 -> 0.00044575731 | ... AS20: =Storage_modulus_G!AS20/1000000 -> 0.024532199
A21: 5 | B21: 4 | C21: =Storage_modulus_G!C21/1000000 -> 7.3773048e-05 | D21: =Storage_modulus_G!D21/1000000 -> 8.9768713e-05 | E21: =Storage_modulus_G!E21/1000000 -> 0.0001092326 | F21: =Storage_modulus_G!F21/1000000 -> 0.00011853965 | G21: =Storage_modulus_G!G21/1000000 -> 0.00012863969 | H21: =Storage_modulus_G!H21/1000000 -> 0.0001396003 | I21: =Storage_modulus_G!I21/1000000 -> 0.0001514948 | J21: =Storage_modulus_G!J21/1000000 -> 0.00015911259 | ... AS21: =Storage_modulus_G!AS21/1000000 -> 0.016821018
